2024-06-15 16:46:16,077 - pocketoption - DEBUG - ======== New Session ========
2024-06-15 16:46:18,848 - pocketoption - DEBUG - Old session worked fine.
2024-06-15 16:46:18,859 - pocketoption - DEBUG - Payout Last Request ID: 164123
2024-06-15 16:59:02,391 - pocketoption - DEBUG - Old session worked fine.
2024-06-15 16:59:03,485 - pocketoption - DEBUG - Processed -> Statistics -> Current week
2024-06-15 16:59:03,485 - pocketoption - DEBUG - Total time taken to perform the task: 2.52 seconds
2024-06-15 17:00:00,153 - pocketoption - DEBUG - No change detected!!
2024-06-15 17:01:01,857 - pocketoption - DEBUG - First Check -> Latest ID: 164123 | Existing ID: 164123
2024-06-15 17:01:02,420 - pocketoption - DEBUG - Balance -> -936 -> Not enough for Withdrawal
2024-06-15 17:01:02,420 - pocketoption - DEBUG - Bonus -> 0.0 -> Not enough for Withdrawal
2024-06-15 17:01:03,281 - pocketoption - DEBUG - Second Check -> Latest ID: 164123 | Existing ID: 164123
2024-06-15 17:59:03,061 - pocketoption - DEBUG - Old session worked fine.
2024-06-15 17:59:04,139 - pocketoption - DEBUG - Processed -> Statistics -> Current week
2024-06-15 17:59:04,139 - pocketoption - DEBUG - Total time taken to perform the task: 3.31 seconds
2024-06-15 18:00:00,558 - pocketoption - DEBUG - No change detected!!
2024-06-15 18:01:02,273 - pocketoption - DEBUG - First Check -> Latest ID: 164123 | Existing ID: 164123
2024-06-15 18:01:02,992 - pocketoption - DEBUG - Balance -> -936 -> Not enough for Withdrawal
2024-06-15 18:01:02,992 - pocketoption - DEBUG - Bonus -> 0.0 -> Not enough for Withdrawal
2024-06-15 18:01:03,929 - pocketoption - DEBUG - Second Check -> Latest ID: 164123 | Existing ID: 164123
2024-06-15 18:59:01,972 - pocketoption - DEBUG - Old session worked fine.
2024-06-15 18:59:03,052 - pocketoption - DEBUG - Processed -> Statistics -> Current week
2024-06-15 18:59:03,052 - pocketoption - DEBUG - Total time taken to perform the task: 2.45 seconds
2024-06-15 19:00:01,267 - pocketoption - INFO - Target [ID:610323477]: success
2024-06-15 19:00:01,533 - pocketoption - INFO - Target [ID:1838317981]: success
2024-06-15 19:01:01,675 - pocketoption - DEBUG - First Check -> Latest ID: 164123 | Existing ID: 164123
2024-06-15 19:01:02,269 - pocketoption - DEBUG - Balance -> -936 -> Not enough for Withdrawal
2024-06-15 19:01:02,269 - pocketoption - DEBUG - Bonus -> 0.0 -> Not enough for Withdrawal
2024-06-15 19:01:03,161 - pocketoption - DEBUG - Second Check -> Latest ID: 164123 | Existing ID: 164123
2024-06-15 19:59:01,480 - pocketoption - DEBUG - Old session worked fine.
2024-06-15 19:59:03,044 - pocketoption - DEBUG - Processed -> Statistics -> Current week
2024-06-15 19:59:03,044 - pocketoption - DEBUG - Total time taken to perform the task: 2.94 seconds
2024-06-15 20:00:00,741 - pocketoption - DEBUG - No change detected!!
2024-06-15 20:01:02,364 - pocketoption - DEBUG - First Check -> Latest ID: 164123 | Existing ID: 164123
2024-06-15 20:01:02,942 - pocketoption - DEBUG - Balance -> -936 -> Not enough for Withdrawal
2024-06-15 20:01:02,942 - pocketoption - DEBUG - Bonus -> 0.0 -> Not enough for Withdrawal
2024-06-15 20:01:03,848 - pocketoption - DEBUG - Second Check -> Latest ID: 164123 | Existing ID: 164123
2024-06-15 20:59:01,485 - pocketoption - DEBUG - Old session worked fine.
2024-06-15 20:59:02,784 - pocketoption - DEBUG - Processed -> Statistics -> Current week
2024-06-15 20:59:02,784 - pocketoption - DEBUG - Total time taken to perform the task: 2.77 seconds
2024-06-15 21:00:00,328 - pocketoption - DEBUG - No change detected!!
2024-06-15 21:01:02,234 - pocketoption - DEBUG - First Check -> Latest ID: 164123 | Existing ID: 164123
2024-06-15 21:01:02,844 - pocketoption - DEBUG - Balance -> -936 -> Not enough for Withdrawal
2024-06-15 21:01:02,844 - pocketoption - DEBUG - Bonus -> 0.0 -> Not enough for Withdrawal
2024-06-15 21:01:03,875 - pocketoption - DEBUG - Second Check -> Latest ID: 164123 | Existing ID: 164123
2024-06-15 21:59:01,406 - pocketoption - DEBUG - Old session worked fine.
2024-06-15 21:59:03,172 - pocketoption - DEBUG - Processed -> Statistics -> Current week
2024-06-15 21:59:03,172 - pocketoption - DEBUG - Total time taken to perform the task: 3.17 seconds
2024-06-15 22:00:00,690 - pocketoption - DEBUG - No change detected!!
2024-06-15 22:01:01,626 - pocketoption - DEBUG - First Check -> Latest ID: 164123 | Existing ID: 164123
2024-06-15 22:01:02,189 - pocketoption - DEBUG - Balance -> -936 -> Not enough for Withdrawal
2024-06-15 22:01:02,189 - pocketoption - DEBUG - Bonus -> 0.0 -> Not enough for Withdrawal
2024-06-15 22:01:03,064 - pocketoption - DEBUG - Second Check -> Latest ID: 164123 | Existing ID: 164123
2024-06-15 22:59:02,756 - pocketoption - DEBUG - Old session worked fine.
2024-06-15 22:59:04,131 - pocketoption - DEBUG - Processed -> Statistics -> Current week
2024-06-15 22:59:04,131 - pocketoption - DEBUG - Total time taken to perform the task: 3.95 seconds
2024-06-15 23:00:00,608 - pocketoption - DEBUG - No change detected!!
2024-06-15 23:01:02,064 - pocketoption - DEBUG - First Check -> Latest ID: 164123 | Existing ID: 164123
2024-06-15 23:01:02,689 - pocketoption - DEBUG - Balance -> -936 -> Not enough for Withdrawal
2024-06-15 23:01:02,689 - pocketoption - DEBUG - Bonus -> 0.0 -> Not enough for Withdrawal
2024-06-15 23:01:05,049 - pocketoption - DEBUG - Second Check -> Latest ID: 164123 | Existing ID: 164123
2024-06-15 23:59:02,327 - pocketoption - DEBUG - Old session worked fine.
2024-06-15 23:59:03,953 - pocketoption - DEBUG - Processed -> Statistics -> Current week
2024-06-15 23:59:03,953 - pocketoption - DEBUG - Total time taken to perform the task: 3.52 seconds
2024-06-16 00:00:00,595 - pocketoption - DEBUG - No change detected!!
2024-06-16 00:01:02,340 - pocketoption - DEBUG - First Check -> Latest ID: 164123 | Existing ID: 164123
2024-06-16 00:01:02,935 - pocketoption - DEBUG - Balance -> -936 -> Not enough for Withdrawal
2024-06-16 00:01:02,935 - pocketoption - DEBUG - Bonus -> 0.0 -> Not enough for Withdrawal
2024-06-16 00:01:03,841 - pocketoption - DEBUG - Second Check -> Latest ID: 164123 | Existing ID: 164123
2024-06-16 00:59:02,074 - pocketoption - DEBUG - Old session worked fine.
2024-06-16 00:59:03,325 - pocketoption - DEBUG - Processed -> Statistics -> Current week
2024-06-16 00:59:03,325 - pocketoption - DEBUG - Total time taken to perform the task: 2.63 seconds
2024-06-16 01:00:00,756 - pocketoption - DEBUG - No change detected!!
2024-06-16 01:01:02,313 - pocketoption - DEBUG - First Check -> Latest ID: 164123 | Existing ID: 164123
2024-06-16 01:01:02,970 - pocketoption - DEBUG - Balance -> -936 -> Not enough for Withdrawal
2024-06-16 01:01:02,970 - pocketoption - DEBUG - Bonus -> 0.0 -> Not enough for Withdrawal
2024-06-16 01:01:03,986 - pocketoption - DEBUG - Second Check -> Latest ID: 164123 | Existing ID: 164123
2024-06-16 01:59:02,070 - pocketoption - DEBUG - Old session worked fine.
2024-06-16 01:59:03,743 - pocketoption - DEBUG - Processed -> Statistics -> Current week
2024-06-16 01:59:03,743 - pocketoption - DEBUG - Total time taken to perform the task: 3.03 seconds
2024-06-16 02:00:00,216 - pocketoption - DEBUG - No change detected!!
2024-06-16 02:01:02,072 - pocketoption - DEBUG - First Check -> Latest ID: 164123 | Existing ID: 164123
2024-06-16 02:01:02,697 - pocketoption - DEBUG - Balance -> -936 -> Not enough for Withdrawal
2024-06-16 02:01:02,697 - pocketoption - DEBUG - Bonus -> 0.0 -> Not enough for Withdrawal
2024-06-16 02:01:03,667 - pocketoption - DEBUG - Second Check -> Latest ID: 164123 | Existing ID: 164123
2024-06-16 02:59:01,629 - pocketoption - DEBUG - Old session worked fine.
2024-06-16 02:59:02,942 - pocketoption - DEBUG - Processed -> Statistics -> Current week
2024-06-16 02:59:02,942 - pocketoption - DEBUG - Total time taken to perform the task: 2.75 seconds
2024-06-16 03:00:00,598 - pocketoption - DEBUG - No change detected!!
2024-06-16 03:01:02,392 - pocketoption - DEBUG - First Check -> Latest ID: 164123 | Existing ID: 164123
2024-06-16 03:01:03,002 - pocketoption - DEBUG - Balance -> -936 -> Not enough for Withdrawal
2024-06-16 03:01:03,002 - pocketoption - DEBUG - Bonus -> 0.0 -> Not enough for Withdrawal
2024-06-16 03:01:03,956 - pocketoption - DEBUG - Second Check -> Latest ID: 164123 | Existing ID: 164123
2024-06-16 03:59:02,215 - pocketoption - DEBUG - Old session worked fine.
2024-06-16 03:59:03,668 - pocketoption - DEBUG - Processed -> Statistics -> Current week
2024-06-16 03:59:03,668 - pocketoption - DEBUG - Total time taken to perform the task: 2.83 seconds
2024-06-16 04:00:00,918 - pocketoption - INFO - Target [ID:610323477]: success
2024-06-16 04:00:01,168 - pocketoption - INFO - Target [ID:1838317981]: success
2024-06-16 04:01:02,040 - pocketoption - DEBUG - First Check -> Latest ID: 164123 | Existing ID: 164123
2024-06-16 04:01:02,634 - pocketoption - DEBUG - Balance -> -936 -> Not enough for Withdrawal
2024-06-16 04:01:02,634 - pocketoption - DEBUG - Bonus -> 0.0 -> Not enough for Withdrawal
2024-06-16 04:01:03,603 - pocketoption - DEBUG - Second Check -> Latest ID: 164123 | Existing ID: 164123
2024-06-16 04:59:02,357 - pocketoption - DEBUG - Old session worked fine.
2024-06-16 04:59:03,451 - pocketoption - DEBUG - Processed -> Statistics -> Current week
2024-06-16 04:59:03,451 - pocketoption - DEBUG - Total time taken to perform the task: 3.14 seconds
2024-06-16 05:00:00,937 - pocketoption - DEBUG - No change detected!!
2024-06-16 05:01:02,426 - pocketoption - DEBUG - First Check -> Latest ID: 164123 | Existing ID: 164123
2024-06-16 05:01:03,051 - pocketoption - DEBUG - Balance -> -936 -> Not enough for Withdrawal
2024-06-16 05:01:03,051 - pocketoption - DEBUG - Bonus -> 0.0 -> Not enough for Withdrawal
2024-06-16 05:01:03,957 - pocketoption - DEBUG - Second Check -> Latest ID: 164123 | Existing ID: 164123
2024-06-16 05:59:03,707 - pocketoption - DEBUG - Old session worked fine.
2024-06-16 05:59:05,332 - pocketoption - DEBUG - Processed -> Statistics -> Current week
2024-06-16 05:59:05,347 - pocketoption - DEBUG - Total time taken to perform the task: 5.05 seconds
2024-06-16 06:00:00,985 - pocketoption - DEBUG - No change detected!!
2024-06-16 06:01:01,998 - pocketoption - DEBUG - First Check -> Latest ID: 164123 | Existing ID: 164123
2024-06-16 06:01:02,654 - pocketoption - DEBUG - Balance -> -936 -> Not enough for Withdrawal
2024-06-16 06:01:02,654 - pocketoption - DEBUG - Bonus -> 0.0 -> Not enough for Withdrawal
2024-06-16 06:01:03,641 - pocketoption - DEBUG - Second Check -> Latest ID: 164123 | Existing ID: 164123
2024-06-16 06:59:02,583 - pocketoption - DEBUG - Old session worked fine.
2024-06-16 06:59:04,428 - pocketoption - DEBUG - Processed -> Statistics -> Current week
2024-06-16 06:59:04,428 - pocketoption - DEBUG - Total time taken to perform the task: 3.5 seconds
2024-06-16 07:00:00,058 - pocketoption - DEBUG - No change detected!!
2024-06-16 07:01:01,798 - pocketoption - DEBUG - First Check -> Latest ID: 164123 | Existing ID: 164123
2024-06-16 07:01:02,502 - pocketoption - DEBUG - Balance -> -936 -> Not enough for Withdrawal
2024-06-16 07:01:02,502 - pocketoption - DEBUG - Bonus -> 0.0 -> Not enough for Withdrawal
2024-06-16 07:01:03,439 - pocketoption - DEBUG - Second Check -> Latest ID: 164123 | Existing ID: 164123
2024-06-16 07:59:02,853 - pocketoption - DEBUG - Old session worked fine.
2024-06-16 07:59:05,056 - pocketoption - DEBUG - Processed -> Statistics -> Current week
2024-06-16 07:59:05,056 - pocketoption - DEBUG - Total time taken to perform the task: 4.13 seconds
2024-06-16 08:00:00,621 - pocketoption - DEBUG - No change detected!!
2024-06-16 08:01:04,032 - pocketoption - DEBUG - First Check -> Latest ID: 164123 | Existing ID: 164123
2024-06-16 08:01:04,657 - pocketoption - DEBUG - Balance -> -936 -> Not enough for Withdrawal
2024-06-16 08:01:04,657 - pocketoption - DEBUG - Bonus -> 0.0 -> Not enough for Withdrawal
2024-06-16 08:01:05,565 - pocketoption - DEBUG - Second Check -> Latest ID: 164123 | Existing ID: 164123
2024-06-16 08:59:03,557 - pocketoption - DEBUG - Old session worked fine.
2024-06-16 08:59:05,262 - pocketoption - DEBUG - Processed -> Statistics -> Current week
2024-06-16 08:59:05,262 - pocketoption - DEBUG - Total time taken to perform the task: 4.32 seconds
2024-06-16 09:00:00,818 - pocketoption - DEBUG - No change detected!!
2024-06-16 09:01:02,700 - pocketoption - DEBUG - First Check -> Latest ID: 164123 | Existing ID: 164123
2024-06-16 09:01:03,278 - pocketoption - DEBUG - Balance -> -936 -> Not enough for Withdrawal
2024-06-16 09:01:03,278 - pocketoption - DEBUG - Bonus -> 0.0 -> Not enough for Withdrawal
2024-06-16 09:01:04,215 - pocketoption - DEBUG - Second Check -> Latest ID: 164123 | Existing ID: 164123
2024-06-16 09:59:01,691 - pocketoption - DEBUG - Old session worked fine.
2024-06-16 09:59:03,179 - pocketoption - DEBUG - Processed -> Statistics -> Current week
2024-06-16 09:59:03,179 - pocketoption - DEBUG - Total time taken to perform the task: 2.88 seconds
2024-06-16 10:00:01,370 - pocketoption - INFO - Target [ID:610323477]: success
2024-06-16 10:00:01,667 - pocketoption - INFO - Target [ID:1838317981]: success
2024-06-16 10:01:01,818 - pocketoption - DEBUG - First Check -> Latest ID: 164123 | Existing ID: 164123
2024-06-16 10:01:02,447 - pocketoption - DEBUG - Balance -> -936 -> Not enough for Withdrawal
2024-06-16 10:01:02,447 - pocketoption - DEBUG - Bonus -> 0.0 -> Not enough for Withdrawal
2024-06-16 10:01:03,416 - pocketoption - DEBUG - Second Check -> Latest ID: 164123 | Existing ID: 164123
2024-06-16 10:59:01,625 - pocketoption - DEBUG - Old session worked fine.
2024-06-16 10:59:02,875 - pocketoption - DEBUG - Processed -> Statistics -> Current week
2024-06-16 10:59:02,875 - pocketoption - DEBUG - Total time taken to perform the task: 2.74 seconds
2024-06-16 11:00:00,400 - pocketoption - DEBUG - No change detected!!
2024-06-16 11:01:02,345 - pocketoption - DEBUG - First Check -> Latest ID: 164123 | Existing ID: 164123
2024-06-16 11:01:02,940 - pocketoption - DEBUG - Balance -> -936 -> Not enough for Withdrawal
2024-06-16 11:01:02,940 - pocketoption - DEBUG - Bonus -> 0.0 -> Not enough for Withdrawal
2024-06-16 11:01:03,941 - pocketoption - DEBUG - Second Check -> Latest ID: 164123 | Existing ID: 164123
2024-06-16 11:59:02,422 - pocketoption - DEBUG - Old session worked fine.
2024-06-16 11:59:04,095 - pocketoption - DEBUG - Processed -> Statistics -> Current week
2024-06-16 11:59:04,095 - pocketoption - DEBUG - Total time taken to perform the task: 3.1 seconds
2024-06-16 12:00:00,739 - pocketoption - DEBUG - No change detected!!
2024-06-16 12:01:01,539 - pocketoption - DEBUG - First Check -> Latest ID: 164123 | Existing ID: 164123
2024-06-16 12:01:02,118 - pocketoption - DEBUG - Balance -> -936 -> Not enough for Withdrawal
2024-06-16 12:01:02,118 - pocketoption - DEBUG - Bonus -> 0.0 -> Not enough for Withdrawal
2024-06-16 12:01:03,150 - pocketoption - DEBUG - Second Check -> Latest ID: 164123 | Existing ID: 164123
2024-06-16 12:59:10,625 - pocketoption - DEBUG - Old Session expired!! Trying to login again..
2024-06-16 12:59:15,737 - pocketoption - ERROR - ERR_BROADCAST: 
Traceback (most recent call last):
  File "C:\Users\brenopoubel\AppData\Roaming\Python\Python312\site-packages\anyio\streams\tls.py", line 131, in _call_sslobject_method
    result = func(*args)
             ^^^^^^^^^^^
  File "C:\Program Files\Python312\Lib\ssl.py", line 859, in read
    v = self._sslobj.read(len)
        ^^^^^^^^^^^^^^^^^^^^^^
ssl.SSLWantReadError: The operation did not complete (read) (_ssl.c:2559)

During handling of the above exception, another exception occurred:

Traceback (most recent call last):
  File "C:\Users\brenopoubel\AppData\Roaming\Python\Python312\site-packages\httpcore\backends\asyncio.py", line 31, in read
    return await self._stream.receive(max_bytes=max_bytes)
           ^^^^^^^^^^^^^^^^^^^^^^^^^^^^^^^^^^^^^^^^^^^^^^^
  File "C:\Users\brenopoubel\AppData\Roaming\Python\Python312\site-packages\anyio\streams\tls.py", line 196, in receive
    data = await self._call_sslobject_method(self._ssl_object.read, max_bytes)
           ^^^^^^^^^^^^^^^^^^^^^^^^^^^^^^^^^^^^^^^^^^^^^^^^^^^^^^^^^^^^^^^^^^^
  File "C:\Users\brenopoubel\AppData\Roaming\Python\Python312\site-packages\anyio\streams\tls.py", line 138, in _call_sslobject_method
    data = await self.transport_stream.receive()
           ^^^^^^^^^^^^^^^^^^^^^^^^^^^^^^^^^^^^^
  File "C:\Users\brenopoubel\AppData\Roaming\Python\Python312\site-packages\anyio\_backends\_asyncio.py", line 1203, in receive
    await self._protocol.read_event.wait()
  File "C:\Program Files\Python312\Lib\asyncio\locks.py", line 212, in wait
    await fut
asyncio.exceptions.CancelledError

During handling of the above exception, another exception occurred:

Traceback (most recent call last):
  File "C:\Users\brenopoubel\AppData\Roaming\Python\Python312\site-packages\httpcore\_exceptions.py", line 8, in map_exceptions
    yield
  File "C:\Users\brenopoubel\AppData\Roaming\Python\Python312\site-packages\httpcore\backends\asyncio.py", line 29, in read
    with anyio.fail_after(timeout):
  File "C:\Users\brenopoubel\AppData\Roaming\Python\Python312\site-packages\anyio\_core\_tasks.py", line 119, in __exit__
    raise TimeoutError
TimeoutError

During handling of the above exception, another exception occurred:

Traceback (most recent call last):
  File "C:\Users\brenopoubel\AppData\Roaming\Python\Python312\site-packages\httpx\_transports\default.py", line 60, in map_httpcore_exceptions
    yield
  File "C:\Users\brenopoubel\AppData\Roaming\Python\Python312\site-packages\httpx\_transports\default.py", line 291, in handle_async_request
    resp = await self._pool.handle_async_request(req)
           ^^^^^^^^^^^^^^^^^^^^^^^^^^^^^^^^^^^^^^^^^^
  File "C:\Users\brenopoubel\AppData\Roaming\Python\Python312\site-packages\httpcore\_async\connection_pool.py", line 253, in handle_async_request
    raise exc
  File "C:\Users\brenopoubel\AppData\Roaming\Python\Python312\site-packages\httpcore\_async\connection_pool.py", line 237, in handle_async_request
    response = await connection.handle_async_request(request)
               ^^^^^^^^^^^^^^^^^^^^^^^^^^^^^^^^^^^^^^^^^^^^^^
  File "C:\Users\brenopoubel\AppData\Roaming\Python\Python312\site-packages\httpcore\_async\connection.py", line 90, in handle_async_request
    return await self._connection.handle_async_request(request)
           ^^^^^^^^^^^^^^^^^^^^^^^^^^^^^^^^^^^^^^^^^^^^^^^^^^^^
  File "C:\Users\brenopoubel\AppData\Roaming\Python\Python312\site-packages\httpcore\_async\http11.py", line 102, in handle_async_request
    raise exc
  File "C:\Users\brenopoubel\AppData\Roaming\Python\Python312\site-packages\httpcore\_async\http11.py", line 81, in handle_async_request
    ) = await self._receive_response_headers(**kwargs)
        ^^^^^^^^^^^^^^^^^^^^^^^^^^^^^^^^^^^^^^^^^^^^^^
  File "C:\Users\brenopoubel\AppData\Roaming\Python\Python312\site-packages\httpcore\_async\http11.py", line 143, in _receive_response_headers
    event = await self._receive_event(timeout=timeout)
            ^^^^^^^^^^^^^^^^^^^^^^^^^^^^^^^^^^^^^^^^^^
  File "C:\Users\brenopoubel\AppData\Roaming\Python\Python312\site-packages\httpcore\_async\http11.py", line 172, in _receive_event
    data = await self._network_stream.read(
           ^^^^^^^^^^^^^^^^^^^^^^^^^^^^^^^^
  File "C:\Users\brenopoubel\AppData\Roaming\Python\Python312\site-packages\httpcore\backends\asyncio.py", line 28, in read
    with map_exceptions(exc_map):
  File "C:\Program Files\Python312\Lib\contextlib.py", line 158, in __exit__
    self.gen.throw(value)
  File "C:\Users\brenopoubel\AppData\Roaming\Python\Python312\site-packages\httpcore\_exceptions.py", line 12, in map_exceptions
    raise to_exc(exc)
httpcore.ReadTimeout

The above exception was the direct cause of the following exception:

Traceback (most recent call last):
  File "C:\Users\brenopoubel\My Drive\Monitors\pocketoption2\main.py", line 617, in broadcast
    current_stats = await get_statistics()
                    ^^^^^^^^^^^^^^^^^^^^^^
  File "C:\Users\brenopoubel\My Drive\Monitors\pocketoption2\main.py", line 468, in get_statistics
    await perform_login()
  File "C:\Users\brenopoubel\My Drive\Monitors\pocketoption2\main.py", line 526, in perform_login
    res = await core.session.get(url=core.home_link)
          ^^^^^^^^^^^^^^^^^^^^^^^^^^^^^^^^^^^^^^^^^^
  File "C:\Users\brenopoubel\AppData\Roaming\Python\Python312\site-packages\httpx\_client.py", line 1736, in get
    return await self.request(
           ^^^^^^^^^^^^^^^^^^^
  File "C:\Users\brenopoubel\AppData\Roaming\Python\Python312\site-packages\httpx\_client.py", line 1513, in request
    return await self.send(request, auth=auth, follow_redirects=follow_redirects)
           ^^^^^^^^^^^^^^^^^^^^^^^^^^^^^^^^^^^^^^^^^^^^^^^^^^^^^^^^^^^^^^^^^^^^^^
  File "C:\Users\brenopoubel\AppData\Roaming\Python\Python312\site-packages\httpx\_client.py", line 1600, in send
    response = await self._send_handling_auth(
               ^^^^^^^^^^^^^^^^^^^^^^^^^^^^^^^
  File "C:\Users\brenopoubel\AppData\Roaming\Python\Python312\site-packages\httpx\_client.py", line 1628, in _send_handling_auth
    response = await self._send_handling_redirects(
               ^^^^^^^^^^^^^^^^^^^^^^^^^^^^^^^^^^^^
  File "C:\Users\brenopoubel\AppData\Roaming\Python\Python312\site-packages\httpx\_client.py", line 1665, in _send_handling_redirects
    response = await self._send_single_request(request)
               ^^^^^^^^^^^^^^^^^^^^^^^^^^^^^^^^^^^^^^^^
  File "C:\Users\brenopoubel\AppData\Roaming\Python\Python312\site-packages\httpx\_client.py", line 1702, in _send_single_request
    response = await transport.handle_async_request(request)
               ^^^^^^^^^^^^^^^^^^^^^^^^^^^^^^^^^^^^^^^^^^^^^
  File "C:\Users\brenopoubel\AppData\Roaming\Python\Python312\site-packages\httpx\_transports\default.py", line 290, in handle_async_request
    with map_httpcore_exceptions():
  File "C:\Program Files\Python312\Lib\contextlib.py", line 158, in __exit__
    self.gen.throw(value)
  File "C:\Users\brenopoubel\AppData\Roaming\Python\Python312\site-packages\httpx\_transports\default.py", line 77, in map_httpcore_exceptions
    raise mapped_exc(message) from exc
httpx.ReadTimeout
2024-06-16 12:59:27,181 - pocketoption - DEBUG - Old Session expired!! Trying to login again..
2024-06-16 12:59:32,277 - pocketoption - ERROR - ERR_BROADCAST: 
Traceback (most recent call last):
  File "C:\Users\brenopoubel\AppData\Roaming\Python\Python312\site-packages\anyio\streams\tls.py", line 131, in _call_sslobject_method
    result = func(*args)
             ^^^^^^^^^^^
  File "C:\Program Files\Python312\Lib\ssl.py", line 859, in read
    v = self._sslobj.read(len)
        ^^^^^^^^^^^^^^^^^^^^^^
ssl.SSLWantReadError: The operation did not complete (read) (_ssl.c:2559)

During handling of the above exception, another exception occurred:

Traceback (most recent call last):
  File "C:\Users\brenopoubel\AppData\Roaming\Python\Python312\site-packages\httpcore\backends\asyncio.py", line 31, in read
    return await self._stream.receive(max_bytes=max_bytes)
           ^^^^^^^^^^^^^^^^^^^^^^^^^^^^^^^^^^^^^^^^^^^^^^^
  File "C:\Users\brenopoubel\AppData\Roaming\Python\Python312\site-packages\anyio\streams\tls.py", line 196, in receive
    data = await self._call_sslobject_method(self._ssl_object.read, max_bytes)
           ^^^^^^^^^^^^^^^^^^^^^^^^^^^^^^^^^^^^^^^^^^^^^^^^^^^^^^^^^^^^^^^^^^^
  File "C:\Users\brenopoubel\AppData\Roaming\Python\Python312\site-packages\anyio\streams\tls.py", line 138, in _call_sslobject_method
    data = await self.transport_stream.receive()
           ^^^^^^^^^^^^^^^^^^^^^^^^^^^^^^^^^^^^^
  File "C:\Users\brenopoubel\AppData\Roaming\Python\Python312\site-packages\anyio\_backends\_asyncio.py", line 1203, in receive
    await self._protocol.read_event.wait()
  File "C:\Program Files\Python312\Lib\asyncio\locks.py", line 212, in wait
    await fut
asyncio.exceptions.CancelledError

During handling of the above exception, another exception occurred:

Traceback (most recent call last):
  File "C:\Users\brenopoubel\AppData\Roaming\Python\Python312\site-packages\httpcore\_exceptions.py", line 8, in map_exceptions
    yield
  File "C:\Users\brenopoubel\AppData\Roaming\Python\Python312\site-packages\httpcore\backends\asyncio.py", line 29, in read
    with anyio.fail_after(timeout):
  File "C:\Users\brenopoubel\AppData\Roaming\Python\Python312\site-packages\anyio\_core\_tasks.py", line 119, in __exit__
    raise TimeoutError
TimeoutError

During handling of the above exception, another exception occurred:

Traceback (most recent call last):
  File "C:\Users\brenopoubel\AppData\Roaming\Python\Python312\site-packages\httpx\_transports\default.py", line 60, in map_httpcore_exceptions
    yield
  File "C:\Users\brenopoubel\AppData\Roaming\Python\Python312\site-packages\httpx\_transports\default.py", line 291, in handle_async_request
    resp = await self._pool.handle_async_request(req)
           ^^^^^^^^^^^^^^^^^^^^^^^^^^^^^^^^^^^^^^^^^^
  File "C:\Users\brenopoubel\AppData\Roaming\Python\Python312\site-packages\httpcore\_async\connection_pool.py", line 253, in handle_async_request
    raise exc
  File "C:\Users\brenopoubel\AppData\Roaming\Python\Python312\site-packages\httpcore\_async\connection_pool.py", line 237, in handle_async_request
    response = await connection.handle_async_request(request)
               ^^^^^^^^^^^^^^^^^^^^^^^^^^^^^^^^^^^^^^^^^^^^^^
  File "C:\Users\brenopoubel\AppData\Roaming\Python\Python312\site-packages\httpcore\_async\connection.py", line 90, in handle_async_request
    return await self._connection.handle_async_request(request)
           ^^^^^^^^^^^^^^^^^^^^^^^^^^^^^^^^^^^^^^^^^^^^^^^^^^^^
  File "C:\Users\brenopoubel\AppData\Roaming\Python\Python312\site-packages\httpcore\_async\http11.py", line 102, in handle_async_request
    raise exc
  File "C:\Users\brenopoubel\AppData\Roaming\Python\Python312\site-packages\httpcore\_async\http11.py", line 81, in handle_async_request
    ) = await self._receive_response_headers(**kwargs)
        ^^^^^^^^^^^^^^^^^^^^^^^^^^^^^^^^^^^^^^^^^^^^^^
  File "C:\Users\brenopoubel\AppData\Roaming\Python\Python312\site-packages\httpcore\_async\http11.py", line 143, in _receive_response_headers
    event = await self._receive_event(timeout=timeout)
            ^^^^^^^^^^^^^^^^^^^^^^^^^^^^^^^^^^^^^^^^^^
  File "C:\Users\brenopoubel\AppData\Roaming\Python\Python312\site-packages\httpcore\_async\http11.py", line 172, in _receive_event
    data = await self._network_stream.read(
           ^^^^^^^^^^^^^^^^^^^^^^^^^^^^^^^^
  File "C:\Users\brenopoubel\AppData\Roaming\Python\Python312\site-packages\httpcore\backends\asyncio.py", line 28, in read
    with map_exceptions(exc_map):
  File "C:\Program Files\Python312\Lib\contextlib.py", line 158, in __exit__
    self.gen.throw(value)
  File "C:\Users\brenopoubel\AppData\Roaming\Python\Python312\site-packages\httpcore\_exceptions.py", line 12, in map_exceptions
    raise to_exc(exc)
httpcore.ReadTimeout

The above exception was the direct cause of the following exception:

Traceback (most recent call last):
  File "C:\Users\brenopoubel\My Drive\Monitors\pocketoption2\main.py", line 617, in broadcast
    current_stats = await get_statistics()
                    ^^^^^^^^^^^^^^^^^^^^^^
  File "C:\Users\brenopoubel\My Drive\Monitors\pocketoption2\main.py", line 468, in get_statistics
    await perform_login()
  File "C:\Users\brenopoubel\My Drive\Monitors\pocketoption2\main.py", line 526, in perform_login
    res = await core.session.get(url=core.home_link)
          ^^^^^^^^^^^^^^^^^^^^^^^^^^^^^^^^^^^^^^^^^^
  File "C:\Users\brenopoubel\AppData\Roaming\Python\Python312\site-packages\httpx\_client.py", line 1736, in get
    return await self.request(
           ^^^^^^^^^^^^^^^^^^^
  File "C:\Users\brenopoubel\AppData\Roaming\Python\Python312\site-packages\httpx\_client.py", line 1513, in request
    return await self.send(request, auth=auth, follow_redirects=follow_redirects)
           ^^^^^^^^^^^^^^^^^^^^^^^^^^^^^^^^^^^^^^^^^^^^^^^^^^^^^^^^^^^^^^^^^^^^^^
  File "C:\Users\brenopoubel\AppData\Roaming\Python\Python312\site-packages\httpx\_client.py", line 1600, in send
    response = await self._send_handling_auth(
               ^^^^^^^^^^^^^^^^^^^^^^^^^^^^^^^
  File "C:\Users\brenopoubel\AppData\Roaming\Python\Python312\site-packages\httpx\_client.py", line 1628, in _send_handling_auth
    response = await self._send_handling_redirects(
               ^^^^^^^^^^^^^^^^^^^^^^^^^^^^^^^^^^^^
  File "C:\Users\brenopoubel\AppData\Roaming\Python\Python312\site-packages\httpx\_client.py", line 1665, in _send_handling_redirects
    response = await self._send_single_request(request)
               ^^^^^^^^^^^^^^^^^^^^^^^^^^^^^^^^^^^^^^^^
  File "C:\Users\brenopoubel\AppData\Roaming\Python\Python312\site-packages\httpx\_client.py", line 1702, in _send_single_request
    response = await transport.handle_async_request(request)
               ^^^^^^^^^^^^^^^^^^^^^^^^^^^^^^^^^^^^^^^^^^^^^
  File "C:\Users\brenopoubel\AppData\Roaming\Python\Python312\site-packages\httpx\_transports\default.py", line 290, in handle_async_request
    with map_httpcore_exceptions():
  File "C:\Program Files\Python312\Lib\contextlib.py", line 158, in __exit__
    self.gen.throw(value)
  File "C:\Users\brenopoubel\AppData\Roaming\Python\Python312\site-packages\httpx\_transports\default.py", line 77, in map_httpcore_exceptions
    raise mapped_exc(message) from exc
httpx.ReadTimeout
2024-06-16 12:59:43,346 - pocketoption - DEBUG - Old Session expired!! Trying to login again..
2024-06-16 12:59:48,443 - pocketoption - ERROR - ERR_BROADCAST: 
Traceback (most recent call last):
  File "C:\Users\brenopoubel\AppData\Roaming\Python\Python312\site-packages\anyio\streams\tls.py", line 131, in _call_sslobject_method
    result = func(*args)
             ^^^^^^^^^^^
  File "C:\Program Files\Python312\Lib\ssl.py", line 859, in read
    v = self._sslobj.read(len)
        ^^^^^^^^^^^^^^^^^^^^^^
ssl.SSLWantReadError: The operation did not complete (read) (_ssl.c:2559)

During handling of the above exception, another exception occurred:

Traceback (most recent call last):
  File "C:\Users\brenopoubel\AppData\Roaming\Python\Python312\site-packages\httpcore\backends\asyncio.py", line 31, in read
    return await self._stream.receive(max_bytes=max_bytes)
           ^^^^^^^^^^^^^^^^^^^^^^^^^^^^^^^^^^^^^^^^^^^^^^^
  File "C:\Users\brenopoubel\AppData\Roaming\Python\Python312\site-packages\anyio\streams\tls.py", line 196, in receive
    data = await self._call_sslobject_method(self._ssl_object.read, max_bytes)
           ^^^^^^^^^^^^^^^^^^^^^^^^^^^^^^^^^^^^^^^^^^^^^^^^^^^^^^^^^^^^^^^^^^^
  File "C:\Users\brenopoubel\AppData\Roaming\Python\Python312\site-packages\anyio\streams\tls.py", line 138, in _call_sslobject_method
    data = await self.transport_stream.receive()
           ^^^^^^^^^^^^^^^^^^^^^^^^^^^^^^^^^^^^^
  File "C:\Users\brenopoubel\AppData\Roaming\Python\Python312\site-packages\anyio\_backends\_asyncio.py", line 1203, in receive
    await self._protocol.read_event.wait()
  File "C:\Program Files\Python312\Lib\asyncio\locks.py", line 212, in wait
    await fut
asyncio.exceptions.CancelledError

During handling of the above exception, another exception occurred:

Traceback (most recent call last):
  File "C:\Users\brenopoubel\AppData\Roaming\Python\Python312\site-packages\httpcore\_exceptions.py", line 8, in map_exceptions
    yield
  File "C:\Users\brenopoubel\AppData\Roaming\Python\Python312\site-packages\httpcore\backends\asyncio.py", line 29, in read
    with anyio.fail_after(timeout):
  File "C:\Users\brenopoubel\AppData\Roaming\Python\Python312\site-packages\anyio\_core\_tasks.py", line 119, in __exit__
    raise TimeoutError
TimeoutError

During handling of the above exception, another exception occurred:

Traceback (most recent call last):
  File "C:\Users\brenopoubel\AppData\Roaming\Python\Python312\site-packages\httpx\_transports\default.py", line 60, in map_httpcore_exceptions
    yield
  File "C:\Users\brenopoubel\AppData\Roaming\Python\Python312\site-packages\httpx\_transports\default.py", line 291, in handle_async_request
    resp = await self._pool.handle_async_request(req)
           ^^^^^^^^^^^^^^^^^^^^^^^^^^^^^^^^^^^^^^^^^^
  File "C:\Users\brenopoubel\AppData\Roaming\Python\Python312\site-packages\httpcore\_async\connection_pool.py", line 253, in handle_async_request
    raise exc
  File "C:\Users\brenopoubel\AppData\Roaming\Python\Python312\site-packages\httpcore\_async\connection_pool.py", line 237, in handle_async_request
    response = await connection.handle_async_request(request)
               ^^^^^^^^^^^^^^^^^^^^^^^^^^^^^^^^^^^^^^^^^^^^^^
  File "C:\Users\brenopoubel\AppData\Roaming\Python\Python312\site-packages\httpcore\_async\connection.py", line 90, in handle_async_request
    return await self._connection.handle_async_request(request)
           ^^^^^^^^^^^^^^^^^^^^^^^^^^^^^^^^^^^^^^^^^^^^^^^^^^^^
  File "C:\Users\brenopoubel\AppData\Roaming\Python\Python312\site-packages\httpcore\_async\http11.py", line 102, in handle_async_request
    raise exc
  File "C:\Users\brenopoubel\AppData\Roaming\Python\Python312\site-packages\httpcore\_async\http11.py", line 81, in handle_async_request
    ) = await self._receive_response_headers(**kwargs)
        ^^^^^^^^^^^^^^^^^^^^^^^^^^^^^^^^^^^^^^^^^^^^^^
  File "C:\Users\brenopoubel\AppData\Roaming\Python\Python312\site-packages\httpcore\_async\http11.py", line 143, in _receive_response_headers
    event = await self._receive_event(timeout=timeout)
            ^^^^^^^^^^^^^^^^^^^^^^^^^^^^^^^^^^^^^^^^^^
  File "C:\Users\brenopoubel\AppData\Roaming\Python\Python312\site-packages\httpcore\_async\http11.py", line 172, in _receive_event
    data = await self._network_stream.read(
           ^^^^^^^^^^^^^^^^^^^^^^^^^^^^^^^^
  File "C:\Users\brenopoubel\AppData\Roaming\Python\Python312\site-packages\httpcore\backends\asyncio.py", line 28, in read
    with map_exceptions(exc_map):
  File "C:\Program Files\Python312\Lib\contextlib.py", line 158, in __exit__
    self.gen.throw(value)
  File "C:\Users\brenopoubel\AppData\Roaming\Python\Python312\site-packages\httpcore\_exceptions.py", line 12, in map_exceptions
    raise to_exc(exc)
httpcore.ReadTimeout

The above exception was the direct cause of the following exception:

Traceback (most recent call last):
  File "C:\Users\brenopoubel\My Drive\Monitors\pocketoption2\main.py", line 617, in broadcast
    current_stats = await get_statistics()
                    ^^^^^^^^^^^^^^^^^^^^^^
  File "C:\Users\brenopoubel\My Drive\Monitors\pocketoption2\main.py", line 468, in get_statistics
    await perform_login()
  File "C:\Users\brenopoubel\My Drive\Monitors\pocketoption2\main.py", line 526, in perform_login
    res = await core.session.get(url=core.home_link)
          ^^^^^^^^^^^^^^^^^^^^^^^^^^^^^^^^^^^^^^^^^^
  File "C:\Users\brenopoubel\AppData\Roaming\Python\Python312\site-packages\httpx\_client.py", line 1736, in get
    return await self.request(
           ^^^^^^^^^^^^^^^^^^^
  File "C:\Users\brenopoubel\AppData\Roaming\Python\Python312\site-packages\httpx\_client.py", line 1513, in request
    return await self.send(request, auth=auth, follow_redirects=follow_redirects)
           ^^^^^^^^^^^^^^^^^^^^^^^^^^^^^^^^^^^^^^^^^^^^^^^^^^^^^^^^^^^^^^^^^^^^^^
  File "C:\Users\brenopoubel\AppData\Roaming\Python\Python312\site-packages\httpx\_client.py", line 1600, in send
    response = await self._send_handling_auth(
               ^^^^^^^^^^^^^^^^^^^^^^^^^^^^^^^
  File "C:\Users\brenopoubel\AppData\Roaming\Python\Python312\site-packages\httpx\_client.py", line 1628, in _send_handling_auth
    response = await self._send_handling_redirects(
               ^^^^^^^^^^^^^^^^^^^^^^^^^^^^^^^^^^^^
  File "C:\Users\brenopoubel\AppData\Roaming\Python\Python312\site-packages\httpx\_client.py", line 1665, in _send_handling_redirects
    response = await self._send_single_request(request)
               ^^^^^^^^^^^^^^^^^^^^^^^^^^^^^^^^^^^^^^^^
  File "C:\Users\brenopoubel\AppData\Roaming\Python\Python312\site-packages\httpx\_client.py", line 1702, in _send_single_request
    response = await transport.handle_async_request(request)
               ^^^^^^^^^^^^^^^^^^^^^^^^^^^^^^^^^^^^^^^^^^^^^
  File "C:\Users\brenopoubel\AppData\Roaming\Python\Python312\site-packages\httpx\_transports\default.py", line 290, in handle_async_request
    with map_httpcore_exceptions():
  File "C:\Program Files\Python312\Lib\contextlib.py", line 158, in __exit__
    self.gen.throw(value)
  File "C:\Users\brenopoubel\AppData\Roaming\Python\Python312\site-packages\httpx\_transports\default.py", line 77, in map_httpcore_exceptions
    raise mapped_exc(message) from exc
httpx.ReadTimeout
2024-06-16 12:59:59,450 - pocketoption - DEBUG - Old session worked fine.
2024-06-16 13:00:11,535 - pocketoption - ERROR - ERR_PROCESS_SUMMARY -> Period: Current week -> Error: 
Traceback (most recent call last):
  File "C:\Users\brenopoubel\AppData\Roaming\Python\Python312\site-packages\anyio\streams\tls.py", line 131, in _call_sslobject_method
    result = func(*args)
             ^^^^^^^^^^^
  File "C:\Program Files\Python312\Lib\ssl.py", line 859, in read
    v = self._sslobj.read(len)
        ^^^^^^^^^^^^^^^^^^^^^^
ssl.SSLWantReadError: The operation did not complete (read) (_ssl.c:2559)

During handling of the above exception, another exception occurred:

Traceback (most recent call last):
  File "C:\Users\brenopoubel\AppData\Roaming\Python\Python312\site-packages\httpcore\backends\asyncio.py", line 31, in read
    return await self._stream.receive(max_bytes=max_bytes)
           ^^^^^^^^^^^^^^^^^^^^^^^^^^^^^^^^^^^^^^^^^^^^^^^
  File "C:\Users\brenopoubel\AppData\Roaming\Python\Python312\site-packages\anyio\streams\tls.py", line 196, in receive
    data = await self._call_sslobject_method(self._ssl_object.read, max_bytes)
           ^^^^^^^^^^^^^^^^^^^^^^^^^^^^^^^^^^^^^^^^^^^^^^^^^^^^^^^^^^^^^^^^^^^
  File "C:\Users\brenopoubel\AppData\Roaming\Python\Python312\site-packages\anyio\streams\tls.py", line 138, in _call_sslobject_method
    data = await self.transport_stream.receive()
           ^^^^^^^^^^^^^^^^^^^^^^^^^^^^^^^^^^^^^
  File "C:\Users\brenopoubel\AppData\Roaming\Python\Python312\site-packages\anyio\_backends\_asyncio.py", line 1203, in receive
    await self._protocol.read_event.wait()
  File "C:\Program Files\Python312\Lib\asyncio\locks.py", line 212, in wait
    await fut
asyncio.exceptions.CancelledError

During handling of the above exception, another exception occurred:

Traceback (most recent call last):
  File "C:\Users\brenopoubel\AppData\Roaming\Python\Python312\site-packages\httpcore\_exceptions.py", line 8, in map_exceptions
    yield
  File "C:\Users\brenopoubel\AppData\Roaming\Python\Python312\site-packages\httpcore\backends\asyncio.py", line 29, in read
    with anyio.fail_after(timeout):
  File "C:\Users\brenopoubel\AppData\Roaming\Python\Python312\site-packages\anyio\_core\_tasks.py", line 119, in __exit__
    raise TimeoutError
TimeoutError

During handling of the above exception, another exception occurred:

Traceback (most recent call last):
  File "C:\Users\brenopoubel\AppData\Roaming\Python\Python312\site-packages\httpx\_transports\default.py", line 60, in map_httpcore_exceptions
    yield
  File "C:\Users\brenopoubel\AppData\Roaming\Python\Python312\site-packages\httpx\_transports\default.py", line 291, in handle_async_request
    resp = await self._pool.handle_async_request(req)
           ^^^^^^^^^^^^^^^^^^^^^^^^^^^^^^^^^^^^^^^^^^
  File "C:\Users\brenopoubel\AppData\Roaming\Python\Python312\site-packages\httpcore\_async\connection_pool.py", line 253, in handle_async_request
    raise exc
  File "C:\Users\brenopoubel\AppData\Roaming\Python\Python312\site-packages\httpcore\_async\connection_pool.py", line 237, in handle_async_request
    response = await connection.handle_async_request(request)
               ^^^^^^^^^^^^^^^^^^^^^^^^^^^^^^^^^^^^^^^^^^^^^^
  File "C:\Users\brenopoubel\AppData\Roaming\Python\Python312\site-packages\httpcore\_async\connection.py", line 90, in handle_async_request
    return await self._connection.handle_async_request(request)
           ^^^^^^^^^^^^^^^^^^^^^^^^^^^^^^^^^^^^^^^^^^^^^^^^^^^^
  File "C:\Users\brenopoubel\AppData\Roaming\Python\Python312\site-packages\httpcore\_async\http11.py", line 102, in handle_async_request
    raise exc
  File "C:\Users\brenopoubel\AppData\Roaming\Python\Python312\site-packages\httpcore\_async\http11.py", line 81, in handle_async_request
    ) = await self._receive_response_headers(**kwargs)
        ^^^^^^^^^^^^^^^^^^^^^^^^^^^^^^^^^^^^^^^^^^^^^^
  File "C:\Users\brenopoubel\AppData\Roaming\Python\Python312\site-packages\httpcore\_async\http11.py", line 143, in _receive_response_headers
    event = await self._receive_event(timeout=timeout)
            ^^^^^^^^^^^^^^^^^^^^^^^^^^^^^^^^^^^^^^^^^^
  File "C:\Users\brenopoubel\AppData\Roaming\Python\Python312\site-packages\httpcore\_async\http11.py", line 172, in _receive_event
    data = await self._network_stream.read(
           ^^^^^^^^^^^^^^^^^^^^^^^^^^^^^^^^
  File "C:\Users\brenopoubel\AppData\Roaming\Python\Python312\site-packages\httpcore\backends\asyncio.py", line 28, in read
    with map_exceptions(exc_map):
  File "C:\Program Files\Python312\Lib\contextlib.py", line 158, in __exit__
    self.gen.throw(value)
  File "C:\Users\brenopoubel\AppData\Roaming\Python\Python312\site-packages\httpcore\_exceptions.py", line 12, in map_exceptions
    raise to_exc(exc)
httpcore.ReadTimeout

The above exception was the direct cause of the following exception:

Traceback (most recent call last):
  File "C:\Users\brenopoubel\My Drive\Monitors\pocketoption2\main.py", line 174, in process_statistics
    res_statistics = await fetch(
                     ^^^^^^^^^^^^
  File "C:\Users\brenopoubel\My Drive\Monitors\pocketoption2\main.py", line 79, in fetch
    return await core.session.get(url, **kwargs)
           ^^^^^^^^^^^^^^^^^^^^^^^^^^^^^^^^^^^^^
  File "C:\Users\brenopoubel\AppData\Roaming\Python\Python312\site-packages\httpx\_client.py", line 1736, in get
    return await self.request(
           ^^^^^^^^^^^^^^^^^^^
  File "C:\Users\brenopoubel\AppData\Roaming\Python\Python312\site-packages\httpx\_client.py", line 1513, in request
    return await self.send(request, auth=auth, follow_redirects=follow_redirects)
           ^^^^^^^^^^^^^^^^^^^^^^^^^^^^^^^^^^^^^^^^^^^^^^^^^^^^^^^^^^^^^^^^^^^^^^
  File "C:\Users\brenopoubel\AppData\Roaming\Python\Python312\site-packages\httpx\_client.py", line 1600, in send
    response = await self._send_handling_auth(
               ^^^^^^^^^^^^^^^^^^^^^^^^^^^^^^^
  File "C:\Users\brenopoubel\AppData\Roaming\Python\Python312\site-packages\httpx\_client.py", line 1628, in _send_handling_auth
    response = await self._send_handling_redirects(
               ^^^^^^^^^^^^^^^^^^^^^^^^^^^^^^^^^^^^
  File "C:\Users\brenopoubel\AppData\Roaming\Python\Python312\site-packages\httpx\_client.py", line 1665, in _send_handling_redirects
    response = await self._send_single_request(request)
               ^^^^^^^^^^^^^^^^^^^^^^^^^^^^^^^^^^^^^^^^
  File "C:\Users\brenopoubel\AppData\Roaming\Python\Python312\site-packages\httpx\_client.py", line 1702, in _send_single_request
    response = await transport.handle_async_request(request)
               ^^^^^^^^^^^^^^^^^^^^^^^^^^^^^^^^^^^^^^^^^^^^^
  File "C:\Users\brenopoubel\AppData\Roaming\Python\Python312\site-packages\httpx\_transports\default.py", line 290, in handle_async_request
    with map_httpcore_exceptions():
  File "C:\Program Files\Python312\Lib\contextlib.py", line 158, in __exit__
    self.gen.throw(value)
  File "C:\Users\brenopoubel\AppData\Roaming\Python\Python312\site-packages\httpx\_transports\default.py", line 77, in map_httpcore_exceptions
    raise mapped_exc(message) from exc
httpx.ReadTimeout

During handling of the above exception, another exception occurred:

Traceback (most recent call last):
  File "C:\Users\brenopoubel\AppData\Roaming\Python\Python312\site-packages\anyio\streams\tls.py", line 131, in _call_sslobject_method
    result = func(*args)
             ^^^^^^^^^^^
  File "C:\Program Files\Python312\Lib\ssl.py", line 859, in read
    v = self._sslobj.read(len)
        ^^^^^^^^^^^^^^^^^^^^^^
ssl.SSLWantReadError: The operation did not complete (read) (_ssl.c:2559)

During handling of the above exception, another exception occurred:

Traceback (most recent call last):
  File "C:\Users\brenopoubel\AppData\Roaming\Python\Python312\site-packages\httpcore\backends\asyncio.py", line 31, in read
    return await self._stream.receive(max_bytes=max_bytes)
           ^^^^^^^^^^^^^^^^^^^^^^^^^^^^^^^^^^^^^^^^^^^^^^^
  File "C:\Users\brenopoubel\AppData\Roaming\Python\Python312\site-packages\anyio\streams\tls.py", line 196, in receive
    data = await self._call_sslobject_method(self._ssl_object.read, max_bytes)
           ^^^^^^^^^^^^^^^^^^^^^^^^^^^^^^^^^^^^^^^^^^^^^^^^^^^^^^^^^^^^^^^^^^^
  File "C:\Users\brenopoubel\AppData\Roaming\Python\Python312\site-packages\anyio\streams\tls.py", line 138, in _call_sslobject_method
    data = await self.transport_stream.receive()
           ^^^^^^^^^^^^^^^^^^^^^^^^^^^^^^^^^^^^^
  File "C:\Users\brenopoubel\AppData\Roaming\Python\Python312\site-packages\anyio\_backends\_asyncio.py", line 1203, in receive
    await self._protocol.read_event.wait()
  File "C:\Program Files\Python312\Lib\asyncio\locks.py", line 212, in wait
    await fut
asyncio.exceptions.CancelledError

During handling of the above exception, another exception occurred:

Traceback (most recent call last):
  File "C:\Users\brenopoubel\AppData\Roaming\Python\Python312\site-packages\httpcore\_exceptions.py", line 8, in map_exceptions
    yield
  File "C:\Users\brenopoubel\AppData\Roaming\Python\Python312\site-packages\httpcore\backends\asyncio.py", line 29, in read
    with anyio.fail_after(timeout):
  File "C:\Users\brenopoubel\AppData\Roaming\Python\Python312\site-packages\anyio\_core\_tasks.py", line 119, in __exit__
    raise TimeoutError
TimeoutError

During handling of the above exception, another exception occurred:

Traceback (most recent call last):
  File "C:\Users\brenopoubel\AppData\Roaming\Python\Python312\site-packages\httpx\_transports\default.py", line 60, in map_httpcore_exceptions
    yield
  File "C:\Users\brenopoubel\AppData\Roaming\Python\Python312\site-packages\httpx\_transports\default.py", line 291, in handle_async_request
    resp = await self._pool.handle_async_request(req)
           ^^^^^^^^^^^^^^^^^^^^^^^^^^^^^^^^^^^^^^^^^^
  File "C:\Users\brenopoubel\AppData\Roaming\Python\Python312\site-packages\httpcore\_async\connection_pool.py", line 253, in handle_async_request
    raise exc
  File "C:\Users\brenopoubel\AppData\Roaming\Python\Python312\site-packages\httpcore\_async\connection_pool.py", line 237, in handle_async_request
    response = await connection.handle_async_request(request)
               ^^^^^^^^^^^^^^^^^^^^^^^^^^^^^^^^^^^^^^^^^^^^^^
  File "C:\Users\brenopoubel\AppData\Roaming\Python\Python312\site-packages\httpcore\_async\connection.py", line 90, in handle_async_request
    return await self._connection.handle_async_request(request)
           ^^^^^^^^^^^^^^^^^^^^^^^^^^^^^^^^^^^^^^^^^^^^^^^^^^^^
  File "C:\Users\brenopoubel\AppData\Roaming\Python\Python312\site-packages\httpcore\_async\http11.py", line 102, in handle_async_request
    raise exc
  File "C:\Users\brenopoubel\AppData\Roaming\Python\Python312\site-packages\httpcore\_async\http11.py", line 81, in handle_async_request
    ) = await self._receive_response_headers(**kwargs)
        ^^^^^^^^^^^^^^^^^^^^^^^^^^^^^^^^^^^^^^^^^^^^^^
  File "C:\Users\brenopoubel\AppData\Roaming\Python\Python312\site-packages\httpcore\_async\http11.py", line 143, in _receive_response_headers
    event = await self._receive_event(timeout=timeout)
            ^^^^^^^^^^^^^^^^^^^^^^^^^^^^^^^^^^^^^^^^^^
  File "C:\Users\brenopoubel\AppData\Roaming\Python\Python312\site-packages\httpcore\_async\http11.py", line 172, in _receive_event
    data = await self._network_stream.read(
           ^^^^^^^^^^^^^^^^^^^^^^^^^^^^^^^^
  File "C:\Users\brenopoubel\AppData\Roaming\Python\Python312\site-packages\httpcore\backends\asyncio.py", line 28, in read
    with map_exceptions(exc_map):
  File "C:\Program Files\Python312\Lib\contextlib.py", line 158, in __exit__
    self.gen.throw(value)
  File "C:\Users\brenopoubel\AppData\Roaming\Python\Python312\site-packages\httpcore\_exceptions.py", line 12, in map_exceptions
    raise to_exc(exc)
httpcore.ReadTimeout

The above exception was the direct cause of the following exception:

Traceback (most recent call last):
  File "C:\Users\brenopoubel\My Drive\Monitors\pocketoption2\main.py", line 174, in process_statistics
    res_statistics = await fetch(
                     ^^^^^^^^^^^^
  File "C:\Users\brenopoubel\My Drive\Monitors\pocketoption2\main.py", line 79, in fetch
    return await core.session.get(url, **kwargs)
           ^^^^^^^^^^^^^^^^^^^^^^^^^^^^^^^^^^^^^
  File "C:\Users\brenopoubel\AppData\Roaming\Python\Python312\site-packages\httpx\_client.py", line 1736, in get
    return await self.request(
           ^^^^^^^^^^^^^^^^^^^
  File "C:\Users\brenopoubel\AppData\Roaming\Python\Python312\site-packages\httpx\_client.py", line 1513, in request
    return await self.send(request, auth=auth, follow_redirects=follow_redirects)
           ^^^^^^^^^^^^^^^^^^^^^^^^^^^^^^^^^^^^^^^^^^^^^^^^^^^^^^^^^^^^^^^^^^^^^^
  File "C:\Users\brenopoubel\AppData\Roaming\Python\Python312\site-packages\httpx\_client.py", line 1600, in send
    response = await self._send_handling_auth(
               ^^^^^^^^^^^^^^^^^^^^^^^^^^^^^^^
  File "C:\Users\brenopoubel\AppData\Roaming\Python\Python312\site-packages\httpx\_client.py", line 1628, in _send_handling_auth
    response = await self._send_handling_redirects(
               ^^^^^^^^^^^^^^^^^^^^^^^^^^^^^^^^^^^^
  File "C:\Users\brenopoubel\AppData\Roaming\Python\Python312\site-packages\httpx\_client.py", line 1665, in _send_handling_redirects
    response = await self._send_single_request(request)
               ^^^^^^^^^^^^^^^^^^^^^^^^^^^^^^^^^^^^^^^^
  File "C:\Users\brenopoubel\AppData\Roaming\Python\Python312\site-packages\httpx\_client.py", line 1702, in _send_single_request
    response = await transport.handle_async_request(request)
               ^^^^^^^^^^^^^^^^^^^^^^^^^^^^^^^^^^^^^^^^^^^^^
  File "C:\Users\brenopoubel\AppData\Roaming\Python\Python312\site-packages\httpx\_transports\default.py", line 290, in handle_async_request
    with map_httpcore_exceptions():
  File "C:\Program Files\Python312\Lib\contextlib.py", line 158, in __exit__
    self.gen.throw(value)
  File "C:\Users\brenopoubel\AppData\Roaming\Python\Python312\site-packages\httpx\_transports\default.py", line 77, in map_httpcore_exceptions
    raise mapped_exc(message) from exc
httpx.ReadTimeout
2024-06-16 13:00:11,550 - pocketoption - DEBUG - Total time taken to perform the task: 22.11 seconds
2024-06-16 13:00:16,819 - pocketoption - DEBUG - Old session worked fine.
2024-06-16 13:00:18,428 - pocketoption - DEBUG - Processed -> Statistics -> Current week
2024-06-16 13:00:18,428 - pocketoption - DEBUG - Total time taken to perform the task: 5.86 seconds
2024-06-16 13:01:01,957 - pocketoption - DEBUG - First Check -> Latest ID: 164123 | Existing ID: 164123
2024-06-16 13:01:02,582 - pocketoption - DEBUG - Balance -> -936 -> Not enough for Withdrawal
2024-06-16 13:01:02,582 - pocketoption - DEBUG - Bonus -> 0.0 -> Not enough for Withdrawal
2024-06-16 13:01:03,505 - pocketoption - DEBUG - Second Check -> Latest ID: 164123 | Existing ID: 164123
2024-06-16 13:59:02,346 - pocketoption - DEBUG - Old session worked fine.
2024-06-16 13:59:04,066 - pocketoption - DEBUG - Processed -> Statistics -> Current week
2024-06-16 13:59:04,066 - pocketoption - DEBUG - Total time taken to perform the task: 3.1 seconds
2024-06-16 14:00:00,585 - pocketoption - DEBUG - No change detected!!
2024-06-16 14:01:02,310 - pocketoption - DEBUG - First Check -> Latest ID: 164123 | Existing ID: 164123
2024-06-16 14:01:02,982 - pocketoption - DEBUG - Balance -> -936 -> Not enough for Withdrawal
2024-06-16 14:01:02,982 - pocketoption - DEBUG - Bonus -> 0.0 -> Not enough for Withdrawal
2024-06-16 14:01:03,983 - pocketoption - DEBUG - Second Check -> Latest ID: 164123 | Existing ID: 164123
2024-06-16 14:59:01,778 - pocketoption - DEBUG - Old session worked fine.
2024-06-16 14:59:03,484 - pocketoption - DEBUG - Processed -> Statistics -> Current week
2024-06-16 14:59:03,499 - pocketoption - DEBUG - Total time taken to perform the task: 3.14 seconds
2024-06-16 15:00:00,001 - pocketoption - DEBUG - No change detected!!
2024-06-16 15:01:02,442 - pocketoption - DEBUG - First Check -> Latest ID: 164123 | Existing ID: 164123
2024-06-16 15:01:03,068 - pocketoption - DEBUG - Balance -> -936 -> Not enough for Withdrawal
2024-06-16 15:01:03,068 - pocketoption - DEBUG - Bonus -> 0.0 -> Not enough for Withdrawal
2024-06-16 15:01:03,977 - pocketoption - DEBUG - Second Check -> Latest ID: 164123 | Existing ID: 164123
2024-06-16 15:59:01,789 - pocketoption - DEBUG - Old session worked fine.
2024-06-16 15:59:03,164 - pocketoption - DEBUG - Processed -> Statistics -> Current week
2024-06-16 15:59:03,164 - pocketoption - DEBUG - Total time taken to perform the task: 2.8 seconds
2024-06-16 16:00:00,856 - pocketoption - DEBUG - No change detected!!
2024-06-16 16:01:03,008 - pocketoption - DEBUG - First Check -> Latest ID: 164123 | Existing ID: 164123
2024-06-16 16:01:04,119 - pocketoption - DEBUG - Balance -> -936 -> Not enough for Withdrawal
2024-06-16 16:01:04,119 - pocketoption - DEBUG - Bonus -> 0.0 -> Not enough for Withdrawal
2024-06-16 16:01:05,152 - pocketoption - DEBUG - Second Check -> Latest ID: 164123 | Existing ID: 164123
2024-06-16 16:59:02,836 - pocketoption - DEBUG - Old session worked fine.
2024-06-16 16:59:04,681 - pocketoption - DEBUG - Processed -> Statistics -> Current week
2024-06-16 16:59:04,681 - pocketoption - DEBUG - Total time taken to perform the task: 4.08 seconds
2024-06-16 17:00:00,905 - pocketoption - INFO - Target [ID:610323477]: success
2024-06-16 17:00:01,218 - pocketoption - INFO - Target [ID:1838317981]: success
2024-06-16 17:01:01,894 - pocketoption - DEBUG - First Check -> Latest ID: 164123 | Existing ID: 164123
2024-06-16 17:01:02,472 - pocketoption - DEBUG - Balance -> -936 -> Not enough for Withdrawal
2024-06-16 17:01:02,472 - pocketoption - DEBUG - Bonus -> 0.0 -> Not enough for Withdrawal
2024-06-16 17:01:03,396 - pocketoption - DEBUG - Second Check -> Latest ID: 164123 | Existing ID: 164123
2024-06-16 17:59:02,247 - pocketoption - DEBUG - Old session worked fine.
2024-06-16 17:59:03,279 - pocketoption - DEBUG - Processed -> Statistics -> Current week
2024-06-16 17:59:03,279 - pocketoption - DEBUG - Total time taken to perform the task: 2.99 seconds
2024-06-16 18:00:01,327 - pocketoption - INFO - Target [ID:610323477]: success
2024-06-16 18:00:01,592 - pocketoption - INFO - Target [ID:1838317981]: success
2024-06-16 18:01:05,111 - pocketoption - ERROR - ERR_GET_LATEST_PAYMENT_REQUEST: 164123
Traceback (most recent call last):
  File "C:\Users\brenopoubel\AppData\Roaming\Python\Python312\site-packages\anyio\streams\tls.py", line 131, in _call_sslobject_method
    result = func(*args)
             ^^^^^^^^^^^
  File "C:\Program Files\Python312\Lib\ssl.py", line 859, in read
    v = self._sslobj.read(len)
        ^^^^^^^^^^^^^^^^^^^^^^
ssl.SSLWantReadError: The operation did not complete (read) (_ssl.c:2559)

During handling of the above exception, another exception occurred:

Traceback (most recent call last):
  File "C:\Users\brenopoubel\AppData\Roaming\Python\Python312\site-packages\httpcore\backends\asyncio.py", line 31, in read
    return await self._stream.receive(max_bytes=max_bytes)
           ^^^^^^^^^^^^^^^^^^^^^^^^^^^^^^^^^^^^^^^^^^^^^^^
  File "C:\Users\brenopoubel\AppData\Roaming\Python\Python312\site-packages\anyio\streams\tls.py", line 196, in receive
    data = await self._call_sslobject_method(self._ssl_object.read, max_bytes)
           ^^^^^^^^^^^^^^^^^^^^^^^^^^^^^^^^^^^^^^^^^^^^^^^^^^^^^^^^^^^^^^^^^^^
  File "C:\Users\brenopoubel\AppData\Roaming\Python\Python312\site-packages\anyio\streams\tls.py", line 138, in _call_sslobject_method
    data = await self.transport_stream.receive()
           ^^^^^^^^^^^^^^^^^^^^^^^^^^^^^^^^^^^^^
  File "C:\Users\brenopoubel\AppData\Roaming\Python\Python312\site-packages\anyio\_backends\_asyncio.py", line 1203, in receive
    await self._protocol.read_event.wait()
  File "C:\Program Files\Python312\Lib\asyncio\locks.py", line 212, in wait
    await fut
asyncio.exceptions.CancelledError

During handling of the above exception, another exception occurred:

Traceback (most recent call last):
  File "C:\Users\brenopoubel\AppData\Roaming\Python\Python312\site-packages\httpcore\_exceptions.py", line 8, in map_exceptions
    yield
  File "C:\Users\brenopoubel\AppData\Roaming\Python\Python312\site-packages\httpcore\backends\asyncio.py", line 29, in read
    with anyio.fail_after(timeout):
  File "C:\Users\brenopoubel\AppData\Roaming\Python\Python312\site-packages\anyio\_core\_tasks.py", line 119, in __exit__
    raise TimeoutError
TimeoutError

During handling of the above exception, another exception occurred:

Traceback (most recent call last):
  File "C:\Users\brenopoubel\AppData\Roaming\Python\Python312\site-packages\httpx\_transports\default.py", line 60, in map_httpcore_exceptions
    yield
  File "C:\Users\brenopoubel\AppData\Roaming\Python\Python312\site-packages\httpx\_transports\default.py", line 291, in handle_async_request
    resp = await self._pool.handle_async_request(req)
           ^^^^^^^^^^^^^^^^^^^^^^^^^^^^^^^^^^^^^^^^^^
  File "C:\Users\brenopoubel\AppData\Roaming\Python\Python312\site-packages\httpcore\_async\connection_pool.py", line 253, in handle_async_request
    raise exc
  File "C:\Users\brenopoubel\AppData\Roaming\Python\Python312\site-packages\httpcore\_async\connection_pool.py", line 237, in handle_async_request
    response = await connection.handle_async_request(request)
               ^^^^^^^^^^^^^^^^^^^^^^^^^^^^^^^^^^^^^^^^^^^^^^
  File "C:\Users\brenopoubel\AppData\Roaming\Python\Python312\site-packages\httpcore\_async\connection.py", line 90, in handle_async_request
    return await self._connection.handle_async_request(request)
           ^^^^^^^^^^^^^^^^^^^^^^^^^^^^^^^^^^^^^^^^^^^^^^^^^^^^
  File "C:\Users\brenopoubel\AppData\Roaming\Python\Python312\site-packages\httpcore\_async\http11.py", line 102, in handle_async_request
    raise exc
  File "C:\Users\brenopoubel\AppData\Roaming\Python\Python312\site-packages\httpcore\_async\http11.py", line 81, in handle_async_request
    ) = await self._receive_response_headers(**kwargs)
        ^^^^^^^^^^^^^^^^^^^^^^^^^^^^^^^^^^^^^^^^^^^^^^
  File "C:\Users\brenopoubel\AppData\Roaming\Python\Python312\site-packages\httpcore\_async\http11.py", line 143, in _receive_response_headers
    event = await self._receive_event(timeout=timeout)
            ^^^^^^^^^^^^^^^^^^^^^^^^^^^^^^^^^^^^^^^^^^
  File "C:\Users\brenopoubel\AppData\Roaming\Python\Python312\site-packages\httpcore\_async\http11.py", line 172, in _receive_event
    data = await self._network_stream.read(
           ^^^^^^^^^^^^^^^^^^^^^^^^^^^^^^^^
  File "C:\Users\brenopoubel\AppData\Roaming\Python\Python312\site-packages\httpcore\backends\asyncio.py", line 28, in read
    with map_exceptions(exc_map):
  File "C:\Program Files\Python312\Lib\contextlib.py", line 158, in __exit__
    self.gen.throw(value)
  File "C:\Users\brenopoubel\AppData\Roaming\Python\Python312\site-packages\httpcore\_exceptions.py", line 12, in map_exceptions
    raise to_exc(exc)
httpcore.ReadTimeout

The above exception was the direct cause of the following exception:

Traceback (most recent call last):
  File "C:\Users\brenopoubel\My Drive\Monitors\pocketoption2\main.py", line 757, in get_latest_payment_requests
    res = await fetch(core.payment_history_link)
          ^^^^^^^^^^^^^^^^^^^^^^^^^^^^^^^^^^^^^^
  File "C:\Users\brenopoubel\My Drive\Monitors\pocketoption2\main.py", line 79, in fetch
    return await core.session.get(url, **kwargs)
           ^^^^^^^^^^^^^^^^^^^^^^^^^^^^^^^^^^^^^
  File "C:\Users\brenopoubel\AppData\Roaming\Python\Python312\site-packages\httpx\_client.py", line 1736, in get
    return await self.request(
           ^^^^^^^^^^^^^^^^^^^
  File "C:\Users\brenopoubel\AppData\Roaming\Python\Python312\site-packages\httpx\_client.py", line 1513, in request
    return await self.send(request, auth=auth, follow_redirects=follow_redirects)
           ^^^^^^^^^^^^^^^^^^^^^^^^^^^^^^^^^^^^^^^^^^^^^^^^^^^^^^^^^^^^^^^^^^^^^^
  File "C:\Users\brenopoubel\AppData\Roaming\Python\Python312\site-packages\httpx\_client.py", line 1600, in send
    response = await self._send_handling_auth(
               ^^^^^^^^^^^^^^^^^^^^^^^^^^^^^^^
  File "C:\Users\brenopoubel\AppData\Roaming\Python\Python312\site-packages\httpx\_client.py", line 1628, in _send_handling_auth
    response = await self._send_handling_redirects(
               ^^^^^^^^^^^^^^^^^^^^^^^^^^^^^^^^^^^^
  File "C:\Users\brenopoubel\AppData\Roaming\Python\Python312\site-packages\httpx\_client.py", line 1665, in _send_handling_redirects
    response = await self._send_single_request(request)
               ^^^^^^^^^^^^^^^^^^^^^^^^^^^^^^^^^^^^^^^^
  File "C:\Users\brenopoubel\AppData\Roaming\Python\Python312\site-packages\httpx\_client.py", line 1702, in _send_single_request
    response = await transport.handle_async_request(request)
               ^^^^^^^^^^^^^^^^^^^^^^^^^^^^^^^^^^^^^^^^^^^^^
  File "C:\Users\brenopoubel\AppData\Roaming\Python\Python312\site-packages\httpx\_transports\default.py", line 290, in handle_async_request
    with map_httpcore_exceptions():
  File "C:\Program Files\Python312\Lib\contextlib.py", line 158, in __exit__
    self.gen.throw(value)
  File "C:\Users\brenopoubel\AppData\Roaming\Python\Python312\site-packages\httpx\_transports\default.py", line 77, in map_httpcore_exceptions
    raise mapped_exc(message) from exc
httpx.ReadTimeout
2024-06-16 18:01:05,204 - pocketoption - DEBUG - First Check -> Latest ID: 164123 | Existing ID: 164123
2024-06-16 18:01:17,384 - pocketoption - ERROR - ERR_PROCESS_SUMMARY -> Period: Current week -> Error: 
Traceback (most recent call last):
  File "C:\Users\brenopoubel\AppData\Roaming\Python\Python312\site-packages\anyio\streams\tls.py", line 131, in _call_sslobject_method
    result = func(*args)
             ^^^^^^^^^^^
  File "C:\Program Files\Python312\Lib\ssl.py", line 859, in read
    v = self._sslobj.read(len)
        ^^^^^^^^^^^^^^^^^^^^^^
ssl.SSLWantReadError: The operation did not complete (read) (_ssl.c:2559)

During handling of the above exception, another exception occurred:

Traceback (most recent call last):
  File "C:\Users\brenopoubel\AppData\Roaming\Python\Python312\site-packages\httpcore\backends\asyncio.py", line 31, in read
    return await self._stream.receive(max_bytes=max_bytes)
           ^^^^^^^^^^^^^^^^^^^^^^^^^^^^^^^^^^^^^^^^^^^^^^^
  File "C:\Users\brenopoubel\AppData\Roaming\Python\Python312\site-packages\anyio\streams\tls.py", line 196, in receive
    data = await self._call_sslobject_method(self._ssl_object.read, max_bytes)
           ^^^^^^^^^^^^^^^^^^^^^^^^^^^^^^^^^^^^^^^^^^^^^^^^^^^^^^^^^^^^^^^^^^^
  File "C:\Users\brenopoubel\AppData\Roaming\Python\Python312\site-packages\anyio\streams\tls.py", line 138, in _call_sslobject_method
    data = await self.transport_stream.receive()
           ^^^^^^^^^^^^^^^^^^^^^^^^^^^^^^^^^^^^^
  File "C:\Users\brenopoubel\AppData\Roaming\Python\Python312\site-packages\anyio\_backends\_asyncio.py", line 1203, in receive
    await self._protocol.read_event.wait()
  File "C:\Program Files\Python312\Lib\asyncio\locks.py", line 212, in wait
    await fut
asyncio.exceptions.CancelledError

During handling of the above exception, another exception occurred:

Traceback (most recent call last):
  File "C:\Users\brenopoubel\AppData\Roaming\Python\Python312\site-packages\httpcore\_exceptions.py", line 8, in map_exceptions
    yield
  File "C:\Users\brenopoubel\AppData\Roaming\Python\Python312\site-packages\httpcore\backends\asyncio.py", line 29, in read
    with anyio.fail_after(timeout):
  File "C:\Users\brenopoubel\AppData\Roaming\Python\Python312\site-packages\anyio\_core\_tasks.py", line 119, in __exit__
    raise TimeoutError
TimeoutError

During handling of the above exception, another exception occurred:

Traceback (most recent call last):
  File "C:\Users\brenopoubel\AppData\Roaming\Python\Python312\site-packages\httpx\_transports\default.py", line 60, in map_httpcore_exceptions
    yield
  File "C:\Users\brenopoubel\AppData\Roaming\Python\Python312\site-packages\httpx\_transports\default.py", line 291, in handle_async_request
    resp = await self._pool.handle_async_request(req)
           ^^^^^^^^^^^^^^^^^^^^^^^^^^^^^^^^^^^^^^^^^^
  File "C:\Users\brenopoubel\AppData\Roaming\Python\Python312\site-packages\httpcore\_async\connection_pool.py", line 253, in handle_async_request
    raise exc
  File "C:\Users\brenopoubel\AppData\Roaming\Python\Python312\site-packages\httpcore\_async\connection_pool.py", line 237, in handle_async_request
    response = await connection.handle_async_request(request)
               ^^^^^^^^^^^^^^^^^^^^^^^^^^^^^^^^^^^^^^^^^^^^^^
  File "C:\Users\brenopoubel\AppData\Roaming\Python\Python312\site-packages\httpcore\_async\connection.py", line 90, in handle_async_request
    return await self._connection.handle_async_request(request)
           ^^^^^^^^^^^^^^^^^^^^^^^^^^^^^^^^^^^^^^^^^^^^^^^^^^^^
  File "C:\Users\brenopoubel\AppData\Roaming\Python\Python312\site-packages\httpcore\_async\http11.py", line 102, in handle_async_request
    raise exc
  File "C:\Users\brenopoubel\AppData\Roaming\Python\Python312\site-packages\httpcore\_async\http11.py", line 81, in handle_async_request
    ) = await self._receive_response_headers(**kwargs)
        ^^^^^^^^^^^^^^^^^^^^^^^^^^^^^^^^^^^^^^^^^^^^^^
  File "C:\Users\brenopoubel\AppData\Roaming\Python\Python312\site-packages\httpcore\_async\http11.py", line 143, in _receive_response_headers
    event = await self._receive_event(timeout=timeout)
            ^^^^^^^^^^^^^^^^^^^^^^^^^^^^^^^^^^^^^^^^^^
  File "C:\Users\brenopoubel\AppData\Roaming\Python\Python312\site-packages\httpcore\_async\http11.py", line 172, in _receive_event
    data = await self._network_stream.read(
           ^^^^^^^^^^^^^^^^^^^^^^^^^^^^^^^^
  File "C:\Users\brenopoubel\AppData\Roaming\Python\Python312\site-packages\httpcore\backends\asyncio.py", line 28, in read
    with map_exceptions(exc_map):
  File "C:\Program Files\Python312\Lib\contextlib.py", line 158, in __exit__
    self.gen.throw(value)
  File "C:\Users\brenopoubel\AppData\Roaming\Python\Python312\site-packages\httpcore\_exceptions.py", line 12, in map_exceptions
    raise to_exc(exc)
httpcore.ReadTimeout

The above exception was the direct cause of the following exception:

Traceback (most recent call last):
  File "C:\Users\brenopoubel\My Drive\Monitors\pocketoption2\main.py", line 174, in process_statistics
    res_statistics = await fetch(
                     ^^^^^^^^^^^^
  File "C:\Users\brenopoubel\My Drive\Monitors\pocketoption2\main.py", line 79, in fetch
    return await core.session.get(url, **kwargs)
           ^^^^^^^^^^^^^^^^^^^^^^^^^^^^^^^^^^^^^
  File "C:\Users\brenopoubel\AppData\Roaming\Python\Python312\site-packages\httpx\_client.py", line 1736, in get
    return await self.request(
           ^^^^^^^^^^^^^^^^^^^
  File "C:\Users\brenopoubel\AppData\Roaming\Python\Python312\site-packages\httpx\_client.py", line 1513, in request
    return await self.send(request, auth=auth, follow_redirects=follow_redirects)
           ^^^^^^^^^^^^^^^^^^^^^^^^^^^^^^^^^^^^^^^^^^^^^^^^^^^^^^^^^^^^^^^^^^^^^^
  File "C:\Users\brenopoubel\AppData\Roaming\Python\Python312\site-packages\httpx\_client.py", line 1600, in send
    response = await self._send_handling_auth(
               ^^^^^^^^^^^^^^^^^^^^^^^^^^^^^^^
  File "C:\Users\brenopoubel\AppData\Roaming\Python\Python312\site-packages\httpx\_client.py", line 1628, in _send_handling_auth
    response = await self._send_handling_redirects(
               ^^^^^^^^^^^^^^^^^^^^^^^^^^^^^^^^^^^^
  File "C:\Users\brenopoubel\AppData\Roaming\Python\Python312\site-packages\httpx\_client.py", line 1665, in _send_handling_redirects
    response = await self._send_single_request(request)
               ^^^^^^^^^^^^^^^^^^^^^^^^^^^^^^^^^^^^^^^^
  File "C:\Users\brenopoubel\AppData\Roaming\Python\Python312\site-packages\httpx\_client.py", line 1702, in _send_single_request
    response = await transport.handle_async_request(request)
               ^^^^^^^^^^^^^^^^^^^^^^^^^^^^^^^^^^^^^^^^^^^^^
  File "C:\Users\brenopoubel\AppData\Roaming\Python\Python312\site-packages\httpx\_transports\default.py", line 290, in handle_async_request
    with map_httpcore_exceptions():
  File "C:\Program Files\Python312\Lib\contextlib.py", line 158, in __exit__
    self.gen.throw(value)
  File "C:\Users\brenopoubel\AppData\Roaming\Python\Python312\site-packages\httpx\_transports\default.py", line 77, in map_httpcore_exceptions
    raise mapped_exc(message) from exc
httpx.ReadTimeout

During handling of the above exception, another exception occurred:

Traceback (most recent call last):
  File "C:\Users\brenopoubel\AppData\Roaming\Python\Python312\site-packages\anyio\streams\tls.py", line 131, in _call_sslobject_method
    result = func(*args)
             ^^^^^^^^^^^
  File "C:\Program Files\Python312\Lib\ssl.py", line 859, in read
    v = self._sslobj.read(len)
        ^^^^^^^^^^^^^^^^^^^^^^
ssl.SSLWantReadError: The operation did not complete (read) (_ssl.c:2559)

During handling of the above exception, another exception occurred:

Traceback (most recent call last):
  File "C:\Users\brenopoubel\AppData\Roaming\Python\Python312\site-packages\httpcore\backends\asyncio.py", line 31, in read
    return await self._stream.receive(max_bytes=max_bytes)
           ^^^^^^^^^^^^^^^^^^^^^^^^^^^^^^^^^^^^^^^^^^^^^^^
  File "C:\Users\brenopoubel\AppData\Roaming\Python\Python312\site-packages\anyio\streams\tls.py", line 196, in receive
    data = await self._call_sslobject_method(self._ssl_object.read, max_bytes)
           ^^^^^^^^^^^^^^^^^^^^^^^^^^^^^^^^^^^^^^^^^^^^^^^^^^^^^^^^^^^^^^^^^^^
  File "C:\Users\brenopoubel\AppData\Roaming\Python\Python312\site-packages\anyio\streams\tls.py", line 138, in _call_sslobject_method
    data = await self.transport_stream.receive()
           ^^^^^^^^^^^^^^^^^^^^^^^^^^^^^^^^^^^^^
  File "C:\Users\brenopoubel\AppData\Roaming\Python\Python312\site-packages\anyio\_backends\_asyncio.py", line 1203, in receive
    await self._protocol.read_event.wait()
  File "C:\Program Files\Python312\Lib\asyncio\locks.py", line 212, in wait
    await fut
asyncio.exceptions.CancelledError

During handling of the above exception, another exception occurred:

Traceback (most recent call last):
  File "C:\Users\brenopoubel\AppData\Roaming\Python\Python312\site-packages\httpcore\_exceptions.py", line 8, in map_exceptions
    yield
  File "C:\Users\brenopoubel\AppData\Roaming\Python\Python312\site-packages\httpcore\backends\asyncio.py", line 29, in read
    with anyio.fail_after(timeout):
  File "C:\Users\brenopoubel\AppData\Roaming\Python\Python312\site-packages\anyio\_core\_tasks.py", line 119, in __exit__
    raise TimeoutError
TimeoutError

During handling of the above exception, another exception occurred:

Traceback (most recent call last):
  File "C:\Users\brenopoubel\AppData\Roaming\Python\Python312\site-packages\httpx\_transports\default.py", line 60, in map_httpcore_exceptions
    yield
  File "C:\Users\brenopoubel\AppData\Roaming\Python\Python312\site-packages\httpx\_transports\default.py", line 291, in handle_async_request
    resp = await self._pool.handle_async_request(req)
           ^^^^^^^^^^^^^^^^^^^^^^^^^^^^^^^^^^^^^^^^^^
  File "C:\Users\brenopoubel\AppData\Roaming\Python\Python312\site-packages\httpcore\_async\connection_pool.py", line 253, in handle_async_request
    raise exc
  File "C:\Users\brenopoubel\AppData\Roaming\Python\Python312\site-packages\httpcore\_async\connection_pool.py", line 237, in handle_async_request
    response = await connection.handle_async_request(request)
               ^^^^^^^^^^^^^^^^^^^^^^^^^^^^^^^^^^^^^^^^^^^^^^
  File "C:\Users\brenopoubel\AppData\Roaming\Python\Python312\site-packages\httpcore\_async\connection.py", line 90, in handle_async_request
    return await self._connection.handle_async_request(request)
           ^^^^^^^^^^^^^^^^^^^^^^^^^^^^^^^^^^^^^^^^^^^^^^^^^^^^
  File "C:\Users\brenopoubel\AppData\Roaming\Python\Python312\site-packages\httpcore\_async\http11.py", line 102, in handle_async_request
    raise exc
  File "C:\Users\brenopoubel\AppData\Roaming\Python\Python312\site-packages\httpcore\_async\http11.py", line 81, in handle_async_request
    ) = await self._receive_response_headers(**kwargs)
        ^^^^^^^^^^^^^^^^^^^^^^^^^^^^^^^^^^^^^^^^^^^^^^
  File "C:\Users\brenopoubel\AppData\Roaming\Python\Python312\site-packages\httpcore\_async\http11.py", line 143, in _receive_response_headers
    event = await self._receive_event(timeout=timeout)
            ^^^^^^^^^^^^^^^^^^^^^^^^^^^^^^^^^^^^^^^^^^
  File "C:\Users\brenopoubel\AppData\Roaming\Python\Python312\site-packages\httpcore\_async\http11.py", line 172, in _receive_event
    data = await self._network_stream.read(
           ^^^^^^^^^^^^^^^^^^^^^^^^^^^^^^^^
  File "C:\Users\brenopoubel\AppData\Roaming\Python\Python312\site-packages\httpcore\backends\asyncio.py", line 28, in read
    with map_exceptions(exc_map):
  File "C:\Program Files\Python312\Lib\contextlib.py", line 158, in __exit__
    self.gen.throw(value)
  File "C:\Users\brenopoubel\AppData\Roaming\Python\Python312\site-packages\httpcore\_exceptions.py", line 12, in map_exceptions
    raise to_exc(exc)
httpcore.ReadTimeout

The above exception was the direct cause of the following exception:

Traceback (most recent call last):
  File "C:\Users\brenopoubel\My Drive\Monitors\pocketoption2\main.py", line 174, in process_statistics
    res_statistics = await fetch(
                     ^^^^^^^^^^^^
  File "C:\Users\brenopoubel\My Drive\Monitors\pocketoption2\main.py", line 79, in fetch
    return await core.session.get(url, **kwargs)
           ^^^^^^^^^^^^^^^^^^^^^^^^^^^^^^^^^^^^^
  File "C:\Users\brenopoubel\AppData\Roaming\Python\Python312\site-packages\httpx\_client.py", line 1736, in get
    return await self.request(
           ^^^^^^^^^^^^^^^^^^^
  File "C:\Users\brenopoubel\AppData\Roaming\Python\Python312\site-packages\httpx\_client.py", line 1513, in request
    return await self.send(request, auth=auth, follow_redirects=follow_redirects)
           ^^^^^^^^^^^^^^^^^^^^^^^^^^^^^^^^^^^^^^^^^^^^^^^^^^^^^^^^^^^^^^^^^^^^^^
  File "C:\Users\brenopoubel\AppData\Roaming\Python\Python312\site-packages\httpx\_client.py", line 1600, in send
    response = await self._send_handling_auth(
               ^^^^^^^^^^^^^^^^^^^^^^^^^^^^^^^
  File "C:\Users\brenopoubel\AppData\Roaming\Python\Python312\site-packages\httpx\_client.py", line 1628, in _send_handling_auth
    response = await self._send_handling_redirects(
               ^^^^^^^^^^^^^^^^^^^^^^^^^^^^^^^^^^^^
  File "C:\Users\brenopoubel\AppData\Roaming\Python\Python312\site-packages\httpx\_client.py", line 1665, in _send_handling_redirects
    response = await self._send_single_request(request)
               ^^^^^^^^^^^^^^^^^^^^^^^^^^^^^^^^^^^^^^^^
  File "C:\Users\brenopoubel\AppData\Roaming\Python\Python312\site-packages\httpx\_client.py", line 1702, in _send_single_request
    response = await transport.handle_async_request(request)
               ^^^^^^^^^^^^^^^^^^^^^^^^^^^^^^^^^^^^^^^^^^^^^
  File "C:\Users\brenopoubel\AppData\Roaming\Python\Python312\site-packages\httpx\_transports\default.py", line 290, in handle_async_request
    with map_httpcore_exceptions():
  File "C:\Program Files\Python312\Lib\contextlib.py", line 158, in __exit__
    self.gen.throw(value)
  File "C:\Users\brenopoubel\AppData\Roaming\Python\Python312\site-packages\httpx\_transports\default.py", line 77, in map_httpcore_exceptions
    raise mapped_exc(message) from exc
httpx.ReadTimeout
2024-06-16 18:01:17,399 - pocketoption - DEBUG - Balance -> None -> Not enough for Withdrawal
2024-06-16 18:01:17,399 - pocketoption - DEBUG - Bonus -> None -> Not enough for Withdrawal
2024-06-16 18:01:22,511 - pocketoption - ERROR - ERR_GET_LAST_PAYMENT_REQUEST_ID
Traceback (most recent call last):
  File "C:\Users\brenopoubel\AppData\Roaming\Python\Python312\site-packages\anyio\streams\tls.py", line 131, in _call_sslobject_method
    result = func(*args)
             ^^^^^^^^^^^
  File "C:\Program Files\Python312\Lib\ssl.py", line 859, in read
    v = self._sslobj.read(len)
        ^^^^^^^^^^^^^^^^^^^^^^
ssl.SSLWantReadError: The operation did not complete (read) (_ssl.c:2559)

During handling of the above exception, another exception occurred:

Traceback (most recent call last):
  File "C:\Users\brenopoubel\AppData\Roaming\Python\Python312\site-packages\httpcore\backends\asyncio.py", line 31, in read
    return await self._stream.receive(max_bytes=max_bytes)
           ^^^^^^^^^^^^^^^^^^^^^^^^^^^^^^^^^^^^^^^^^^^^^^^
  File "C:\Users\brenopoubel\AppData\Roaming\Python\Python312\site-packages\anyio\streams\tls.py", line 196, in receive
    data = await self._call_sslobject_method(self._ssl_object.read, max_bytes)
           ^^^^^^^^^^^^^^^^^^^^^^^^^^^^^^^^^^^^^^^^^^^^^^^^^^^^^^^^^^^^^^^^^^^
  File "C:\Users\brenopoubel\AppData\Roaming\Python\Python312\site-packages\anyio\streams\tls.py", line 138, in _call_sslobject_method
    data = await self.transport_stream.receive()
           ^^^^^^^^^^^^^^^^^^^^^^^^^^^^^^^^^^^^^
  File "C:\Users\brenopoubel\AppData\Roaming\Python\Python312\site-packages\anyio\_backends\_asyncio.py", line 1203, in receive
    await self._protocol.read_event.wait()
  File "C:\Program Files\Python312\Lib\asyncio\locks.py", line 212, in wait
    await fut
asyncio.exceptions.CancelledError

During handling of the above exception, another exception occurred:

Traceback (most recent call last):
  File "C:\Users\brenopoubel\AppData\Roaming\Python\Python312\site-packages\httpcore\_exceptions.py", line 8, in map_exceptions
    yield
  File "C:\Users\brenopoubel\AppData\Roaming\Python\Python312\site-packages\httpcore\backends\asyncio.py", line 29, in read
    with anyio.fail_after(timeout):
  File "C:\Users\brenopoubel\AppData\Roaming\Python\Python312\site-packages\anyio\_core\_tasks.py", line 119, in __exit__
    raise TimeoutError
TimeoutError

During handling of the above exception, another exception occurred:

Traceback (most recent call last):
  File "C:\Users\brenopoubel\AppData\Roaming\Python\Python312\site-packages\httpx\_transports\default.py", line 60, in map_httpcore_exceptions
    yield
  File "C:\Users\brenopoubel\AppData\Roaming\Python\Python312\site-packages\httpx\_transports\default.py", line 291, in handle_async_request
    resp = await self._pool.handle_async_request(req)
           ^^^^^^^^^^^^^^^^^^^^^^^^^^^^^^^^^^^^^^^^^^
  File "C:\Users\brenopoubel\AppData\Roaming\Python\Python312\site-packages\httpcore\_async\connection_pool.py", line 253, in handle_async_request
    raise exc
  File "C:\Users\brenopoubel\AppData\Roaming\Python\Python312\site-packages\httpcore\_async\connection_pool.py", line 237, in handle_async_request
    response = await connection.handle_async_request(request)
               ^^^^^^^^^^^^^^^^^^^^^^^^^^^^^^^^^^^^^^^^^^^^^^
  File "C:\Users\brenopoubel\AppData\Roaming\Python\Python312\site-packages\httpcore\_async\connection.py", line 90, in handle_async_request
    return await self._connection.handle_async_request(request)
           ^^^^^^^^^^^^^^^^^^^^^^^^^^^^^^^^^^^^^^^^^^^^^^^^^^^^
  File "C:\Users\brenopoubel\AppData\Roaming\Python\Python312\site-packages\httpcore\_async\http11.py", line 102, in handle_async_request
    raise exc
  File "C:\Users\brenopoubel\AppData\Roaming\Python\Python312\site-packages\httpcore\_async\http11.py", line 81, in handle_async_request
    ) = await self._receive_response_headers(**kwargs)
        ^^^^^^^^^^^^^^^^^^^^^^^^^^^^^^^^^^^^^^^^^^^^^^
  File "C:\Users\brenopoubel\AppData\Roaming\Python\Python312\site-packages\httpcore\_async\http11.py", line 143, in _receive_response_headers
    event = await self._receive_event(timeout=timeout)
            ^^^^^^^^^^^^^^^^^^^^^^^^^^^^^^^^^^^^^^^^^^
  File "C:\Users\brenopoubel\AppData\Roaming\Python\Python312\site-packages\httpcore\_async\http11.py", line 172, in _receive_event
    data = await self._network_stream.read(
           ^^^^^^^^^^^^^^^^^^^^^^^^^^^^^^^^
  File "C:\Users\brenopoubel\AppData\Roaming\Python\Python312\site-packages\httpcore\backends\asyncio.py", line 28, in read
    with map_exceptions(exc_map):
  File "C:\Program Files\Python312\Lib\contextlib.py", line 158, in __exit__
    self.gen.throw(value)
  File "C:\Users\brenopoubel\AppData\Roaming\Python\Python312\site-packages\httpcore\_exceptions.py", line 12, in map_exceptions
    raise to_exc(exc)
httpcore.ReadTimeout

The above exception was the direct cause of the following exception:

Traceback (most recent call last):
  File "C:\Users\brenopoubel\My Drive\Monitors\pocketoption2\main.py", line 788, in get_last_payment_request_id
    res = await fetch(core.payment_history_link)
          ^^^^^^^^^^^^^^^^^^^^^^^^^^^^^^^^^^^^^^
  File "C:\Users\brenopoubel\My Drive\Monitors\pocketoption2\main.py", line 79, in fetch
    return await core.session.get(url, **kwargs)
           ^^^^^^^^^^^^^^^^^^^^^^^^^^^^^^^^^^^^^
  File "C:\Users\brenopoubel\AppData\Roaming\Python\Python312\site-packages\httpx\_client.py", line 1736, in get
    return await self.request(
           ^^^^^^^^^^^^^^^^^^^
  File "C:\Users\brenopoubel\AppData\Roaming\Python\Python312\site-packages\httpx\_client.py", line 1513, in request
    return await self.send(request, auth=auth, follow_redirects=follow_redirects)
           ^^^^^^^^^^^^^^^^^^^^^^^^^^^^^^^^^^^^^^^^^^^^^^^^^^^^^^^^^^^^^^^^^^^^^^
  File "C:\Users\brenopoubel\AppData\Roaming\Python\Python312\site-packages\httpx\_client.py", line 1600, in send
    response = await self._send_handling_auth(
               ^^^^^^^^^^^^^^^^^^^^^^^^^^^^^^^
  File "C:\Users\brenopoubel\AppData\Roaming\Python\Python312\site-packages\httpx\_client.py", line 1628, in _send_handling_auth
    response = await self._send_handling_redirects(
               ^^^^^^^^^^^^^^^^^^^^^^^^^^^^^^^^^^^^
  File "C:\Users\brenopoubel\AppData\Roaming\Python\Python312\site-packages\httpx\_client.py", line 1665, in _send_handling_redirects
    response = await self._send_single_request(request)
               ^^^^^^^^^^^^^^^^^^^^^^^^^^^^^^^^^^^^^^^^
  File "C:\Users\brenopoubel\AppData\Roaming\Python\Python312\site-packages\httpx\_client.py", line 1702, in _send_single_request
    response = await transport.handle_async_request(request)
               ^^^^^^^^^^^^^^^^^^^^^^^^^^^^^^^^^^^^^^^^^^^^^
  File "C:\Users\brenopoubel\AppData\Roaming\Python\Python312\site-packages\httpx\_transports\default.py", line 290, in handle_async_request
    with map_httpcore_exceptions():
  File "C:\Program Files\Python312\Lib\contextlib.py", line 158, in __exit__
    self.gen.throw(value)
  File "C:\Users\brenopoubel\AppData\Roaming\Python\Python312\site-packages\httpx\_transports\default.py", line 77, in map_httpcore_exceptions
    raise mapped_exc(message) from exc
httpx.ReadTimeout
2024-06-16 18:01:22,511 - pocketoption - DEBUG - Second Check -> Latest ID:  | Existing ID: 164123
2024-06-16 18:59:01,700 - pocketoption - DEBUG - Old session worked fine.
2024-06-16 18:59:02,764 - pocketoption - DEBUG - Processed -> Statistics -> Current week
2024-06-16 18:59:02,764 - pocketoption - DEBUG - Total time taken to perform the task: 2.52 seconds
2024-06-16 19:00:01,530 - pocketoption - INFO - Target [ID:610323477]: success
2024-06-16 19:00:01,906 - pocketoption - INFO - Target [ID:1838317981]: success
2024-06-16 19:01:01,950 - pocketoption - DEBUG - First Check -> Latest ID: 164123 | Existing ID: 164123
2024-06-16 19:01:02,559 - pocketoption - DEBUG - Balance -> -119 -> Not enough for Withdrawal
2024-06-16 19:01:02,559 - pocketoption - DEBUG - Bonus -> 0.0 -> Not enough for Withdrawal
2024-06-16 19:01:03,466 - pocketoption - DEBUG - Second Check -> Latest ID: 164123 | Existing ID: 164123
2024-06-16 19:59:02,345 - pocketoption - DEBUG - Old session worked fine.
2024-06-16 19:59:03,267 - pocketoption - DEBUG - Processed -> Statistics -> Current week
2024-06-16 19:59:03,267 - pocketoption - DEBUG - Total time taken to perform the task: 2.33 seconds
2024-06-16 20:00:00,604 - pocketoption - DEBUG - No change detected!!
2024-06-16 20:01:02,154 - pocketoption - DEBUG - First Check -> Latest ID: 164123 | Existing ID: 164123
2024-06-16 20:01:02,779 - pocketoption - DEBUG - Balance -> -119 -> Not enough for Withdrawal
2024-06-16 20:01:02,779 - pocketoption - DEBUG - Bonus -> 0.0 -> Not enough for Withdrawal
2024-06-16 20:01:03,750 - pocketoption - DEBUG - Second Check -> Latest ID: 164123 | Existing ID: 164123
2024-06-16 20:59:02,053 - pocketoption - DEBUG - Old session worked fine.
2024-06-16 20:59:03,396 - pocketoption - DEBUG - Processed -> Statistics -> Current week
2024-06-16 20:59:03,396 - pocketoption - DEBUG - Total time taken to perform the task: 2.81 seconds
2024-06-16 21:00:00,998 - pocketoption - DEBUG - No change detected!!
2024-06-16 21:01:02,573 - pocketoption - DEBUG - First Check -> Latest ID: 164123 | Existing ID: 164123
2024-06-16 21:01:03,151 - pocketoption - DEBUG - Balance -> -119 -> Not enough for Withdrawal
2024-06-16 21:01:03,151 - pocketoption - DEBUG - Bonus -> 0.0 -> Not enough for Withdrawal
2024-06-16 21:01:04,051 - pocketoption - DEBUG - Second Check -> Latest ID: 164123 | Existing ID: 164123
2024-06-16 21:59:02,145 - pocketoption - DEBUG - Old session worked fine.
2024-06-16 21:59:03,349 - pocketoption - DEBUG - Processed -> Statistics -> Current week
2024-06-16 21:59:03,349 - pocketoption - DEBUG - Total time taken to perform the task: 3.33 seconds
2024-06-16 22:00:00,944 - pocketoption - DEBUG - No change detected!!
2024-06-16 22:01:02,386 - pocketoption - DEBUG - First Check -> Latest ID: 164123 | Existing ID: 164123
2024-06-16 22:01:02,997 - pocketoption - DEBUG - Balance -> -119 -> Not enough for Withdrawal
2024-06-16 22:01:02,997 - pocketoption - DEBUG - Bonus -> 0.0 -> Not enough for Withdrawal
2024-06-16 22:01:04,106 - pocketoption - DEBUG - Second Check -> Latest ID: 164123 | Existing ID: 164123
2024-06-16 22:59:01,632 - pocketoption - DEBUG - Old session worked fine.
2024-06-16 22:59:03,053 - pocketoption - DEBUG - Processed -> Statistics -> Current week
2024-06-16 22:59:03,053 - pocketoption - DEBUG - Total time taken to perform the task: 2.87 seconds
2024-06-16 23:00:00,512 - pocketoption - DEBUG - No change detected!!
2024-06-16 23:01:01,907 - pocketoption - DEBUG - First Check -> Latest ID: 164123 | Existing ID: 164123
2024-06-16 23:01:02,549 - pocketoption - DEBUG - Balance -> -119 -> Not enough for Withdrawal
2024-06-16 23:01:02,549 - pocketoption - DEBUG - Bonus -> 0.0 -> Not enough for Withdrawal
2024-06-16 23:01:03,455 - pocketoption - DEBUG - Second Check -> Latest ID: 164123 | Existing ID: 164123
2024-06-16 23:59:01,897 - pocketoption - DEBUG - Old session worked fine.
2024-06-16 23:59:02,960 - pocketoption - DEBUG - Processed -> Statistics -> Current week
2024-06-16 23:59:02,960 - pocketoption - DEBUG - Total time taken to perform the task: 2.7 seconds
2024-06-17 00:00:01,228 - pocketoption - INFO - Target [ID:610323477]: success
2024-06-17 00:00:01,618 - pocketoption - INFO - Target [ID:1838317981]: success
2024-06-17 00:01:01,828 - pocketoption - DEBUG - First Check -> Latest ID: 164123 | Existing ID: 164123
2024-06-17 00:01:02,640 - pocketoption - DEBUG - Balance -> -119 -> Not enough for Withdrawal
2024-06-17 00:01:02,640 - pocketoption - DEBUG - Bonus -> 0.0 -> Not enough for Withdrawal
2024-06-17 00:01:03,657 - pocketoption - DEBUG - Second Check -> Latest ID: 164123 | Existing ID: 164123
2024-06-17 00:59:02,493 - pocketoption - DEBUG - Old session worked fine.
2024-06-17 00:59:03,556 - pocketoption - DEBUG - Processed -> Statistics -> Current week
2024-06-17 00:59:03,556 - pocketoption - DEBUG - Total time taken to perform the task: 2.73 seconds
2024-06-17 01:00:00,125 - pocketoption - DEBUG - No change detected!!
2024-06-17 01:01:01,973 - pocketoption - DEBUG - First Check -> Latest ID: 164123 | Existing ID: 164123
2024-06-17 01:01:02,629 - pocketoption - DEBUG - Balance -> -119 -> Not enough for Withdrawal
2024-06-17 01:01:02,629 - pocketoption - DEBUG - Bonus -> 0.0 -> Not enough for Withdrawal
2024-06-17 01:01:04,944 - pocketoption - DEBUG - Second Check -> Latest ID: 164123 | Existing ID: 164123
2024-06-17 01:59:02,031 - pocketoption - DEBUG - Old session worked fine.
2024-06-17 01:59:03,281 - pocketoption - DEBUG - Processed -> Statistics -> Current week
2024-06-17 01:59:03,281 - pocketoption - DEBUG - Total time taken to perform the task: 2.69 seconds
2024-06-17 02:00:00,803 - pocketoption - DEBUG - No change detected!!
2024-06-17 02:01:02,339 - pocketoption - DEBUG - First Check -> Latest ID: 164123 | Existing ID: 164123
2024-06-17 02:01:02,948 - pocketoption - DEBUG - Balance -> -119 -> Not enough for Withdrawal
2024-06-17 02:01:02,948 - pocketoption - DEBUG - Bonus -> 0.0 -> Not enough for Withdrawal
2024-06-17 02:01:03,808 - pocketoption - DEBUG - Second Check -> Latest ID: 164123 | Existing ID: 164123
2024-06-17 02:59:01,557 - pocketoption - DEBUG - Old session worked fine.
2024-06-17 02:59:02,997 - pocketoption - DEBUG - Processed -> Statistics -> Current week
2024-06-17 02:59:02,997 - pocketoption - DEBUG - Total time taken to perform the task: 2.88 seconds
2024-06-17 03:00:00,926 - pocketoption - INFO - Target [ID:610323477]: success
2024-06-17 03:00:01,189 - pocketoption - INFO - Target [ID:1838317981]: success
2024-06-17 03:01:02,060 - pocketoption - DEBUG - First Check -> Latest ID: 164123 | Existing ID: 164123
2024-06-17 03:01:02,747 - pocketoption - DEBUG - Balance -> -119 -> Not enough for Withdrawal
2024-06-17 03:01:02,747 - pocketoption - DEBUG - Bonus -> 0.0 -> Not enough for Withdrawal
2024-06-17 03:01:03,727 - pocketoption - DEBUG - Second Check -> Latest ID: 164123 | Existing ID: 164123
2024-06-17 03:59:01,550 - pocketoption - DEBUG - Old session worked fine.
2024-06-17 03:59:02,973 - pocketoption - DEBUG - Processed -> Statistics -> Current week
2024-06-17 03:59:02,988 - pocketoption - DEBUG - Total time taken to perform the task: 2.91 seconds
2024-06-17 04:00:01,119 - pocketoption - INFO - Target [ID:610323477]: success
2024-06-17 04:00:01,385 - pocketoption - INFO - Target [ID:1838317981]: success
2024-06-17 04:01:01,906 - pocketoption - DEBUG - First Check -> Latest ID: 164123 | Existing ID: 164123
2024-06-17 04:01:02,515 - pocketoption - DEBUG - Balance -> -117 -> Not enough for Withdrawal
2024-06-17 04:01:02,515 - pocketoption - DEBUG - Bonus -> 0.0 -> Not enough for Withdrawal
2024-06-17 04:01:03,391 - pocketoption - DEBUG - Second Check -> Latest ID: 164123 | Existing ID: 164123
2024-06-17 04:59:02,624 - pocketoption - DEBUG - Old session worked fine.
2024-06-17 04:59:04,174 - pocketoption - DEBUG - Processed -> Statistics -> Current week
2024-06-17 04:59:04,174 - pocketoption - DEBUG - Total time taken to perform the task: 3.88 seconds
2024-06-17 05:00:00,717 - pocketoption - DEBUG - No change detected!!
2024-06-17 05:01:01,414 - pocketoption - DEBUG - First Check -> Latest ID: 164123 | Existing ID: 164123
2024-06-17 05:01:02,117 - pocketoption - DEBUG - Balance -> -117 -> Not enough for Withdrawal
2024-06-17 05:01:02,117 - pocketoption - DEBUG - Bonus -> 0.0 -> Not enough for Withdrawal
2024-06-17 05:01:03,009 - pocketoption - DEBUG - Second Check -> Latest ID: 164123 | Existing ID: 164123
2024-06-17 05:59:11,269 - pocketoption - DEBUG - Old Session expired!! Trying to login again..
2024-06-17 05:59:16,444 - pocketoption - ERROR - ERR_BROADCAST: 
Traceback (most recent call last):
  File "C:\Users\brenopoubel\AppData\Roaming\Python\Python312\site-packages\anyio\streams\tls.py", line 131, in _call_sslobject_method
    result = func(*args)
             ^^^^^^^^^^^
  File "C:\Program Files\Python312\Lib\ssl.py", line 859, in read
    v = self._sslobj.read(len)
        ^^^^^^^^^^^^^^^^^^^^^^
ssl.SSLWantReadError: The operation did not complete (read) (_ssl.c:2559)

During handling of the above exception, another exception occurred:

Traceback (most recent call last):
  File "C:\Users\brenopoubel\AppData\Roaming\Python\Python312\site-packages\httpcore\backends\asyncio.py", line 31, in read
    return await self._stream.receive(max_bytes=max_bytes)
           ^^^^^^^^^^^^^^^^^^^^^^^^^^^^^^^^^^^^^^^^^^^^^^^
  File "C:\Users\brenopoubel\AppData\Roaming\Python\Python312\site-packages\anyio\streams\tls.py", line 196, in receive
    data = await self._call_sslobject_method(self._ssl_object.read, max_bytes)
           ^^^^^^^^^^^^^^^^^^^^^^^^^^^^^^^^^^^^^^^^^^^^^^^^^^^^^^^^^^^^^^^^^^^
  File "C:\Users\brenopoubel\AppData\Roaming\Python\Python312\site-packages\anyio\streams\tls.py", line 138, in _call_sslobject_method
    data = await self.transport_stream.receive()
           ^^^^^^^^^^^^^^^^^^^^^^^^^^^^^^^^^^^^^
  File "C:\Users\brenopoubel\AppData\Roaming\Python\Python312\site-packages\anyio\_backends\_asyncio.py", line 1203, in receive
    await self._protocol.read_event.wait()
  File "C:\Program Files\Python312\Lib\asyncio\locks.py", line 212, in wait
    await fut
asyncio.exceptions.CancelledError

During handling of the above exception, another exception occurred:

Traceback (most recent call last):
  File "C:\Users\brenopoubel\AppData\Roaming\Python\Python312\site-packages\httpcore\_exceptions.py", line 8, in map_exceptions
    yield
  File "C:\Users\brenopoubel\AppData\Roaming\Python\Python312\site-packages\httpcore\backends\asyncio.py", line 29, in read
    with anyio.fail_after(timeout):
  File "C:\Users\brenopoubel\AppData\Roaming\Python\Python312\site-packages\anyio\_core\_tasks.py", line 119, in __exit__
    raise TimeoutError
TimeoutError

During handling of the above exception, another exception occurred:

Traceback (most recent call last):
  File "C:\Users\brenopoubel\AppData\Roaming\Python\Python312\site-packages\httpx\_transports\default.py", line 60, in map_httpcore_exceptions
    yield
  File "C:\Users\brenopoubel\AppData\Roaming\Python\Python312\site-packages\httpx\_transports\default.py", line 291, in handle_async_request
    resp = await self._pool.handle_async_request(req)
           ^^^^^^^^^^^^^^^^^^^^^^^^^^^^^^^^^^^^^^^^^^
  File "C:\Users\brenopoubel\AppData\Roaming\Python\Python312\site-packages\httpcore\_async\connection_pool.py", line 253, in handle_async_request
    raise exc
  File "C:\Users\brenopoubel\AppData\Roaming\Python\Python312\site-packages\httpcore\_async\connection_pool.py", line 237, in handle_async_request
    response = await connection.handle_async_request(request)
               ^^^^^^^^^^^^^^^^^^^^^^^^^^^^^^^^^^^^^^^^^^^^^^
  File "C:\Users\brenopoubel\AppData\Roaming\Python\Python312\site-packages\httpcore\_async\connection.py", line 90, in handle_async_request
    return await self._connection.handle_async_request(request)
           ^^^^^^^^^^^^^^^^^^^^^^^^^^^^^^^^^^^^^^^^^^^^^^^^^^^^
  File "C:\Users\brenopoubel\AppData\Roaming\Python\Python312\site-packages\httpcore\_async\http11.py", line 102, in handle_async_request
    raise exc
  File "C:\Users\brenopoubel\AppData\Roaming\Python\Python312\site-packages\httpcore\_async\http11.py", line 81, in handle_async_request
    ) = await self._receive_response_headers(**kwargs)
        ^^^^^^^^^^^^^^^^^^^^^^^^^^^^^^^^^^^^^^^^^^^^^^
  File "C:\Users\brenopoubel\AppData\Roaming\Python\Python312\site-packages\httpcore\_async\http11.py", line 143, in _receive_response_headers
    event = await self._receive_event(timeout=timeout)
            ^^^^^^^^^^^^^^^^^^^^^^^^^^^^^^^^^^^^^^^^^^
  File "C:\Users\brenopoubel\AppData\Roaming\Python\Python312\site-packages\httpcore\_async\http11.py", line 172, in _receive_event
    data = await self._network_stream.read(
           ^^^^^^^^^^^^^^^^^^^^^^^^^^^^^^^^
  File "C:\Users\brenopoubel\AppData\Roaming\Python\Python312\site-packages\httpcore\backends\asyncio.py", line 28, in read
    with map_exceptions(exc_map):
  File "C:\Program Files\Python312\Lib\contextlib.py", line 158, in __exit__
    self.gen.throw(value)
  File "C:\Users\brenopoubel\AppData\Roaming\Python\Python312\site-packages\httpcore\_exceptions.py", line 12, in map_exceptions
    raise to_exc(exc)
httpcore.ReadTimeout

The above exception was the direct cause of the following exception:

Traceback (most recent call last):
  File "C:\Users\brenopoubel\My Drive\Monitors\pocketoption2\main.py", line 617, in broadcast
    current_stats = await get_statistics()
                    ^^^^^^^^^^^^^^^^^^^^^^
  File "C:\Users\brenopoubel\My Drive\Monitors\pocketoption2\main.py", line 468, in get_statistics
    await perform_login()
  File "C:\Users\brenopoubel\My Drive\Monitors\pocketoption2\main.py", line 526, in perform_login
    res = await core.session.get(url=core.home_link)
          ^^^^^^^^^^^^^^^^^^^^^^^^^^^^^^^^^^^^^^^^^^
  File "C:\Users\brenopoubel\AppData\Roaming\Python\Python312\site-packages\httpx\_client.py", line 1736, in get
    return await self.request(
           ^^^^^^^^^^^^^^^^^^^
  File "C:\Users\brenopoubel\AppData\Roaming\Python\Python312\site-packages\httpx\_client.py", line 1513, in request
    return await self.send(request, auth=auth, follow_redirects=follow_redirects)
           ^^^^^^^^^^^^^^^^^^^^^^^^^^^^^^^^^^^^^^^^^^^^^^^^^^^^^^^^^^^^^^^^^^^^^^
  File "C:\Users\brenopoubel\AppData\Roaming\Python\Python312\site-packages\httpx\_client.py", line 1600, in send
    response = await self._send_handling_auth(
               ^^^^^^^^^^^^^^^^^^^^^^^^^^^^^^^
  File "C:\Users\brenopoubel\AppData\Roaming\Python\Python312\site-packages\httpx\_client.py", line 1628, in _send_handling_auth
    response = await self._send_handling_redirects(
               ^^^^^^^^^^^^^^^^^^^^^^^^^^^^^^^^^^^^
  File "C:\Users\brenopoubel\AppData\Roaming\Python\Python312\site-packages\httpx\_client.py", line 1665, in _send_handling_redirects
    response = await self._send_single_request(request)
               ^^^^^^^^^^^^^^^^^^^^^^^^^^^^^^^^^^^^^^^^
  File "C:\Users\brenopoubel\AppData\Roaming\Python\Python312\site-packages\httpx\_client.py", line 1702, in _send_single_request
    response = await transport.handle_async_request(request)
               ^^^^^^^^^^^^^^^^^^^^^^^^^^^^^^^^^^^^^^^^^^^^^
  File "C:\Users\brenopoubel\AppData\Roaming\Python\Python312\site-packages\httpx\_transports\default.py", line 290, in handle_async_request
    with map_httpcore_exceptions():
  File "C:\Program Files\Python312\Lib\contextlib.py", line 158, in __exit__
    self.gen.throw(value)
  File "C:\Users\brenopoubel\AppData\Roaming\Python\Python312\site-packages\httpx\_transports\default.py", line 77, in map_httpcore_exceptions
    raise mapped_exc(message) from exc
httpx.ReadTimeout
2024-06-17 05:59:27,748 - pocketoption - DEBUG - Old Session expired!! Trying to login again..
2024-06-17 06:00:21,336 - pocketoption - DEBUG - Logged-In successfully!
2024-06-17 06:00:21,368 - pocketoption - DEBUG - Cookies Saved!!
2024-06-17 06:00:22,823 - pocketoption - DEBUG - Cookies Saved!!
2024-06-17 06:00:23,010 - pocketoption - DEBUG - Processed -> Statistics -> Current week
2024-06-17 06:00:23,010 - pocketoption - DEBUG - Total time taken to perform the task: 65.36 seconds
2024-06-17 06:00:23,010 - pocketoption - DEBUG - No change detected!!
2024-06-17 06:01:01,665 - pocketoption - DEBUG - Cookies Saved!!
2024-06-17 06:01:01,744 - pocketoption - DEBUG - First Check -> Latest ID: 164123 | Existing ID: 164123
2024-06-17 06:01:02,353 - pocketoption - DEBUG - Cookies Saved!!
2024-06-17 06:01:02,353 - pocketoption - DEBUG - Balance -> -117 -> Not enough for Withdrawal
2024-06-17 06:01:02,353 - pocketoption - DEBUG - Bonus -> 0.0 -> Not enough for Withdrawal
2024-06-17 06:01:03,214 - pocketoption - DEBUG - Cookies Saved!!
2024-06-17 06:01:03,261 - pocketoption - DEBUG - Second Check -> Latest ID: 164123 | Existing ID: 164123
2024-06-17 06:59:01,917 - pocketoption - DEBUG - Old session worked fine.
2024-06-17 06:59:03,981 - pocketoption - DEBUG - Processed -> Statistics -> Current week
2024-06-17 06:59:03,981 - pocketoption - DEBUG - Total time taken to perform the task: 3.0 seconds
2024-06-17 07:00:01,162 - pocketoption - INFO - Target [ID:610323477]: success
2024-06-17 07:00:01,444 - pocketoption - INFO - Target [ID:1838317981]: success
2024-06-17 07:01:01,980 - pocketoption - DEBUG - First Check -> Latest ID: 164123 | Existing ID: 164123
2024-06-17 07:01:02,591 - pocketoption - DEBUG - Balance -> -117 -> Not enough for Withdrawal
2024-06-17 07:01:02,591 - pocketoption - DEBUG - Bonus -> 0.0 -> Not enough for Withdrawal
2024-06-17 07:01:03,528 - pocketoption - DEBUG - Second Check -> Latest ID: 164123 | Existing ID: 164123
2024-06-17 07:59:01,794 - pocketoption - DEBUG - Old session worked fine.
2024-06-17 07:59:03,717 - pocketoption - DEBUG - Processed -> Statistics -> Current week
2024-06-17 07:59:03,717 - pocketoption - DEBUG - Total time taken to perform the task: 3.39 seconds
2024-06-17 08:00:00,213 - pocketoption - DEBUG - No change detected!!
2024-06-17 08:01:01,732 - pocketoption - DEBUG - First Check -> Latest ID: 164123 | Existing ID: 164123
2024-06-17 08:01:02,342 - pocketoption - DEBUG - Balance -> -117 -> Not enough for Withdrawal
2024-06-17 08:01:02,342 - pocketoption - DEBUG - Bonus -> 0.0 -> Not enough for Withdrawal
2024-06-17 08:01:03,499 - pocketoption - DEBUG - Second Check -> Latest ID: 164123 | Existing ID: 164123
2024-06-17 08:59:02,014 - pocketoption - DEBUG - Old session worked fine.
2024-06-17 08:59:03,655 - pocketoption - DEBUG - Processed -> Statistics -> Current week
2024-06-17 08:59:03,655 - pocketoption - DEBUG - Total time taken to perform the task: 3.3 seconds
2024-06-17 09:00:00,069 - pocketoption - DEBUG - No change detected!!
2024-06-17 09:01:01,638 - pocketoption - DEBUG - First Check -> Latest ID: 164123 | Existing ID: 164123
2024-06-17 09:01:02,435 - pocketoption - DEBUG - Balance -> -117 -> Not enough for Withdrawal
2024-06-17 09:01:02,435 - pocketoption - DEBUG - Bonus -> 0.0 -> Not enough for Withdrawal
2024-06-17 09:01:04,998 - pocketoption - DEBUG - Second Check -> Latest ID: 164123 | Existing ID: 164123
2024-06-17 09:59:02,869 - pocketoption - DEBUG - Old session worked fine.
2024-06-17 09:59:04,245 - pocketoption - DEBUG - Processed -> Statistics -> Current week
2024-06-17 09:59:04,245 - pocketoption - DEBUG - Total time taken to perform the task: 3.69 seconds
2024-06-17 10:00:01,302 - pocketoption - INFO - Target [ID:610323477]: success
2024-06-17 10:00:01,568 - pocketoption - INFO - Target [ID:1838317981]: success
2024-06-17 10:01:02,347 - pocketoption - DEBUG - First Check -> Latest ID: 164123 | Existing ID: 164123
2024-06-17 10:01:02,988 - pocketoption - DEBUG - Balance -> -117 -> Not enough for Withdrawal
2024-06-17 10:01:02,988 - pocketoption - DEBUG - Bonus -> 0.0 -> Not enough for Withdrawal
2024-06-17 10:01:03,896 - pocketoption - DEBUG - Second Check -> Latest ID: 164123 | Existing ID: 164123
2024-06-17 10:59:03,777 - pocketoption - DEBUG - Old session worked fine.
2024-06-17 10:59:05,450 - pocketoption - DEBUG - Processed -> Statistics -> Current week
2024-06-17 10:59:05,466 - pocketoption - DEBUG - Total time taken to perform the task: 4.97 seconds
2024-06-17 11:00:00,083 - pocketoption - DEBUG - No change detected!!
2024-06-17 11:01:02,012 - pocketoption - DEBUG - First Check -> Latest ID: 164123 | Existing ID: 164123
2024-06-17 11:01:02,637 - pocketoption - DEBUG - Balance -> -117 -> Not enough for Withdrawal
2024-06-17 11:01:02,637 - pocketoption - DEBUG - Bonus -> 0.0 -> Not enough for Withdrawal
2024-06-17 11:01:03,591 - pocketoption - DEBUG - Second Check -> Latest ID: 164123 | Existing ID: 164123
2024-06-17 11:52:05,074 - pocketoption - DEBUG - Date: 2024-06-10 | Hour: 14
2024-06-17 11:52:05,137 - pocketoption - DEBUG - Date: 2024-06-17 | Hour: 14
2024-06-17 11:59:01,867 - pocketoption - DEBUG - Old session worked fine.
2024-06-17 11:59:03,697 - pocketoption - DEBUG - Processed -> Statistics -> Current week
2024-06-17 11:59:03,697 - pocketoption - DEBUG - Total time taken to perform the task: 3.3 seconds
2024-06-17 12:00:00,160 - pocketoption - DEBUG - No change detected!!
2024-06-17 12:01:01,821 - pocketoption - DEBUG - First Check -> Latest ID: 164123 | Existing ID: 164123
2024-06-17 12:01:02,446 - pocketoption - DEBUG - Balance -> -117 -> Not enough for Withdrawal
2024-06-17 12:01:02,446 - pocketoption - DEBUG - Bonus -> 0.0 -> Not enough for Withdrawal
2024-06-17 12:01:03,354 - pocketoption - DEBUG - Second Check -> Latest ID: 164123 | Existing ID: 164123
2024-06-17 12:59:01,570 - pocketoption - DEBUG - Old session worked fine.
2024-06-17 12:59:03,665 - pocketoption - DEBUG - Processed -> Statistics -> Current week
2024-06-17 12:59:03,665 - pocketoption - DEBUG - Total time taken to perform the task: 3.53 seconds
2024-06-17 13:00:00,847 - pocketoption - INFO - Target [ID:610323477]: success
2024-06-17 13:00:01,175 - pocketoption - INFO - Target [ID:1838317981]: success
2024-06-17 13:01:01,512 - pocketoption - DEBUG - First Check -> Latest ID: 164123 | Existing ID: 164123
2024-06-17 13:01:02,153 - pocketoption - DEBUG - Balance -> -117 -> Not enough for Withdrawal
2024-06-17 13:01:02,153 - pocketoption - DEBUG - Bonus -> 0.0 -> Not enough for Withdrawal
2024-06-17 13:01:03,138 - pocketoption - DEBUG - Second Check -> Latest ID: 164123 | Existing ID: 164123
2024-06-17 13:59:02,037 - pocketoption - DEBUG - Old session worked fine.
2024-06-17 13:59:04,150 - pocketoption - DEBUG - Processed -> Statistics -> Current week
2024-06-17 13:59:04,150 - pocketoption - DEBUG - Total time taken to perform the task: 3.52 seconds
2024-06-17 14:00:01,223 - pocketoption - INFO - Target [ID:610323477]: success
2024-06-17 14:00:01,543 - pocketoption - INFO - Target [ID:1838317981]: success
2024-06-17 14:01:01,515 - pocketoption - DEBUG - First Check -> Latest ID: 164123 | Existing ID: 164123
2024-06-17 14:01:02,108 - pocketoption - DEBUG - Balance -> -117 -> Not enough for Withdrawal
2024-06-17 14:01:02,108 - pocketoption - DEBUG - Bonus -> 0.0 -> Not enough for Withdrawal
2024-06-17 14:01:03,078 - pocketoption - DEBUG - Second Check -> Latest ID: 164123 | Existing ID: 164123
2024-06-17 14:59:02,988 - pocketoption - DEBUG - Old session worked fine.
2024-06-17 14:59:04,331 - pocketoption - DEBUG - Processed -> Statistics -> Current week
2024-06-17 14:59:04,331 - pocketoption - DEBUG - Total time taken to perform the task: 3.73 seconds
2024-06-17 15:00:00,950 - pocketoption - DEBUG - No change detected!!
2024-06-17 15:01:02,468 - pocketoption - DEBUG - First Check -> Latest ID: 164123 | Existing ID: 164123
2024-06-17 15:01:03,077 - pocketoption - DEBUG - Balance -> -117 -> Not enough for Withdrawal
2024-06-17 15:01:03,077 - pocketoption - DEBUG - Bonus -> 0.0 -> Not enough for Withdrawal
2024-06-17 15:01:03,984 - pocketoption - DEBUG - Second Check -> Latest ID: 164123 | Existing ID: 164123
2024-06-17 15:59:01,818 - pocketoption - DEBUG - Old session worked fine.
2024-06-17 15:59:04,116 - pocketoption - DEBUG - Processed -> Statistics -> Current week
2024-06-17 15:59:04,116 - pocketoption - DEBUG - Total time taken to perform the task: 3.69 seconds
2024-06-17 16:00:01,203 - pocketoption - INFO - Target [ID:610323477]: success
2024-06-17 16:00:01,484 - pocketoption - INFO - Target [ID:1838317981]: success
2024-06-17 16:01:02,395 - pocketoption - DEBUG - First Check -> Latest ID: 164123 | Existing ID: 164123
2024-06-17 16:01:02,974 - pocketoption - DEBUG - Balance -> -117 -> Not enough for Withdrawal
2024-06-17 16:01:02,974 - pocketoption - DEBUG - Bonus -> 0.0 -> Not enough for Withdrawal
2024-06-17 16:01:03,895 - pocketoption - DEBUG - Second Check -> Latest ID: 164123 | Existing ID: 164123
2024-06-17 16:59:03,441 - pocketoption - DEBUG - Old session worked fine.
2024-06-17 16:59:05,161 - pocketoption - DEBUG - Processed -> Statistics -> Current week
2024-06-17 16:59:05,161 - pocketoption - DEBUG - Total time taken to perform the task: 4.64 seconds
2024-06-17 17:00:00,589 - pocketoption - DEBUG - No change detected!!
2024-06-17 17:01:02,710 - pocketoption - DEBUG - First Check -> Latest ID: 164123 | Existing ID: 164123
2024-06-17 17:01:03,335 - pocketoption - DEBUG - Balance -> -117 -> Not enough for Withdrawal
2024-06-17 17:01:03,335 - pocketoption - DEBUG - Bonus -> 0.0 -> Not enough for Withdrawal
2024-06-17 17:01:04,383 - pocketoption - DEBUG - Second Check -> Latest ID: 164123 | Existing ID: 164123
2024-06-17 17:59:01,485 - pocketoption - DEBUG - Old session worked fine.
2024-06-17 17:59:03,362 - pocketoption - DEBUG - Processed -> Statistics -> Current week
2024-06-17 17:59:03,362 - pocketoption - DEBUG - Total time taken to perform the task: 3.33 seconds
2024-06-17 18:00:00,839 - pocketoption - DEBUG - No change detected!!
2024-06-17 18:01:04,194 - pocketoption - DEBUG - First Check -> Latest ID: 164123 | Existing ID: 164123
2024-06-17 18:01:04,756 - pocketoption - DEBUG - Balance -> -117 -> Not enough for Withdrawal
2024-06-17 18:01:04,756 - pocketoption - DEBUG - Bonus -> 0.0 -> Not enough for Withdrawal
2024-06-17 18:01:05,803 - pocketoption - DEBUG - Second Check -> Latest ID: 164123 | Existing ID: 164123
2024-06-17 18:59:02,270 - pocketoption - DEBUG - Old session worked fine.
2024-06-17 18:59:03,535 - pocketoption - DEBUG - Processed -> Statistics -> Current week
2024-06-17 18:59:03,535 - pocketoption - DEBUG - Total time taken to perform the task: 2.58 seconds
2024-06-17 19:00:00,122 - pocketoption - DEBUG - No change detected!!
2024-06-17 19:01:01,774 - pocketoption - DEBUG - First Check -> Latest ID: 164123 | Existing ID: 164123
2024-06-17 19:01:02,352 - pocketoption - DEBUG - Balance -> -117 -> Not enough for Withdrawal
2024-06-17 19:01:02,352 - pocketoption - DEBUG - Bonus -> 0.0 -> Not enough for Withdrawal
2024-06-17 19:01:03,352 - pocketoption - DEBUG - Second Check -> Latest ID: 164123 | Existing ID: 164123
2024-06-17 19:59:02,099 - pocketoption - DEBUG - Old session worked fine.
2024-06-17 19:59:03,177 - pocketoption - DEBUG - Processed -> Statistics -> Current week
2024-06-17 19:59:03,177 - pocketoption - DEBUG - Total time taken to perform the task: 2.89 seconds
2024-06-17 20:00:00,626 - pocketoption - DEBUG - No change detected!!
2024-06-17 20:01:02,108 - pocketoption - DEBUG - First Check -> Latest ID: 164123 | Existing ID: 164123
2024-06-17 20:01:02,702 - pocketoption - DEBUG - Balance -> -117 -> Not enough for Withdrawal
2024-06-17 20:01:02,702 - pocketoption - DEBUG - Bonus -> 0.0 -> Not enough for Withdrawal
2024-06-17 20:01:03,594 - pocketoption - DEBUG - Second Check -> Latest ID: 164123 | Existing ID: 164123
2024-06-17 20:59:02,943 - pocketoption - DEBUG - Old session worked fine.
2024-06-17 20:59:04,287 - pocketoption - DEBUG - Processed -> Statistics -> Current week
2024-06-17 20:59:04,287 - pocketoption - DEBUG - Total time taken to perform the task: 3.32 seconds
2024-06-17 21:00:00,847 - pocketoption - DEBUG - No change detected!!
2024-06-17 21:01:02,264 - pocketoption - DEBUG - First Check -> Latest ID: 164123 | Existing ID: 164123
2024-06-17 21:01:02,842 - pocketoption - DEBUG - Balance -> -117 -> Not enough for Withdrawal
2024-06-17 21:01:02,857 - pocketoption - DEBUG - Bonus -> 0.0 -> Not enough for Withdrawal
2024-06-17 21:01:03,795 - pocketoption - DEBUG - Second Check -> Latest ID: 164123 | Existing ID: 164123
2024-06-17 21:59:01,792 - pocketoption - DEBUG - Old session worked fine.
2024-06-17 21:59:03,560 - pocketoption - DEBUG - Processed -> Statistics -> Current week
2024-06-17 21:59:03,560 - pocketoption - DEBUG - Total time taken to perform the task: 3.14 seconds
2024-06-17 22:00:00,024 - pocketoption - DEBUG - No change detected!!
2024-06-17 22:01:02,410 - pocketoption - DEBUG - First Check -> Latest ID: 164123 | Existing ID: 164123
2024-06-17 22:01:03,021 - pocketoption - DEBUG - Balance -> -117 -> Not enough for Withdrawal
2024-06-17 22:01:03,021 - pocketoption - DEBUG - Bonus -> 0.0 -> Not enough for Withdrawal
2024-06-17 22:01:03,897 - pocketoption - DEBUG - Second Check -> Latest ID: 164123 | Existing ID: 164123
2024-06-17 22:59:02,364 - pocketoption - DEBUG - Old session worked fine.
2024-06-17 22:59:04,695 - pocketoption - DEBUG - Processed -> Statistics -> Current week
2024-06-17 22:59:04,695 - pocketoption - DEBUG - Total time taken to perform the task: 4.69 seconds
2024-06-17 23:00:00,194 - pocketoption - DEBUG - No change detected!!
2024-06-17 23:01:02,117 - pocketoption - DEBUG - First Check -> Latest ID: 164123 | Existing ID: 164123
2024-06-17 23:01:02,789 - pocketoption - DEBUG - Balance -> -117 -> Not enough for Withdrawal
2024-06-17 23:01:02,789 - pocketoption - DEBUG - Bonus -> 0.0 -> Not enough for Withdrawal
2024-06-17 23:01:03,868 - pocketoption - DEBUG - Second Check -> Latest ID: 164123 | Existing ID: 164123
2024-06-17 23:59:03,287 - pocketoption - DEBUG - Old session worked fine.
2024-06-17 23:59:05,350 - pocketoption - DEBUG - Processed -> Statistics -> Current week
2024-06-17 23:59:05,350 - pocketoption - DEBUG - Total time taken to perform the task: 5.14 seconds
2024-06-18 00:00:00,923 - pocketoption - DEBUG - No change detected!!
2024-06-18 00:01:01,825 - pocketoption - DEBUG - First Check -> Latest ID: 164123 | Existing ID: 164123
2024-06-18 00:01:02,465 - pocketoption - DEBUG - Balance -> -117 -> Not enough for Withdrawal
2024-06-18 00:01:02,465 - pocketoption - DEBUG - Bonus -> 0.0 -> Not enough for Withdrawal
2024-06-18 00:01:03,483 - pocketoption - DEBUG - Second Check -> Latest ID: 164123 | Existing ID: 164123
2024-06-18 00:59:09,632 - pocketoption - DEBUG - Old session worked fine.
2024-06-18 00:59:13,807 - pocketoption - DEBUG - Processed -> Statistics -> Current week
2024-06-18 00:59:13,823 - pocketoption - DEBUG - Total time taken to perform the task: 13.48 seconds
2024-06-18 01:00:00,376 - pocketoption - DEBUG - No change detected!!
2024-06-18 01:01:02,337 - pocketoption - DEBUG - First Check -> Latest ID: 164123 | Existing ID: 164123
2024-06-18 01:01:02,960 - pocketoption - DEBUG - Balance -> -117 -> Not enough for Withdrawal
2024-06-18 01:01:02,960 - pocketoption - DEBUG - Bonus -> 0.0 -> Not enough for Withdrawal
2024-06-18 01:01:03,980 - pocketoption - DEBUG - Second Check -> Latest ID: 164123 | Existing ID: 164123
2024-06-18 01:59:01,459 - pocketoption - DEBUG - Old session worked fine.
2024-06-18 01:59:03,133 - pocketoption - DEBUG - Processed -> Statistics -> Current week
2024-06-18 01:59:03,133 - pocketoption - DEBUG - Total time taken to perform the task: 3.1 seconds
2024-06-18 02:00:00,794 - pocketoption - DEBUG - No change detected!!
2024-06-18 02:01:03,967 - pocketoption - DEBUG - First Check -> Latest ID: 164123 | Existing ID: 164123
2024-06-18 02:01:04,529 - pocketoption - DEBUG - Balance -> -117 -> Not enough for Withdrawal
2024-06-18 02:01:04,529 - pocketoption - DEBUG - Bonus -> 0.0 -> Not enough for Withdrawal
2024-06-18 02:01:05,404 - pocketoption - DEBUG - Second Check -> Latest ID: 164123 | Existing ID: 164123
2024-06-18 02:59:01,502 - pocketoption - DEBUG - Old session worked fine.
2024-06-18 02:59:03,189 - pocketoption - DEBUG - Processed -> Statistics -> Current week
2024-06-18 02:59:03,189 - pocketoption - DEBUG - Total time taken to perform the task: 3.17 seconds
2024-06-18 03:00:00,710 - pocketoption - DEBUG - No change detected!!
2024-06-18 03:01:02,326 - pocketoption - DEBUG - First Check -> Latest ID: 164123 | Existing ID: 164123
2024-06-18 03:01:02,936 - pocketoption - DEBUG - Balance -> -117 -> Not enough for Withdrawal
2024-06-18 03:01:02,936 - pocketoption - DEBUG - Bonus -> 0.0 -> Not enough for Withdrawal
2024-06-18 03:01:03,828 - pocketoption - DEBUG - Second Check -> Latest ID: 164123 | Existing ID: 164123
2024-06-18 03:59:01,825 - pocketoption - DEBUG - Old session worked fine.
2024-06-18 03:59:03,326 - pocketoption - DEBUG - Processed -> Statistics -> Current week
2024-06-18 03:59:03,326 - pocketoption - DEBUG - Total time taken to perform the task: 2.91 seconds
2024-06-18 04:00:00,889 - pocketoption - DEBUG - No change detected!!
2024-06-18 04:01:03,117 - pocketoption - DEBUG - First Check -> Latest ID: 164123 | Existing ID: 164123
2024-06-18 04:01:03,788 - pocketoption - DEBUG - Balance -> -117 -> Not enough for Withdrawal
2024-06-18 04:01:03,788 - pocketoption - DEBUG - Bonus -> 0.0 -> Not enough for Withdrawal
2024-06-18 04:01:04,695 - pocketoption - DEBUG - Second Check -> Latest ID: 164123 | Existing ID: 164123
2024-06-18 04:59:02,196 - pocketoption - DEBUG - Old session worked fine.
2024-06-18 04:59:04,135 - pocketoption - DEBUG - Processed -> Statistics -> Current week
2024-06-18 04:59:04,135 - pocketoption - DEBUG - Total time taken to perform the task: 3.19 seconds
2024-06-18 05:00:00,576 - pocketoption - DEBUG - No change detected!!
2024-06-18 05:01:02,036 - pocketoption - DEBUG - First Check -> Latest ID: 164123 | Existing ID: 164123
2024-06-18 05:01:02,739 - pocketoption - DEBUG - Balance -> -117 -> Not enough for Withdrawal
2024-06-18 05:01:02,739 - pocketoption - DEBUG - Bonus -> 0.0 -> Not enough for Withdrawal
2024-06-18 05:01:03,755 - pocketoption - DEBUG - Second Check -> Latest ID: 164123 | Existing ID: 164123
2024-06-18 05:59:04,738 - pocketoption - DEBUG - Old session worked fine.
2024-06-18 05:59:06,833 - pocketoption - DEBUG - Processed -> Statistics -> Current week
2024-06-18 05:59:06,833 - pocketoption - DEBUG - Total time taken to perform the task: 6.01 seconds
2024-06-18 06:00:00,335 - pocketoption - DEBUG - No change detected!!
2024-06-18 06:01:02,503 - pocketoption - DEBUG - First Check -> Latest ID: 164123 | Existing ID: 164123
2024-06-18 06:01:03,112 - pocketoption - DEBUG - Balance -> -117 -> Not enough for Withdrawal
2024-06-18 06:01:03,112 - pocketoption - DEBUG - Bonus -> 0.0 -> Not enough for Withdrawal
2024-06-18 06:01:04,301 - pocketoption - DEBUG - Second Check -> Latest ID: 164123 | Existing ID: 164123
2024-06-18 06:59:01,920 - pocketoption - DEBUG - Old session worked fine.
2024-06-18 06:59:03,843 - pocketoption - DEBUG - Processed -> Statistics -> Current week
2024-06-18 06:59:03,843 - pocketoption - DEBUG - Total time taken to perform the task: 3.36 seconds
2024-06-18 07:00:00,226 - pocketoption - DEBUG - No change detected!!
2024-06-18 07:01:01,696 - pocketoption - DEBUG - First Check -> Latest ID: 164123 | Existing ID: 164123
2024-06-18 07:01:02,383 - pocketoption - DEBUG - Balance -> -117 -> Not enough for Withdrawal
2024-06-18 07:01:02,383 - pocketoption - DEBUG - Bonus -> 0.0 -> Not enough for Withdrawal
2024-06-18 07:01:03,323 - pocketoption - DEBUG - Second Check -> Latest ID: 164123 | Existing ID: 164123
2024-06-18 07:59:10,267 - pocketoption - DEBUG - Old Session expired!! Trying to login again..
2024-06-18 07:59:15,380 - pocketoption - ERROR - ERR_BROADCAST: 
Traceback (most recent call last):
  File "C:\Users\brenopoubel\AppData\Roaming\Python\Python312\site-packages\anyio\streams\tls.py", line 131, in _call_sslobject_method
    result = func(*args)
             ^^^^^^^^^^^
  File "C:\Program Files\Python312\Lib\ssl.py", line 859, in read
    v = self._sslobj.read(len)
        ^^^^^^^^^^^^^^^^^^^^^^
ssl.SSLWantReadError: The operation did not complete (read) (_ssl.c:2559)

During handling of the above exception, another exception occurred:

Traceback (most recent call last):
  File "C:\Users\brenopoubel\AppData\Roaming\Python\Python312\site-packages\httpcore\backends\asyncio.py", line 31, in read
    return await self._stream.receive(max_bytes=max_bytes)
           ^^^^^^^^^^^^^^^^^^^^^^^^^^^^^^^^^^^^^^^^^^^^^^^
  File "C:\Users\brenopoubel\AppData\Roaming\Python\Python312\site-packages\anyio\streams\tls.py", line 196, in receive
    data = await self._call_sslobject_method(self._ssl_object.read, max_bytes)
           ^^^^^^^^^^^^^^^^^^^^^^^^^^^^^^^^^^^^^^^^^^^^^^^^^^^^^^^^^^^^^^^^^^^
  File "C:\Users\brenopoubel\AppData\Roaming\Python\Python312\site-packages\anyio\streams\tls.py", line 138, in _call_sslobject_method
    data = await self.transport_stream.receive()
           ^^^^^^^^^^^^^^^^^^^^^^^^^^^^^^^^^^^^^
  File "C:\Users\brenopoubel\AppData\Roaming\Python\Python312\site-packages\anyio\_backends\_asyncio.py", line 1203, in receive
    await self._protocol.read_event.wait()
  File "C:\Program Files\Python312\Lib\asyncio\locks.py", line 212, in wait
    await fut
asyncio.exceptions.CancelledError

During handling of the above exception, another exception occurred:

Traceback (most recent call last):
  File "C:\Users\brenopoubel\AppData\Roaming\Python\Python312\site-packages\httpcore\_exceptions.py", line 8, in map_exceptions
    yield
  File "C:\Users\brenopoubel\AppData\Roaming\Python\Python312\site-packages\httpcore\backends\asyncio.py", line 29, in read
    with anyio.fail_after(timeout):
  File "C:\Users\brenopoubel\AppData\Roaming\Python\Python312\site-packages\anyio\_core\_tasks.py", line 119, in __exit__
    raise TimeoutError
TimeoutError

During handling of the above exception, another exception occurred:

Traceback (most recent call last):
  File "C:\Users\brenopoubel\AppData\Roaming\Python\Python312\site-packages\httpx\_transports\default.py", line 60, in map_httpcore_exceptions
    yield
  File "C:\Users\brenopoubel\AppData\Roaming\Python\Python312\site-packages\httpx\_transports\default.py", line 291, in handle_async_request
    resp = await self._pool.handle_async_request(req)
           ^^^^^^^^^^^^^^^^^^^^^^^^^^^^^^^^^^^^^^^^^^
  File "C:\Users\brenopoubel\AppData\Roaming\Python\Python312\site-packages\httpcore\_async\connection_pool.py", line 253, in handle_async_request
    raise exc
  File "C:\Users\brenopoubel\AppData\Roaming\Python\Python312\site-packages\httpcore\_async\connection_pool.py", line 237, in handle_async_request
    response = await connection.handle_async_request(request)
               ^^^^^^^^^^^^^^^^^^^^^^^^^^^^^^^^^^^^^^^^^^^^^^
  File "C:\Users\brenopoubel\AppData\Roaming\Python\Python312\site-packages\httpcore\_async\connection.py", line 90, in handle_async_request
    return await self._connection.handle_async_request(request)
           ^^^^^^^^^^^^^^^^^^^^^^^^^^^^^^^^^^^^^^^^^^^^^^^^^^^^
  File "C:\Users\brenopoubel\AppData\Roaming\Python\Python312\site-packages\httpcore\_async\http11.py", line 102, in handle_async_request
    raise exc
  File "C:\Users\brenopoubel\AppData\Roaming\Python\Python312\site-packages\httpcore\_async\http11.py", line 81, in handle_async_request
    ) = await self._receive_response_headers(**kwargs)
        ^^^^^^^^^^^^^^^^^^^^^^^^^^^^^^^^^^^^^^^^^^^^^^
  File "C:\Users\brenopoubel\AppData\Roaming\Python\Python312\site-packages\httpcore\_async\http11.py", line 143, in _receive_response_headers
    event = await self._receive_event(timeout=timeout)
            ^^^^^^^^^^^^^^^^^^^^^^^^^^^^^^^^^^^^^^^^^^
  File "C:\Users\brenopoubel\AppData\Roaming\Python\Python312\site-packages\httpcore\_async\http11.py", line 172, in _receive_event
    data = await self._network_stream.read(
           ^^^^^^^^^^^^^^^^^^^^^^^^^^^^^^^^
  File "C:\Users\brenopoubel\AppData\Roaming\Python\Python312\site-packages\httpcore\backends\asyncio.py", line 28, in read
    with map_exceptions(exc_map):
  File "C:\Program Files\Python312\Lib\contextlib.py", line 158, in __exit__
    self.gen.throw(value)
  File "C:\Users\brenopoubel\AppData\Roaming\Python\Python312\site-packages\httpcore\_exceptions.py", line 12, in map_exceptions
    raise to_exc(exc)
httpcore.ReadTimeout

The above exception was the direct cause of the following exception:

Traceback (most recent call last):
  File "C:\Users\brenopoubel\My Drive\Monitors\pocketoption2\main.py", line 617, in broadcast
    current_stats = await get_statistics()
                    ^^^^^^^^^^^^^^^^^^^^^^
  File "C:\Users\brenopoubel\My Drive\Monitors\pocketoption2\main.py", line 468, in get_statistics
    await perform_login()
  File "C:\Users\brenopoubel\My Drive\Monitors\pocketoption2\main.py", line 526, in perform_login
    res = await core.session.get(url=core.home_link)
          ^^^^^^^^^^^^^^^^^^^^^^^^^^^^^^^^^^^^^^^^^^
  File "C:\Users\brenopoubel\AppData\Roaming\Python\Python312\site-packages\httpx\_client.py", line 1736, in get
    return await self.request(
           ^^^^^^^^^^^^^^^^^^^
  File "C:\Users\brenopoubel\AppData\Roaming\Python\Python312\site-packages\httpx\_client.py", line 1513, in request
    return await self.send(request, auth=auth, follow_redirects=follow_redirects)
           ^^^^^^^^^^^^^^^^^^^^^^^^^^^^^^^^^^^^^^^^^^^^^^^^^^^^^^^^^^^^^^^^^^^^^^
  File "C:\Users\brenopoubel\AppData\Roaming\Python\Python312\site-packages\httpx\_client.py", line 1600, in send
    response = await self._send_handling_auth(
               ^^^^^^^^^^^^^^^^^^^^^^^^^^^^^^^
  File "C:\Users\brenopoubel\AppData\Roaming\Python\Python312\site-packages\httpx\_client.py", line 1628, in _send_handling_auth
    response = await self._send_handling_redirects(
               ^^^^^^^^^^^^^^^^^^^^^^^^^^^^^^^^^^^^
  File "C:\Users\brenopoubel\AppData\Roaming\Python\Python312\site-packages\httpx\_client.py", line 1665, in _send_handling_redirects
    response = await self._send_single_request(request)
               ^^^^^^^^^^^^^^^^^^^^^^^^^^^^^^^^^^^^^^^^
  File "C:\Users\brenopoubel\AppData\Roaming\Python\Python312\site-packages\httpx\_client.py", line 1702, in _send_single_request
    response = await transport.handle_async_request(request)
               ^^^^^^^^^^^^^^^^^^^^^^^^^^^^^^^^^^^^^^^^^^^^^
  File "C:\Users\brenopoubel\AppData\Roaming\Python\Python312\site-packages\httpx\_transports\default.py", line 290, in handle_async_request
    with map_httpcore_exceptions():
  File "C:\Program Files\Python312\Lib\contextlib.py", line 158, in __exit__
    self.gen.throw(value)
  File "C:\Users\brenopoubel\AppData\Roaming\Python\Python312\site-packages\httpx\_transports\default.py", line 77, in map_httpcore_exceptions
    raise mapped_exc(message) from exc
httpx.ReadTimeout
2024-06-18 07:59:26,607 - pocketoption - DEBUG - Old Session expired!! Trying to login again..
2024-06-18 07:59:31,719 - pocketoption - ERROR - ERR_BROADCAST: 
Traceback (most recent call last):
  File "C:\Users\brenopoubel\AppData\Roaming\Python\Python312\site-packages\anyio\streams\tls.py", line 131, in _call_sslobject_method
    result = func(*args)
             ^^^^^^^^^^^
  File "C:\Program Files\Python312\Lib\ssl.py", line 859, in read
    v = self._sslobj.read(len)
        ^^^^^^^^^^^^^^^^^^^^^^
ssl.SSLWantReadError: The operation did not complete (read) (_ssl.c:2559)

During handling of the above exception, another exception occurred:

Traceback (most recent call last):
  File "C:\Users\brenopoubel\AppData\Roaming\Python\Python312\site-packages\httpcore\backends\asyncio.py", line 31, in read
    return await self._stream.receive(max_bytes=max_bytes)
           ^^^^^^^^^^^^^^^^^^^^^^^^^^^^^^^^^^^^^^^^^^^^^^^
  File "C:\Users\brenopoubel\AppData\Roaming\Python\Python312\site-packages\anyio\streams\tls.py", line 196, in receive
    data = await self._call_sslobject_method(self._ssl_object.read, max_bytes)
           ^^^^^^^^^^^^^^^^^^^^^^^^^^^^^^^^^^^^^^^^^^^^^^^^^^^^^^^^^^^^^^^^^^^
  File "C:\Users\brenopoubel\AppData\Roaming\Python\Python312\site-packages\anyio\streams\tls.py", line 138, in _call_sslobject_method
    data = await self.transport_stream.receive()
           ^^^^^^^^^^^^^^^^^^^^^^^^^^^^^^^^^^^^^
  File "C:\Users\brenopoubel\AppData\Roaming\Python\Python312\site-packages\anyio\_backends\_asyncio.py", line 1203, in receive
    await self._protocol.read_event.wait()
  File "C:\Program Files\Python312\Lib\asyncio\locks.py", line 212, in wait
    await fut
asyncio.exceptions.CancelledError

During handling of the above exception, another exception occurred:

Traceback (most recent call last):
  File "C:\Users\brenopoubel\AppData\Roaming\Python\Python312\site-packages\httpcore\_exceptions.py", line 8, in map_exceptions
    yield
  File "C:\Users\brenopoubel\AppData\Roaming\Python\Python312\site-packages\httpcore\backends\asyncio.py", line 29, in read
    with anyio.fail_after(timeout):
  File "C:\Users\brenopoubel\AppData\Roaming\Python\Python312\site-packages\anyio\_core\_tasks.py", line 119, in __exit__
    raise TimeoutError
TimeoutError

During handling of the above exception, another exception occurred:

Traceback (most recent call last):
  File "C:\Users\brenopoubel\AppData\Roaming\Python\Python312\site-packages\httpx\_transports\default.py", line 60, in map_httpcore_exceptions
    yield
  File "C:\Users\brenopoubel\AppData\Roaming\Python\Python312\site-packages\httpx\_transports\default.py", line 291, in handle_async_request
    resp = await self._pool.handle_async_request(req)
           ^^^^^^^^^^^^^^^^^^^^^^^^^^^^^^^^^^^^^^^^^^
  File "C:\Users\brenopoubel\AppData\Roaming\Python\Python312\site-packages\httpcore\_async\connection_pool.py", line 253, in handle_async_request
    raise exc
  File "C:\Users\brenopoubel\AppData\Roaming\Python\Python312\site-packages\httpcore\_async\connection_pool.py", line 237, in handle_async_request
    response = await connection.handle_async_request(request)
               ^^^^^^^^^^^^^^^^^^^^^^^^^^^^^^^^^^^^^^^^^^^^^^
  File "C:\Users\brenopoubel\AppData\Roaming\Python\Python312\site-packages\httpcore\_async\connection.py", line 90, in handle_async_request
    return await self._connection.handle_async_request(request)
           ^^^^^^^^^^^^^^^^^^^^^^^^^^^^^^^^^^^^^^^^^^^^^^^^^^^^
  File "C:\Users\brenopoubel\AppData\Roaming\Python\Python312\site-packages\httpcore\_async\http11.py", line 102, in handle_async_request
    raise exc
  File "C:\Users\brenopoubel\AppData\Roaming\Python\Python312\site-packages\httpcore\_async\http11.py", line 81, in handle_async_request
    ) = await self._receive_response_headers(**kwargs)
        ^^^^^^^^^^^^^^^^^^^^^^^^^^^^^^^^^^^^^^^^^^^^^^
  File "C:\Users\brenopoubel\AppData\Roaming\Python\Python312\site-packages\httpcore\_async\http11.py", line 143, in _receive_response_headers
    event = await self._receive_event(timeout=timeout)
            ^^^^^^^^^^^^^^^^^^^^^^^^^^^^^^^^^^^^^^^^^^
  File "C:\Users\brenopoubel\AppData\Roaming\Python\Python312\site-packages\httpcore\_async\http11.py", line 172, in _receive_event
    data = await self._network_stream.read(
           ^^^^^^^^^^^^^^^^^^^^^^^^^^^^^^^^
  File "C:\Users\brenopoubel\AppData\Roaming\Python\Python312\site-packages\httpcore\backends\asyncio.py", line 28, in read
    with map_exceptions(exc_map):
  File "C:\Program Files\Python312\Lib\contextlib.py", line 158, in __exit__
    self.gen.throw(value)
  File "C:\Users\brenopoubel\AppData\Roaming\Python\Python312\site-packages\httpcore\_exceptions.py", line 12, in map_exceptions
    raise to_exc(exc)
httpcore.ReadTimeout

The above exception was the direct cause of the following exception:

Traceback (most recent call last):
  File "C:\Users\brenopoubel\My Drive\Monitors\pocketoption2\main.py", line 617, in broadcast
    current_stats = await get_statistics()
                    ^^^^^^^^^^^^^^^^^^^^^^
  File "C:\Users\brenopoubel\My Drive\Monitors\pocketoption2\main.py", line 468, in get_statistics
    await perform_login()
  File "C:\Users\brenopoubel\My Drive\Monitors\pocketoption2\main.py", line 526, in perform_login
    res = await core.session.get(url=core.home_link)
          ^^^^^^^^^^^^^^^^^^^^^^^^^^^^^^^^^^^^^^^^^^
  File "C:\Users\brenopoubel\AppData\Roaming\Python\Python312\site-packages\httpx\_client.py", line 1736, in get
    return await self.request(
           ^^^^^^^^^^^^^^^^^^^
  File "C:\Users\brenopoubel\AppData\Roaming\Python\Python312\site-packages\httpx\_client.py", line 1513, in request
    return await self.send(request, auth=auth, follow_redirects=follow_redirects)
           ^^^^^^^^^^^^^^^^^^^^^^^^^^^^^^^^^^^^^^^^^^^^^^^^^^^^^^^^^^^^^^^^^^^^^^
  File "C:\Users\brenopoubel\AppData\Roaming\Python\Python312\site-packages\httpx\_client.py", line 1600, in send
    response = await self._send_handling_auth(
               ^^^^^^^^^^^^^^^^^^^^^^^^^^^^^^^
  File "C:\Users\brenopoubel\AppData\Roaming\Python\Python312\site-packages\httpx\_client.py", line 1628, in _send_handling_auth
    response = await self._send_handling_redirects(
               ^^^^^^^^^^^^^^^^^^^^^^^^^^^^^^^^^^^^
  File "C:\Users\brenopoubel\AppData\Roaming\Python\Python312\site-packages\httpx\_client.py", line 1665, in _send_handling_redirects
    response = await self._send_single_request(request)
               ^^^^^^^^^^^^^^^^^^^^^^^^^^^^^^^^^^^^^^^^
  File "C:\Users\brenopoubel\AppData\Roaming\Python\Python312\site-packages\httpx\_client.py", line 1702, in _send_single_request
    response = await transport.handle_async_request(request)
               ^^^^^^^^^^^^^^^^^^^^^^^^^^^^^^^^^^^^^^^^^^^^^
  File "C:\Users\brenopoubel\AppData\Roaming\Python\Python312\site-packages\httpx\_transports\default.py", line 290, in handle_async_request
    with map_httpcore_exceptions():
  File "C:\Program Files\Python312\Lib\contextlib.py", line 158, in __exit__
    self.gen.throw(value)
  File "C:\Users\brenopoubel\AppData\Roaming\Python\Python312\site-packages\httpx\_transports\default.py", line 77, in map_httpcore_exceptions
    raise mapped_exc(message) from exc
httpx.ReadTimeout
2024-06-18 07:59:42,820 - pocketoption - DEBUG - Old Session expired!! Trying to login again..
2024-06-18 07:59:47,886 - pocketoption - ERROR - ERR_BROADCAST: 
Traceback (most recent call last):
  File "C:\Users\brenopoubel\AppData\Roaming\Python\Python312\site-packages\anyio\streams\tls.py", line 131, in _call_sslobject_method
    result = func(*args)
             ^^^^^^^^^^^
  File "C:\Program Files\Python312\Lib\ssl.py", line 859, in read
    v = self._sslobj.read(len)
        ^^^^^^^^^^^^^^^^^^^^^^
ssl.SSLWantReadError: The operation did not complete (read) (_ssl.c:2559)

During handling of the above exception, another exception occurred:

Traceback (most recent call last):
  File "C:\Users\brenopoubel\AppData\Roaming\Python\Python312\site-packages\httpcore\backends\asyncio.py", line 31, in read
    return await self._stream.receive(max_bytes=max_bytes)
           ^^^^^^^^^^^^^^^^^^^^^^^^^^^^^^^^^^^^^^^^^^^^^^^
  File "C:\Users\brenopoubel\AppData\Roaming\Python\Python312\site-packages\anyio\streams\tls.py", line 196, in receive
    data = await self._call_sslobject_method(self._ssl_object.read, max_bytes)
           ^^^^^^^^^^^^^^^^^^^^^^^^^^^^^^^^^^^^^^^^^^^^^^^^^^^^^^^^^^^^^^^^^^^
  File "C:\Users\brenopoubel\AppData\Roaming\Python\Python312\site-packages\anyio\streams\tls.py", line 138, in _call_sslobject_method
    data = await self.transport_stream.receive()
           ^^^^^^^^^^^^^^^^^^^^^^^^^^^^^^^^^^^^^
  File "C:\Users\brenopoubel\AppData\Roaming\Python\Python312\site-packages\anyio\_backends\_asyncio.py", line 1203, in receive
    await self._protocol.read_event.wait()
  File "C:\Program Files\Python312\Lib\asyncio\locks.py", line 212, in wait
    await fut
asyncio.exceptions.CancelledError

During handling of the above exception, another exception occurred:

Traceback (most recent call last):
  File "C:\Users\brenopoubel\AppData\Roaming\Python\Python312\site-packages\httpcore\_exceptions.py", line 8, in map_exceptions
    yield
  File "C:\Users\brenopoubel\AppData\Roaming\Python\Python312\site-packages\httpcore\backends\asyncio.py", line 29, in read
    with anyio.fail_after(timeout):
  File "C:\Users\brenopoubel\AppData\Roaming\Python\Python312\site-packages\anyio\_core\_tasks.py", line 119, in __exit__
    raise TimeoutError
TimeoutError

During handling of the above exception, another exception occurred:

Traceback (most recent call last):
  File "C:\Users\brenopoubel\AppData\Roaming\Python\Python312\site-packages\httpx\_transports\default.py", line 60, in map_httpcore_exceptions
    yield
  File "C:\Users\brenopoubel\AppData\Roaming\Python\Python312\site-packages\httpx\_transports\default.py", line 291, in handle_async_request
    resp = await self._pool.handle_async_request(req)
           ^^^^^^^^^^^^^^^^^^^^^^^^^^^^^^^^^^^^^^^^^^
  File "C:\Users\brenopoubel\AppData\Roaming\Python\Python312\site-packages\httpcore\_async\connection_pool.py", line 253, in handle_async_request
    raise exc
  File "C:\Users\brenopoubel\AppData\Roaming\Python\Python312\site-packages\httpcore\_async\connection_pool.py", line 237, in handle_async_request
    response = await connection.handle_async_request(request)
               ^^^^^^^^^^^^^^^^^^^^^^^^^^^^^^^^^^^^^^^^^^^^^^
  File "C:\Users\brenopoubel\AppData\Roaming\Python\Python312\site-packages\httpcore\_async\connection.py", line 90, in handle_async_request
    return await self._connection.handle_async_request(request)
           ^^^^^^^^^^^^^^^^^^^^^^^^^^^^^^^^^^^^^^^^^^^^^^^^^^^^
  File "C:\Users\brenopoubel\AppData\Roaming\Python\Python312\site-packages\httpcore\_async\http11.py", line 102, in handle_async_request
    raise exc
  File "C:\Users\brenopoubel\AppData\Roaming\Python\Python312\site-packages\httpcore\_async\http11.py", line 81, in handle_async_request
    ) = await self._receive_response_headers(**kwargs)
        ^^^^^^^^^^^^^^^^^^^^^^^^^^^^^^^^^^^^^^^^^^^^^^
  File "C:\Users\brenopoubel\AppData\Roaming\Python\Python312\site-packages\httpcore\_async\http11.py", line 143, in _receive_response_headers
    event = await self._receive_event(timeout=timeout)
            ^^^^^^^^^^^^^^^^^^^^^^^^^^^^^^^^^^^^^^^^^^
  File "C:\Users\brenopoubel\AppData\Roaming\Python\Python312\site-packages\httpcore\_async\http11.py", line 172, in _receive_event
    data = await self._network_stream.read(
           ^^^^^^^^^^^^^^^^^^^^^^^^^^^^^^^^
  File "C:\Users\brenopoubel\AppData\Roaming\Python\Python312\site-packages\httpcore\backends\asyncio.py", line 28, in read
    with map_exceptions(exc_map):
  File "C:\Program Files\Python312\Lib\contextlib.py", line 158, in __exit__
    self.gen.throw(value)
  File "C:\Users\brenopoubel\AppData\Roaming\Python\Python312\site-packages\httpcore\_exceptions.py", line 12, in map_exceptions
    raise to_exc(exc)
httpcore.ReadTimeout

The above exception was the direct cause of the following exception:

Traceback (most recent call last):
  File "C:\Users\brenopoubel\My Drive\Monitors\pocketoption2\main.py", line 617, in broadcast
    current_stats = await get_statistics()
                    ^^^^^^^^^^^^^^^^^^^^^^
  File "C:\Users\brenopoubel\My Drive\Monitors\pocketoption2\main.py", line 468, in get_statistics
    await perform_login()
  File "C:\Users\brenopoubel\My Drive\Monitors\pocketoption2\main.py", line 526, in perform_login
    res = await core.session.get(url=core.home_link)
          ^^^^^^^^^^^^^^^^^^^^^^^^^^^^^^^^^^^^^^^^^^
  File "C:\Users\brenopoubel\AppData\Roaming\Python\Python312\site-packages\httpx\_client.py", line 1736, in get
    return await self.request(
           ^^^^^^^^^^^^^^^^^^^
  File "C:\Users\brenopoubel\AppData\Roaming\Python\Python312\site-packages\httpx\_client.py", line 1513, in request
    return await self.send(request, auth=auth, follow_redirects=follow_redirects)
           ^^^^^^^^^^^^^^^^^^^^^^^^^^^^^^^^^^^^^^^^^^^^^^^^^^^^^^^^^^^^^^^^^^^^^^
  File "C:\Users\brenopoubel\AppData\Roaming\Python\Python312\site-packages\httpx\_client.py", line 1600, in send
    response = await self._send_handling_auth(
               ^^^^^^^^^^^^^^^^^^^^^^^^^^^^^^^
  File "C:\Users\brenopoubel\AppData\Roaming\Python\Python312\site-packages\httpx\_client.py", line 1628, in _send_handling_auth
    response = await self._send_handling_redirects(
               ^^^^^^^^^^^^^^^^^^^^^^^^^^^^^^^^^^^^
  File "C:\Users\brenopoubel\AppData\Roaming\Python\Python312\site-packages\httpx\_client.py", line 1665, in _send_handling_redirects
    response = await self._send_single_request(request)
               ^^^^^^^^^^^^^^^^^^^^^^^^^^^^^^^^^^^^^^^^
  File "C:\Users\brenopoubel\AppData\Roaming\Python\Python312\site-packages\httpx\_client.py", line 1702, in _send_single_request
    response = await transport.handle_async_request(request)
               ^^^^^^^^^^^^^^^^^^^^^^^^^^^^^^^^^^^^^^^^^^^^^
  File "C:\Users\brenopoubel\AppData\Roaming\Python\Python312\site-packages\httpx\_transports\default.py", line 290, in handle_async_request
    with map_httpcore_exceptions():
  File "C:\Program Files\Python312\Lib\contextlib.py", line 158, in __exit__
    self.gen.throw(value)
  File "C:\Users\brenopoubel\AppData\Roaming\Python\Python312\site-packages\httpx\_transports\default.py", line 77, in map_httpcore_exceptions
    raise mapped_exc(message) from exc
httpx.ReadTimeout
2024-06-18 07:59:59,003 - pocketoption - DEBUG - Old Session expired!! Trying to login again..
2024-06-18 08:00:04,116 - pocketoption - ERROR - ERR_BROADCAST: 
Traceback (most recent call last):
  File "C:\Users\brenopoubel\AppData\Roaming\Python\Python312\site-packages\anyio\streams\tls.py", line 131, in _call_sslobject_method
    result = func(*args)
             ^^^^^^^^^^^
  File "C:\Program Files\Python312\Lib\ssl.py", line 859, in read
    v = self._sslobj.read(len)
        ^^^^^^^^^^^^^^^^^^^^^^
ssl.SSLWantReadError: The operation did not complete (read) (_ssl.c:2559)

During handling of the above exception, another exception occurred:

Traceback (most recent call last):
  File "C:\Users\brenopoubel\AppData\Roaming\Python\Python312\site-packages\httpcore\backends\asyncio.py", line 31, in read
    return await self._stream.receive(max_bytes=max_bytes)
           ^^^^^^^^^^^^^^^^^^^^^^^^^^^^^^^^^^^^^^^^^^^^^^^
  File "C:\Users\brenopoubel\AppData\Roaming\Python\Python312\site-packages\anyio\streams\tls.py", line 196, in receive
    data = await self._call_sslobject_method(self._ssl_object.read, max_bytes)
           ^^^^^^^^^^^^^^^^^^^^^^^^^^^^^^^^^^^^^^^^^^^^^^^^^^^^^^^^^^^^^^^^^^^
  File "C:\Users\brenopoubel\AppData\Roaming\Python\Python312\site-packages\anyio\streams\tls.py", line 138, in _call_sslobject_method
    data = await self.transport_stream.receive()
           ^^^^^^^^^^^^^^^^^^^^^^^^^^^^^^^^^^^^^
  File "C:\Users\brenopoubel\AppData\Roaming\Python\Python312\site-packages\anyio\_backends\_asyncio.py", line 1203, in receive
    await self._protocol.read_event.wait()
  File "C:\Program Files\Python312\Lib\asyncio\locks.py", line 212, in wait
    await fut
asyncio.exceptions.CancelledError

During handling of the above exception, another exception occurred:

Traceback (most recent call last):
  File "C:\Users\brenopoubel\AppData\Roaming\Python\Python312\site-packages\httpcore\_exceptions.py", line 8, in map_exceptions
    yield
  File "C:\Users\brenopoubel\AppData\Roaming\Python\Python312\site-packages\httpcore\backends\asyncio.py", line 29, in read
    with anyio.fail_after(timeout):
  File "C:\Users\brenopoubel\AppData\Roaming\Python\Python312\site-packages\anyio\_core\_tasks.py", line 119, in __exit__
    raise TimeoutError
TimeoutError

During handling of the above exception, another exception occurred:

Traceback (most recent call last):
  File "C:\Users\brenopoubel\AppData\Roaming\Python\Python312\site-packages\httpx\_transports\default.py", line 60, in map_httpcore_exceptions
    yield
  File "C:\Users\brenopoubel\AppData\Roaming\Python\Python312\site-packages\httpx\_transports\default.py", line 291, in handle_async_request
    resp = await self._pool.handle_async_request(req)
           ^^^^^^^^^^^^^^^^^^^^^^^^^^^^^^^^^^^^^^^^^^
  File "C:\Users\brenopoubel\AppData\Roaming\Python\Python312\site-packages\httpcore\_async\connection_pool.py", line 253, in handle_async_request
    raise exc
  File "C:\Users\brenopoubel\AppData\Roaming\Python\Python312\site-packages\httpcore\_async\connection_pool.py", line 237, in handle_async_request
    response = await connection.handle_async_request(request)
               ^^^^^^^^^^^^^^^^^^^^^^^^^^^^^^^^^^^^^^^^^^^^^^
  File "C:\Users\brenopoubel\AppData\Roaming\Python\Python312\site-packages\httpcore\_async\connection.py", line 90, in handle_async_request
    return await self._connection.handle_async_request(request)
           ^^^^^^^^^^^^^^^^^^^^^^^^^^^^^^^^^^^^^^^^^^^^^^^^^^^^
  File "C:\Users\brenopoubel\AppData\Roaming\Python\Python312\site-packages\httpcore\_async\http11.py", line 102, in handle_async_request
    raise exc
  File "C:\Users\brenopoubel\AppData\Roaming\Python\Python312\site-packages\httpcore\_async\http11.py", line 81, in handle_async_request
    ) = await self._receive_response_headers(**kwargs)
        ^^^^^^^^^^^^^^^^^^^^^^^^^^^^^^^^^^^^^^^^^^^^^^
  File "C:\Users\brenopoubel\AppData\Roaming\Python\Python312\site-packages\httpcore\_async\http11.py", line 143, in _receive_response_headers
    event = await self._receive_event(timeout=timeout)
            ^^^^^^^^^^^^^^^^^^^^^^^^^^^^^^^^^^^^^^^^^^
  File "C:\Users\brenopoubel\AppData\Roaming\Python\Python312\site-packages\httpcore\_async\http11.py", line 172, in _receive_event
    data = await self._network_stream.read(
           ^^^^^^^^^^^^^^^^^^^^^^^^^^^^^^^^
  File "C:\Users\brenopoubel\AppData\Roaming\Python\Python312\site-packages\httpcore\backends\asyncio.py", line 28, in read
    with map_exceptions(exc_map):
  File "C:\Program Files\Python312\Lib\contextlib.py", line 158, in __exit__
    self.gen.throw(value)
  File "C:\Users\brenopoubel\AppData\Roaming\Python\Python312\site-packages\httpcore\_exceptions.py", line 12, in map_exceptions
    raise to_exc(exc)
httpcore.ReadTimeout

The above exception was the direct cause of the following exception:

Traceback (most recent call last):
  File "C:\Users\brenopoubel\My Drive\Monitors\pocketoption2\main.py", line 617, in broadcast
    current_stats = await get_statistics()
                    ^^^^^^^^^^^^^^^^^^^^^^
  File "C:\Users\brenopoubel\My Drive\Monitors\pocketoption2\main.py", line 468, in get_statistics
    await perform_login()
  File "C:\Users\brenopoubel\My Drive\Monitors\pocketoption2\main.py", line 526, in perform_login
    res = await core.session.get(url=core.home_link)
          ^^^^^^^^^^^^^^^^^^^^^^^^^^^^^^^^^^^^^^^^^^
  File "C:\Users\brenopoubel\AppData\Roaming\Python\Python312\site-packages\httpx\_client.py", line 1736, in get
    return await self.request(
           ^^^^^^^^^^^^^^^^^^^
  File "C:\Users\brenopoubel\AppData\Roaming\Python\Python312\site-packages\httpx\_client.py", line 1513, in request
    return await self.send(request, auth=auth, follow_redirects=follow_redirects)
           ^^^^^^^^^^^^^^^^^^^^^^^^^^^^^^^^^^^^^^^^^^^^^^^^^^^^^^^^^^^^^^^^^^^^^^
  File "C:\Users\brenopoubel\AppData\Roaming\Python\Python312\site-packages\httpx\_client.py", line 1600, in send
    response = await self._send_handling_auth(
               ^^^^^^^^^^^^^^^^^^^^^^^^^^^^^^^
  File "C:\Users\brenopoubel\AppData\Roaming\Python\Python312\site-packages\httpx\_client.py", line 1628, in _send_handling_auth
    response = await self._send_handling_redirects(
               ^^^^^^^^^^^^^^^^^^^^^^^^^^^^^^^^^^^^
  File "C:\Users\brenopoubel\AppData\Roaming\Python\Python312\site-packages\httpx\_client.py", line 1665, in _send_handling_redirects
    response = await self._send_single_request(request)
               ^^^^^^^^^^^^^^^^^^^^^^^^^^^^^^^^^^^^^^^^
  File "C:\Users\brenopoubel\AppData\Roaming\Python\Python312\site-packages\httpx\_client.py", line 1702, in _send_single_request
    response = await transport.handle_async_request(request)
               ^^^^^^^^^^^^^^^^^^^^^^^^^^^^^^^^^^^^^^^^^^^^^
  File "C:\Users\brenopoubel\AppData\Roaming\Python\Python312\site-packages\httpx\_transports\default.py", line 290, in handle_async_request
    with map_httpcore_exceptions():
  File "C:\Program Files\Python312\Lib\contextlib.py", line 158, in __exit__
    self.gen.throw(value)
  File "C:\Users\brenopoubel\AppData\Roaming\Python\Python312\site-packages\httpx\_transports\default.py", line 77, in map_httpcore_exceptions
    raise mapped_exc(message) from exc
httpx.ReadTimeout
2024-06-18 08:01:05,534 - pocketoption - DEBUG - Cookies Saved!!
2024-06-18 08:01:05,534 - pocketoption - ERROR - ERR_GET_LATEST_PAYMENT_REQUEST: 164123
Traceback (most recent call last):
  File "C:\Users\brenopoubel\AppData\Roaming\Python\Python312\site-packages\anyio\streams\tls.py", line 131, in _call_sslobject_method
    result = func(*args)
             ^^^^^^^^^^^
  File "C:\Program Files\Python312\Lib\ssl.py", line 859, in read
    v = self._sslobj.read(len)
        ^^^^^^^^^^^^^^^^^^^^^^
ssl.SSLWantReadError: The operation did not complete (read) (_ssl.c:2559)

During handling of the above exception, another exception occurred:

Traceback (most recent call last):
  File "C:\Users\brenopoubel\AppData\Roaming\Python\Python312\site-packages\httpcore\backends\asyncio.py", line 31, in read
    return await self._stream.receive(max_bytes=max_bytes)
           ^^^^^^^^^^^^^^^^^^^^^^^^^^^^^^^^^^^^^^^^^^^^^^^
  File "C:\Users\brenopoubel\AppData\Roaming\Python\Python312\site-packages\anyio\streams\tls.py", line 196, in receive
    data = await self._call_sslobject_method(self._ssl_object.read, max_bytes)
           ^^^^^^^^^^^^^^^^^^^^^^^^^^^^^^^^^^^^^^^^^^^^^^^^^^^^^^^^^^^^^^^^^^^
  File "C:\Users\brenopoubel\AppData\Roaming\Python\Python312\site-packages\anyio\streams\tls.py", line 138, in _call_sslobject_method
    data = await self.transport_stream.receive()
           ^^^^^^^^^^^^^^^^^^^^^^^^^^^^^^^^^^^^^
  File "C:\Users\brenopoubel\AppData\Roaming\Python\Python312\site-packages\anyio\_backends\_asyncio.py", line 1203, in receive
    await self._protocol.read_event.wait()
  File "C:\Program Files\Python312\Lib\asyncio\locks.py", line 212, in wait
    await fut
asyncio.exceptions.CancelledError

During handling of the above exception, another exception occurred:

Traceback (most recent call last):
  File "C:\Users\brenopoubel\AppData\Roaming\Python\Python312\site-packages\httpcore\_exceptions.py", line 8, in map_exceptions
    yield
  File "C:\Users\brenopoubel\AppData\Roaming\Python\Python312\site-packages\httpcore\backends\asyncio.py", line 29, in read
    with anyio.fail_after(timeout):
  File "C:\Users\brenopoubel\AppData\Roaming\Python\Python312\site-packages\anyio\_core\_tasks.py", line 119, in __exit__
    raise TimeoutError
TimeoutError

During handling of the above exception, another exception occurred:

Traceback (most recent call last):
  File "C:\Users\brenopoubel\AppData\Roaming\Python\Python312\site-packages\httpx\_transports\default.py", line 60, in map_httpcore_exceptions
    yield
  File "C:\Users\brenopoubel\AppData\Roaming\Python\Python312\site-packages\httpx\_transports\default.py", line 291, in handle_async_request
    resp = await self._pool.handle_async_request(req)
           ^^^^^^^^^^^^^^^^^^^^^^^^^^^^^^^^^^^^^^^^^^
  File "C:\Users\brenopoubel\AppData\Roaming\Python\Python312\site-packages\httpcore\_async\connection_pool.py", line 253, in handle_async_request
    raise exc
  File "C:\Users\brenopoubel\AppData\Roaming\Python\Python312\site-packages\httpcore\_async\connection_pool.py", line 237, in handle_async_request
    response = await connection.handle_async_request(request)
               ^^^^^^^^^^^^^^^^^^^^^^^^^^^^^^^^^^^^^^^^^^^^^^
  File "C:\Users\brenopoubel\AppData\Roaming\Python\Python312\site-packages\httpcore\_async\connection.py", line 90, in handle_async_request
    return await self._connection.handle_async_request(request)
           ^^^^^^^^^^^^^^^^^^^^^^^^^^^^^^^^^^^^^^^^^^^^^^^^^^^^
  File "C:\Users\brenopoubel\AppData\Roaming\Python\Python312\site-packages\httpcore\_async\http11.py", line 102, in handle_async_request
    raise exc
  File "C:\Users\brenopoubel\AppData\Roaming\Python\Python312\site-packages\httpcore\_async\http11.py", line 81, in handle_async_request
    ) = await self._receive_response_headers(**kwargs)
        ^^^^^^^^^^^^^^^^^^^^^^^^^^^^^^^^^^^^^^^^^^^^^^
  File "C:\Users\brenopoubel\AppData\Roaming\Python\Python312\site-packages\httpcore\_async\http11.py", line 143, in _receive_response_headers
    event = await self._receive_event(timeout=timeout)
            ^^^^^^^^^^^^^^^^^^^^^^^^^^^^^^^^^^^^^^^^^^
  File "C:\Users\brenopoubel\AppData\Roaming\Python\Python312\site-packages\httpcore\_async\http11.py", line 172, in _receive_event
    data = await self._network_stream.read(
           ^^^^^^^^^^^^^^^^^^^^^^^^^^^^^^^^
  File "C:\Users\brenopoubel\AppData\Roaming\Python\Python312\site-packages\httpcore\backends\asyncio.py", line 28, in read
    with map_exceptions(exc_map):
  File "C:\Program Files\Python312\Lib\contextlib.py", line 158, in __exit__
    self.gen.throw(value)
  File "C:\Users\brenopoubel\AppData\Roaming\Python\Python312\site-packages\httpcore\_exceptions.py", line 12, in map_exceptions
    raise to_exc(exc)
httpcore.ReadTimeout

The above exception was the direct cause of the following exception:

Traceback (most recent call last):
  File "C:\Users\brenopoubel\My Drive\Monitors\pocketoption2\main.py", line 757, in get_latest_payment_requests
    res = await fetch(core.payment_history_link)
          ^^^^^^^^^^^^^^^^^^^^^^^^^^^^^^^^^^^^^^
  File "C:\Users\brenopoubel\My Drive\Monitors\pocketoption2\main.py", line 79, in fetch
    return await core.session.get(url, **kwargs)
           ^^^^^^^^^^^^^^^^^^^^^^^^^^^^^^^^^^^^^
  File "C:\Users\brenopoubel\AppData\Roaming\Python\Python312\site-packages\httpx\_client.py", line 1736, in get
    return await self.request(
           ^^^^^^^^^^^^^^^^^^^
  File "C:\Users\brenopoubel\AppData\Roaming\Python\Python312\site-packages\httpx\_client.py", line 1513, in request
    return await self.send(request, auth=auth, follow_redirects=follow_redirects)
           ^^^^^^^^^^^^^^^^^^^^^^^^^^^^^^^^^^^^^^^^^^^^^^^^^^^^^^^^^^^^^^^^^^^^^^
  File "C:\Users\brenopoubel\AppData\Roaming\Python\Python312\site-packages\httpx\_client.py", line 1600, in send
    response = await self._send_handling_auth(
               ^^^^^^^^^^^^^^^^^^^^^^^^^^^^^^^
  File "C:\Users\brenopoubel\AppData\Roaming\Python\Python312\site-packages\httpx\_client.py", line 1628, in _send_handling_auth
    response = await self._send_handling_redirects(
               ^^^^^^^^^^^^^^^^^^^^^^^^^^^^^^^^^^^^
  File "C:\Users\brenopoubel\AppData\Roaming\Python\Python312\site-packages\httpx\_client.py", line 1665, in _send_handling_redirects
    response = await self._send_single_request(request)
               ^^^^^^^^^^^^^^^^^^^^^^^^^^^^^^^^^^^^^^^^
  File "C:\Users\brenopoubel\AppData\Roaming\Python\Python312\site-packages\httpx\_client.py", line 1702, in _send_single_request
    response = await transport.handle_async_request(request)
               ^^^^^^^^^^^^^^^^^^^^^^^^^^^^^^^^^^^^^^^^^^^^^
  File "C:\Users\brenopoubel\AppData\Roaming\Python\Python312\site-packages\httpx\_transports\default.py", line 290, in handle_async_request
    with map_httpcore_exceptions():
  File "C:\Program Files\Python312\Lib\contextlib.py", line 158, in __exit__
    self.gen.throw(value)
  File "C:\Users\brenopoubel\AppData\Roaming\Python\Python312\site-packages\httpx\_transports\default.py", line 77, in map_httpcore_exceptions
    raise mapped_exc(message) from exc
httpx.ReadTimeout
2024-06-18 08:01:05,549 - pocketoption - DEBUG - First Check -> Latest ID: 164123 | Existing ID: 164123
2024-06-18 08:01:10,664 - pocketoption - DEBUG - Cookies Saved!!
2024-06-18 08:01:17,760 - pocketoption - DEBUG - Cookies Saved!!
2024-06-18 08:01:17,760 - pocketoption - ERROR - ERR_PROCESS_SUMMARY -> Period: Current week -> Error: 
Traceback (most recent call last):
  File "C:\Users\brenopoubel\AppData\Roaming\Python\Python312\site-packages\anyio\streams\tls.py", line 131, in _call_sslobject_method
    result = func(*args)
             ^^^^^^^^^^^
  File "C:\Program Files\Python312\Lib\ssl.py", line 859, in read
    v = self._sslobj.read(len)
        ^^^^^^^^^^^^^^^^^^^^^^
ssl.SSLWantReadError: The operation did not complete (read) (_ssl.c:2559)

During handling of the above exception, another exception occurred:

Traceback (most recent call last):
  File "C:\Users\brenopoubel\AppData\Roaming\Python\Python312\site-packages\httpcore\backends\asyncio.py", line 31, in read
    return await self._stream.receive(max_bytes=max_bytes)
           ^^^^^^^^^^^^^^^^^^^^^^^^^^^^^^^^^^^^^^^^^^^^^^^
  File "C:\Users\brenopoubel\AppData\Roaming\Python\Python312\site-packages\anyio\streams\tls.py", line 196, in receive
    data = await self._call_sslobject_method(self._ssl_object.read, max_bytes)
           ^^^^^^^^^^^^^^^^^^^^^^^^^^^^^^^^^^^^^^^^^^^^^^^^^^^^^^^^^^^^^^^^^^^
  File "C:\Users\brenopoubel\AppData\Roaming\Python\Python312\site-packages\anyio\streams\tls.py", line 138, in _call_sslobject_method
    data = await self.transport_stream.receive()
           ^^^^^^^^^^^^^^^^^^^^^^^^^^^^^^^^^^^^^
  File "C:\Users\brenopoubel\AppData\Roaming\Python\Python312\site-packages\anyio\_backends\_asyncio.py", line 1203, in receive
    await self._protocol.read_event.wait()
  File "C:\Program Files\Python312\Lib\asyncio\locks.py", line 212, in wait
    await fut
asyncio.exceptions.CancelledError

During handling of the above exception, another exception occurred:

Traceback (most recent call last):
  File "C:\Users\brenopoubel\AppData\Roaming\Python\Python312\site-packages\httpcore\_exceptions.py", line 8, in map_exceptions
    yield
  File "C:\Users\brenopoubel\AppData\Roaming\Python\Python312\site-packages\httpcore\backends\asyncio.py", line 29, in read
    with anyio.fail_after(timeout):
  File "C:\Users\brenopoubel\AppData\Roaming\Python\Python312\site-packages\anyio\_core\_tasks.py", line 119, in __exit__
    raise TimeoutError
TimeoutError

During handling of the above exception, another exception occurred:

Traceback (most recent call last):
  File "C:\Users\brenopoubel\AppData\Roaming\Python\Python312\site-packages\httpx\_transports\default.py", line 60, in map_httpcore_exceptions
    yield
  File "C:\Users\brenopoubel\AppData\Roaming\Python\Python312\site-packages\httpx\_transports\default.py", line 291, in handle_async_request
    resp = await self._pool.handle_async_request(req)
           ^^^^^^^^^^^^^^^^^^^^^^^^^^^^^^^^^^^^^^^^^^
  File "C:\Users\brenopoubel\AppData\Roaming\Python\Python312\site-packages\httpcore\_async\connection_pool.py", line 253, in handle_async_request
    raise exc
  File "C:\Users\brenopoubel\AppData\Roaming\Python\Python312\site-packages\httpcore\_async\connection_pool.py", line 237, in handle_async_request
    response = await connection.handle_async_request(request)
               ^^^^^^^^^^^^^^^^^^^^^^^^^^^^^^^^^^^^^^^^^^^^^^
  File "C:\Users\brenopoubel\AppData\Roaming\Python\Python312\site-packages\httpcore\_async\connection.py", line 90, in handle_async_request
    return await self._connection.handle_async_request(request)
           ^^^^^^^^^^^^^^^^^^^^^^^^^^^^^^^^^^^^^^^^^^^^^^^^^^^^
  File "C:\Users\brenopoubel\AppData\Roaming\Python\Python312\site-packages\httpcore\_async\http11.py", line 102, in handle_async_request
    raise exc
  File "C:\Users\brenopoubel\AppData\Roaming\Python\Python312\site-packages\httpcore\_async\http11.py", line 81, in handle_async_request
    ) = await self._receive_response_headers(**kwargs)
        ^^^^^^^^^^^^^^^^^^^^^^^^^^^^^^^^^^^^^^^^^^^^^^
  File "C:\Users\brenopoubel\AppData\Roaming\Python\Python312\site-packages\httpcore\_async\http11.py", line 143, in _receive_response_headers
    event = await self._receive_event(timeout=timeout)
            ^^^^^^^^^^^^^^^^^^^^^^^^^^^^^^^^^^^^^^^^^^
  File "C:\Users\brenopoubel\AppData\Roaming\Python\Python312\site-packages\httpcore\_async\http11.py", line 172, in _receive_event
    data = await self._network_stream.read(
           ^^^^^^^^^^^^^^^^^^^^^^^^^^^^^^^^
  File "C:\Users\brenopoubel\AppData\Roaming\Python\Python312\site-packages\httpcore\backends\asyncio.py", line 28, in read
    with map_exceptions(exc_map):
  File "C:\Program Files\Python312\Lib\contextlib.py", line 158, in __exit__
    self.gen.throw(value)
  File "C:\Users\brenopoubel\AppData\Roaming\Python\Python312\site-packages\httpcore\_exceptions.py", line 12, in map_exceptions
    raise to_exc(exc)
httpcore.ReadTimeout

The above exception was the direct cause of the following exception:

Traceback (most recent call last):
  File "C:\Users\brenopoubel\My Drive\Monitors\pocketoption2\main.py", line 174, in process_statistics
    res_statistics = await fetch(
                     ^^^^^^^^^^^^
  File "C:\Users\brenopoubel\My Drive\Monitors\pocketoption2\main.py", line 79, in fetch
    return await core.session.get(url, **kwargs)
           ^^^^^^^^^^^^^^^^^^^^^^^^^^^^^^^^^^^^^
  File "C:\Users\brenopoubel\AppData\Roaming\Python\Python312\site-packages\httpx\_client.py", line 1736, in get
    return await self.request(
           ^^^^^^^^^^^^^^^^^^^
  File "C:\Users\brenopoubel\AppData\Roaming\Python\Python312\site-packages\httpx\_client.py", line 1513, in request
    return await self.send(request, auth=auth, follow_redirects=follow_redirects)
           ^^^^^^^^^^^^^^^^^^^^^^^^^^^^^^^^^^^^^^^^^^^^^^^^^^^^^^^^^^^^^^^^^^^^^^
  File "C:\Users\brenopoubel\AppData\Roaming\Python\Python312\site-packages\httpx\_client.py", line 1600, in send
    response = await self._send_handling_auth(
               ^^^^^^^^^^^^^^^^^^^^^^^^^^^^^^^
  File "C:\Users\brenopoubel\AppData\Roaming\Python\Python312\site-packages\httpx\_client.py", line 1628, in _send_handling_auth
    response = await self._send_handling_redirects(
               ^^^^^^^^^^^^^^^^^^^^^^^^^^^^^^^^^^^^
  File "C:\Users\brenopoubel\AppData\Roaming\Python\Python312\site-packages\httpx\_client.py", line 1665, in _send_handling_redirects
    response = await self._send_single_request(request)
               ^^^^^^^^^^^^^^^^^^^^^^^^^^^^^^^^^^^^^^^^
  File "C:\Users\brenopoubel\AppData\Roaming\Python\Python312\site-packages\httpx\_client.py", line 1702, in _send_single_request
    response = await transport.handle_async_request(request)
               ^^^^^^^^^^^^^^^^^^^^^^^^^^^^^^^^^^^^^^^^^^^^^
  File "C:\Users\brenopoubel\AppData\Roaming\Python\Python312\site-packages\httpx\_transports\default.py", line 290, in handle_async_request
    with map_httpcore_exceptions():
  File "C:\Program Files\Python312\Lib\contextlib.py", line 158, in __exit__
    self.gen.throw(value)
  File "C:\Users\brenopoubel\AppData\Roaming\Python\Python312\site-packages\httpx\_transports\default.py", line 77, in map_httpcore_exceptions
    raise mapped_exc(message) from exc
httpx.ReadTimeout

During handling of the above exception, another exception occurred:

Traceback (most recent call last):
  File "C:\Users\brenopoubel\AppData\Roaming\Python\Python312\site-packages\anyio\streams\tls.py", line 131, in _call_sslobject_method
    result = func(*args)
             ^^^^^^^^^^^
  File "C:\Program Files\Python312\Lib\ssl.py", line 859, in read
    v = self._sslobj.read(len)
        ^^^^^^^^^^^^^^^^^^^^^^
ssl.SSLWantReadError: The operation did not complete (read) (_ssl.c:2559)

During handling of the above exception, another exception occurred:

Traceback (most recent call last):
  File "C:\Users\brenopoubel\AppData\Roaming\Python\Python312\site-packages\httpcore\backends\asyncio.py", line 31, in read
    return await self._stream.receive(max_bytes=max_bytes)
           ^^^^^^^^^^^^^^^^^^^^^^^^^^^^^^^^^^^^^^^^^^^^^^^
  File "C:\Users\brenopoubel\AppData\Roaming\Python\Python312\site-packages\anyio\streams\tls.py", line 196, in receive
    data = await self._call_sslobject_method(self._ssl_object.read, max_bytes)
           ^^^^^^^^^^^^^^^^^^^^^^^^^^^^^^^^^^^^^^^^^^^^^^^^^^^^^^^^^^^^^^^^^^^
  File "C:\Users\brenopoubel\AppData\Roaming\Python\Python312\site-packages\anyio\streams\tls.py", line 138, in _call_sslobject_method
    data = await self.transport_stream.receive()
           ^^^^^^^^^^^^^^^^^^^^^^^^^^^^^^^^^^^^^
  File "C:\Users\brenopoubel\AppData\Roaming\Python\Python312\site-packages\anyio\_backends\_asyncio.py", line 1203, in receive
    await self._protocol.read_event.wait()
  File "C:\Program Files\Python312\Lib\asyncio\locks.py", line 212, in wait
    await fut
asyncio.exceptions.CancelledError

During handling of the above exception, another exception occurred:

Traceback (most recent call last):
  File "C:\Users\brenopoubel\AppData\Roaming\Python\Python312\site-packages\httpcore\_exceptions.py", line 8, in map_exceptions
    yield
  File "C:\Users\brenopoubel\AppData\Roaming\Python\Python312\site-packages\httpcore\backends\asyncio.py", line 29, in read
    with anyio.fail_after(timeout):
  File "C:\Users\brenopoubel\AppData\Roaming\Python\Python312\site-packages\anyio\_core\_tasks.py", line 119, in __exit__
    raise TimeoutError
TimeoutError

During handling of the above exception, another exception occurred:

Traceback (most recent call last):
  File "C:\Users\brenopoubel\AppData\Roaming\Python\Python312\site-packages\httpx\_transports\default.py", line 60, in map_httpcore_exceptions
    yield
  File "C:\Users\brenopoubel\AppData\Roaming\Python\Python312\site-packages\httpx\_transports\default.py", line 291, in handle_async_request
    resp = await self._pool.handle_async_request(req)
           ^^^^^^^^^^^^^^^^^^^^^^^^^^^^^^^^^^^^^^^^^^
  File "C:\Users\brenopoubel\AppData\Roaming\Python\Python312\site-packages\httpcore\_async\connection_pool.py", line 253, in handle_async_request
    raise exc
  File "C:\Users\brenopoubel\AppData\Roaming\Python\Python312\site-packages\httpcore\_async\connection_pool.py", line 237, in handle_async_request
    response = await connection.handle_async_request(request)
               ^^^^^^^^^^^^^^^^^^^^^^^^^^^^^^^^^^^^^^^^^^^^^^
  File "C:\Users\brenopoubel\AppData\Roaming\Python\Python312\site-packages\httpcore\_async\connection.py", line 90, in handle_async_request
    return await self._connection.handle_async_request(request)
           ^^^^^^^^^^^^^^^^^^^^^^^^^^^^^^^^^^^^^^^^^^^^^^^^^^^^
  File "C:\Users\brenopoubel\AppData\Roaming\Python\Python312\site-packages\httpcore\_async\http11.py", line 102, in handle_async_request
    raise exc
  File "C:\Users\brenopoubel\AppData\Roaming\Python\Python312\site-packages\httpcore\_async\http11.py", line 81, in handle_async_request
    ) = await self._receive_response_headers(**kwargs)
        ^^^^^^^^^^^^^^^^^^^^^^^^^^^^^^^^^^^^^^^^^^^^^^
  File "C:\Users\brenopoubel\AppData\Roaming\Python\Python312\site-packages\httpcore\_async\http11.py", line 143, in _receive_response_headers
    event = await self._receive_event(timeout=timeout)
            ^^^^^^^^^^^^^^^^^^^^^^^^^^^^^^^^^^^^^^^^^^
  File "C:\Users\brenopoubel\AppData\Roaming\Python\Python312\site-packages\httpcore\_async\http11.py", line 172, in _receive_event
    data = await self._network_stream.read(
           ^^^^^^^^^^^^^^^^^^^^^^^^^^^^^^^^
  File "C:\Users\brenopoubel\AppData\Roaming\Python\Python312\site-packages\httpcore\backends\asyncio.py", line 28, in read
    with map_exceptions(exc_map):
  File "C:\Program Files\Python312\Lib\contextlib.py", line 158, in __exit__
    self.gen.throw(value)
  File "C:\Users\brenopoubel\AppData\Roaming\Python\Python312\site-packages\httpcore\_exceptions.py", line 12, in map_exceptions
    raise to_exc(exc)
httpcore.ReadTimeout

The above exception was the direct cause of the following exception:

Traceback (most recent call last):
  File "C:\Users\brenopoubel\My Drive\Monitors\pocketoption2\main.py", line 174, in process_statistics
    res_statistics = await fetch(
                     ^^^^^^^^^^^^
  File "C:\Users\brenopoubel\My Drive\Monitors\pocketoption2\main.py", line 79, in fetch
    return await core.session.get(url, **kwargs)
           ^^^^^^^^^^^^^^^^^^^^^^^^^^^^^^^^^^^^^
  File "C:\Users\brenopoubel\AppData\Roaming\Python\Python312\site-packages\httpx\_client.py", line 1736, in get
    return await self.request(
           ^^^^^^^^^^^^^^^^^^^
  File "C:\Users\brenopoubel\AppData\Roaming\Python\Python312\site-packages\httpx\_client.py", line 1513, in request
    return await self.send(request, auth=auth, follow_redirects=follow_redirects)
           ^^^^^^^^^^^^^^^^^^^^^^^^^^^^^^^^^^^^^^^^^^^^^^^^^^^^^^^^^^^^^^^^^^^^^^
  File "C:\Users\brenopoubel\AppData\Roaming\Python\Python312\site-packages\httpx\_client.py", line 1600, in send
    response = await self._send_handling_auth(
               ^^^^^^^^^^^^^^^^^^^^^^^^^^^^^^^
  File "C:\Users\brenopoubel\AppData\Roaming\Python\Python312\site-packages\httpx\_client.py", line 1628, in _send_handling_auth
    response = await self._send_handling_redirects(
               ^^^^^^^^^^^^^^^^^^^^^^^^^^^^^^^^^^^^
  File "C:\Users\brenopoubel\AppData\Roaming\Python\Python312\site-packages\httpx\_client.py", line 1665, in _send_handling_redirects
    response = await self._send_single_request(request)
               ^^^^^^^^^^^^^^^^^^^^^^^^^^^^^^^^^^^^^^^^
  File "C:\Users\brenopoubel\AppData\Roaming\Python\Python312\site-packages\httpx\_client.py", line 1702, in _send_single_request
    response = await transport.handle_async_request(request)
               ^^^^^^^^^^^^^^^^^^^^^^^^^^^^^^^^^^^^^^^^^^^^^
  File "C:\Users\brenopoubel\AppData\Roaming\Python\Python312\site-packages\httpx\_transports\default.py", line 290, in handle_async_request
    with map_httpcore_exceptions():
  File "C:\Program Files\Python312\Lib\contextlib.py", line 158, in __exit__
    self.gen.throw(value)
  File "C:\Users\brenopoubel\AppData\Roaming\Python\Python312\site-packages\httpx\_transports\default.py", line 77, in map_httpcore_exceptions
    raise mapped_exc(message) from exc
httpx.ReadTimeout
2024-06-18 08:01:17,791 - pocketoption - DEBUG - Balance -> None -> Not enough for Withdrawal
2024-06-18 08:01:17,791 - pocketoption - DEBUG - Bonus -> None -> Not enough for Withdrawal
2024-06-18 08:01:22,888 - pocketoption - DEBUG - Cookies Saved!!
2024-06-18 08:01:22,888 - pocketoption - ERROR - ERR_GET_LAST_PAYMENT_REQUEST_ID
Traceback (most recent call last):
  File "C:\Users\brenopoubel\AppData\Roaming\Python\Python312\site-packages\anyio\streams\tls.py", line 131, in _call_sslobject_method
    result = func(*args)
             ^^^^^^^^^^^
  File "C:\Program Files\Python312\Lib\ssl.py", line 859, in read
    v = self._sslobj.read(len)
        ^^^^^^^^^^^^^^^^^^^^^^
ssl.SSLWantReadError: The operation did not complete (read) (_ssl.c:2559)

During handling of the above exception, another exception occurred:

Traceback (most recent call last):
  File "C:\Users\brenopoubel\AppData\Roaming\Python\Python312\site-packages\httpcore\backends\asyncio.py", line 31, in read
    return await self._stream.receive(max_bytes=max_bytes)
           ^^^^^^^^^^^^^^^^^^^^^^^^^^^^^^^^^^^^^^^^^^^^^^^
  File "C:\Users\brenopoubel\AppData\Roaming\Python\Python312\site-packages\anyio\streams\tls.py", line 196, in receive
    data = await self._call_sslobject_method(self._ssl_object.read, max_bytes)
           ^^^^^^^^^^^^^^^^^^^^^^^^^^^^^^^^^^^^^^^^^^^^^^^^^^^^^^^^^^^^^^^^^^^
  File "C:\Users\brenopoubel\AppData\Roaming\Python\Python312\site-packages\anyio\streams\tls.py", line 138, in _call_sslobject_method
    data = await self.transport_stream.receive()
           ^^^^^^^^^^^^^^^^^^^^^^^^^^^^^^^^^^^^^
  File "C:\Users\brenopoubel\AppData\Roaming\Python\Python312\site-packages\anyio\_backends\_asyncio.py", line 1203, in receive
    await self._protocol.read_event.wait()
  File "C:\Program Files\Python312\Lib\asyncio\locks.py", line 212, in wait
    await fut
asyncio.exceptions.CancelledError

During handling of the above exception, another exception occurred:

Traceback (most recent call last):
  File "C:\Users\brenopoubel\AppData\Roaming\Python\Python312\site-packages\httpcore\_exceptions.py", line 8, in map_exceptions
    yield
  File "C:\Users\brenopoubel\AppData\Roaming\Python\Python312\site-packages\httpcore\backends\asyncio.py", line 29, in read
    with anyio.fail_after(timeout):
  File "C:\Users\brenopoubel\AppData\Roaming\Python\Python312\site-packages\anyio\_core\_tasks.py", line 119, in __exit__
    raise TimeoutError
TimeoutError

During handling of the above exception, another exception occurred:

Traceback (most recent call last):
  File "C:\Users\brenopoubel\AppData\Roaming\Python\Python312\site-packages\httpx\_transports\default.py", line 60, in map_httpcore_exceptions
    yield
  File "C:\Users\brenopoubel\AppData\Roaming\Python\Python312\site-packages\httpx\_transports\default.py", line 291, in handle_async_request
    resp = await self._pool.handle_async_request(req)
           ^^^^^^^^^^^^^^^^^^^^^^^^^^^^^^^^^^^^^^^^^^
  File "C:\Users\brenopoubel\AppData\Roaming\Python\Python312\site-packages\httpcore\_async\connection_pool.py", line 253, in handle_async_request
    raise exc
  File "C:\Users\brenopoubel\AppData\Roaming\Python\Python312\site-packages\httpcore\_async\connection_pool.py", line 237, in handle_async_request
    response = await connection.handle_async_request(request)
               ^^^^^^^^^^^^^^^^^^^^^^^^^^^^^^^^^^^^^^^^^^^^^^
  File "C:\Users\brenopoubel\AppData\Roaming\Python\Python312\site-packages\httpcore\_async\connection.py", line 90, in handle_async_request
    return await self._connection.handle_async_request(request)
           ^^^^^^^^^^^^^^^^^^^^^^^^^^^^^^^^^^^^^^^^^^^^^^^^^^^^
  File "C:\Users\brenopoubel\AppData\Roaming\Python\Python312\site-packages\httpcore\_async\http11.py", line 102, in handle_async_request
    raise exc
  File "C:\Users\brenopoubel\AppData\Roaming\Python\Python312\site-packages\httpcore\_async\http11.py", line 81, in handle_async_request
    ) = await self._receive_response_headers(**kwargs)
        ^^^^^^^^^^^^^^^^^^^^^^^^^^^^^^^^^^^^^^^^^^^^^^
  File "C:\Users\brenopoubel\AppData\Roaming\Python\Python312\site-packages\httpcore\_async\http11.py", line 143, in _receive_response_headers
    event = await self._receive_event(timeout=timeout)
            ^^^^^^^^^^^^^^^^^^^^^^^^^^^^^^^^^^^^^^^^^^
  File "C:\Users\brenopoubel\AppData\Roaming\Python\Python312\site-packages\httpcore\_async\http11.py", line 172, in _receive_event
    data = await self._network_stream.read(
           ^^^^^^^^^^^^^^^^^^^^^^^^^^^^^^^^
  File "C:\Users\brenopoubel\AppData\Roaming\Python\Python312\site-packages\httpcore\backends\asyncio.py", line 28, in read
    with map_exceptions(exc_map):
  File "C:\Program Files\Python312\Lib\contextlib.py", line 158, in __exit__
    self.gen.throw(value)
  File "C:\Users\brenopoubel\AppData\Roaming\Python\Python312\site-packages\httpcore\_exceptions.py", line 12, in map_exceptions
    raise to_exc(exc)
httpcore.ReadTimeout

The above exception was the direct cause of the following exception:

Traceback (most recent call last):
  File "C:\Users\brenopoubel\My Drive\Monitors\pocketoption2\main.py", line 788, in get_last_payment_request_id
    res = await fetch(core.payment_history_link)
          ^^^^^^^^^^^^^^^^^^^^^^^^^^^^^^^^^^^^^^
  File "C:\Users\brenopoubel\My Drive\Monitors\pocketoption2\main.py", line 79, in fetch
    return await core.session.get(url, **kwargs)
           ^^^^^^^^^^^^^^^^^^^^^^^^^^^^^^^^^^^^^
  File "C:\Users\brenopoubel\AppData\Roaming\Python\Python312\site-packages\httpx\_client.py", line 1736, in get
    return await self.request(
           ^^^^^^^^^^^^^^^^^^^
  File "C:\Users\brenopoubel\AppData\Roaming\Python\Python312\site-packages\httpx\_client.py", line 1513, in request
    return await self.send(request, auth=auth, follow_redirects=follow_redirects)
           ^^^^^^^^^^^^^^^^^^^^^^^^^^^^^^^^^^^^^^^^^^^^^^^^^^^^^^^^^^^^^^^^^^^^^^
  File "C:\Users\brenopoubel\AppData\Roaming\Python\Python312\site-packages\httpx\_client.py", line 1600, in send
    response = await self._send_handling_auth(
               ^^^^^^^^^^^^^^^^^^^^^^^^^^^^^^^
  File "C:\Users\brenopoubel\AppData\Roaming\Python\Python312\site-packages\httpx\_client.py", line 1628, in _send_handling_auth
    response = await self._send_handling_redirects(
               ^^^^^^^^^^^^^^^^^^^^^^^^^^^^^^^^^^^^
  File "C:\Users\brenopoubel\AppData\Roaming\Python\Python312\site-packages\httpx\_client.py", line 1665, in _send_handling_redirects
    response = await self._send_single_request(request)
               ^^^^^^^^^^^^^^^^^^^^^^^^^^^^^^^^^^^^^^^^
  File "C:\Users\brenopoubel\AppData\Roaming\Python\Python312\site-packages\httpx\_client.py", line 1702, in _send_single_request
    response = await transport.handle_async_request(request)
               ^^^^^^^^^^^^^^^^^^^^^^^^^^^^^^^^^^^^^^^^^^^^^
  File "C:\Users\brenopoubel\AppData\Roaming\Python\Python312\site-packages\httpx\_transports\default.py", line 290, in handle_async_request
    with map_httpcore_exceptions():
  File "C:\Program Files\Python312\Lib\contextlib.py", line 158, in __exit__
    self.gen.throw(value)
  File "C:\Users\brenopoubel\AppData\Roaming\Python\Python312\site-packages\httpx\_transports\default.py", line 77, in map_httpcore_exceptions
    raise mapped_exc(message) from exc
httpx.ReadTimeout
2024-06-18 08:01:22,888 - pocketoption - DEBUG - Second Check -> Latest ID:  | Existing ID: 164123
2024-06-18 08:59:38,561 - pocketoption - DEBUG - Logged-In successfully!
2024-06-18 08:59:38,576 - pocketoption - DEBUG - Cookies Saved!!
2024-06-18 08:59:40,285 - pocketoption - DEBUG - Cookies Saved!!
2024-06-18 08:59:40,295 - pocketoption - DEBUG - Processed -> Statistics -> Current week
2024-06-18 08:59:40,295 - pocketoption - DEBUG - Total time taken to perform the task: 39.66 seconds
2024-06-18 09:00:00,466 - pocketoption - DEBUG - No change detected!!
2024-06-18 09:01:01,871 - pocketoption - DEBUG - Cookies Saved!!
2024-06-18 09:01:01,949 - pocketoption - DEBUG - First Check -> Latest ID: 164123 | Existing ID: 164123
2024-06-18 09:01:03,138 - pocketoption - DEBUG - Cookies Saved!!
2024-06-18 09:01:03,138 - pocketoption - DEBUG - Balance -> -117 -> Not enough for Withdrawal
2024-06-18 09:01:03,138 - pocketoption - DEBUG - Bonus -> 0.0 -> Not enough for Withdrawal
2024-06-18 09:01:03,999 - pocketoption - DEBUG - Cookies Saved!!
2024-06-18 09:01:04,045 - pocketoption - DEBUG - Second Check -> Latest ID: 164123 | Existing ID: 164123
2024-06-18 09:59:01,521 - pocketoption - DEBUG - Old session worked fine.
2024-06-18 09:59:03,663 - pocketoption - DEBUG - Processed -> Statistics -> Current week
2024-06-18 09:59:03,663 - pocketoption - DEBUG - Total time taken to perform the task: 3.47 seconds
2024-06-18 10:00:00,843 - pocketoption - INFO - Target [ID:610323477]: success
2024-06-18 10:00:01,266 - pocketoption - INFO - Target [ID:1838317981]: success
2024-06-18 10:01:02,386 - pocketoption - DEBUG - First Check -> Latest ID: 164123 | Existing ID: 164123
2024-06-18 10:01:03,026 - pocketoption - DEBUG - Balance -> -117 -> Not enough for Withdrawal
2024-06-18 10:01:03,026 - pocketoption - DEBUG - Bonus -> 0.0 -> Not enough for Withdrawal
2024-06-18 10:01:03,996 - pocketoption - DEBUG - Second Check -> Latest ID: 164123 | Existing ID: 164123
2024-06-18 10:59:01,657 - pocketoption - DEBUG - Old session worked fine.
2024-06-18 10:59:04,003 - pocketoption - DEBUG - Processed -> Statistics -> Current week
2024-06-18 10:59:04,003 - pocketoption - DEBUG - Total time taken to perform the task: 3.75 seconds
2024-06-18 11:00:00,615 - pocketoption - DEBUG - No change detected!!
2024-06-18 11:01:04,081 - pocketoption - DEBUG - First Check -> Latest ID: 164123 | Existing ID: 164123
2024-06-18 11:01:04,799 - pocketoption - DEBUG - Balance -> -117 -> Not enough for Withdrawal
2024-06-18 11:01:04,799 - pocketoption - DEBUG - Bonus -> 0.0 -> Not enough for Withdrawal
2024-06-18 11:01:05,691 - pocketoption - DEBUG - Second Check -> Latest ID: 164123 | Existing ID: 164123
2024-06-18 11:59:01,976 - pocketoption - DEBUG - Old session worked fine.
2024-06-18 11:59:04,432 - pocketoption - DEBUG - Processed -> Statistics -> Current week
2024-06-18 11:59:04,432 - pocketoption - DEBUG - Total time taken to perform the task: 3.85 seconds
2024-06-18 12:00:00,018 - pocketoption - DEBUG - No change detected!!
2024-06-18 12:01:01,890 - pocketoption - DEBUG - First Check -> Latest ID: 164123 | Existing ID: 164123
2024-06-18 12:01:02,499 - pocketoption - DEBUG - Balance -> -117 -> Not enough for Withdrawal
2024-06-18 12:01:02,499 - pocketoption - DEBUG - Bonus -> 0.0 -> Not enough for Withdrawal
2024-06-18 12:01:03,531 - pocketoption - DEBUG - Second Check -> Latest ID: 164123 | Existing ID: 164123
2024-06-18 12:59:04,203 - pocketoption - DEBUG - Old session worked fine.
2024-06-18 12:59:06,503 - pocketoption - DEBUG - Processed -> Statistics -> Current week
2024-06-18 12:59:06,519 - pocketoption - DEBUG - Total time taken to perform the task: 5.74 seconds
2024-06-18 13:00:01,578 - pocketoption - INFO - Target [ID:610323477]: success
2024-06-18 13:00:01,875 - pocketoption - INFO - Target [ID:1838317981]: success
2024-06-18 13:01:02,714 - pocketoption - DEBUG - First Check -> Latest ID: 164123 | Existing ID: 164123
2024-06-18 13:01:03,323 - pocketoption - DEBUG - Balance -> -117 -> Not enough for Withdrawal
2024-06-18 13:01:03,323 - pocketoption - DEBUG - Bonus -> 0.0 -> Not enough for Withdrawal
2024-06-18 13:01:04,481 - pocketoption - DEBUG - Second Check -> Latest ID: 164123 | Existing ID: 164123
2024-06-18 13:59:01,940 - pocketoption - DEBUG - Old session worked fine.
2024-06-18 13:59:04,113 - pocketoption - DEBUG - Processed -> Statistics -> Current week
2024-06-18 13:59:04,113 - pocketoption - DEBUG - Total time taken to perform the task: 3.64 seconds
2024-06-18 14:00:00,616 - pocketoption - DEBUG - No change detected!!
2024-06-18 14:01:02,517 - pocketoption - DEBUG - First Check -> Latest ID: 164123 | Existing ID: 164123
2024-06-18 14:01:03,128 - pocketoption - DEBUG - Balance -> -117 -> Not enough for Withdrawal
2024-06-18 14:01:03,128 - pocketoption - DEBUG - Bonus -> 0.0 -> Not enough for Withdrawal
2024-06-18 14:01:04,081 - pocketoption - DEBUG - Second Check -> Latest ID: 164123 | Existing ID: 164123
2024-06-18 14:59:02,946 - pocketoption - DEBUG - Old session worked fine.
2024-06-18 14:59:04,400 - pocketoption - DEBUG - Processed -> Statistics -> Current week
2024-06-18 14:59:04,400 - pocketoption - DEBUG - Total time taken to perform the task: 3.46 seconds
2024-06-18 15:00:01,258 - pocketoption - INFO - Target [ID:610323477]: success
2024-06-18 15:00:01,539 - pocketoption - INFO - Target [ID:1838317981]: success
2024-06-18 15:01:01,614 - pocketoption - DEBUG - First Check -> Latest ID: 164123 | Existing ID: 164123
2024-06-18 15:01:02,346 - pocketoption - DEBUG - Balance -> -117 -> Not enough for Withdrawal
2024-06-18 15:01:02,348 - pocketoption - DEBUG - Bonus -> 0.0 -> Not enough for Withdrawal
2024-06-18 15:01:03,492 - pocketoption - DEBUG - Second Check -> Latest ID: 164123 | Existing ID: 164123
2024-06-18 15:59:02,232 - pocketoption - DEBUG - Old session worked fine.
2024-06-18 15:59:04,296 - pocketoption - DEBUG - Processed -> Statistics -> Current week
2024-06-18 15:59:04,296 - pocketoption - DEBUG - Total time taken to perform the task: 3.52 seconds
2024-06-18 16:00:01,379 - pocketoption - INFO - Target [ID:610323477]: success
2024-06-18 16:00:01,645 - pocketoption - INFO - Target [ID:1838317981]: success
2024-06-18 16:01:02,060 - pocketoption - DEBUG - First Check -> Latest ID: 164123 | Existing ID: 164123
2024-06-18 16:01:02,685 - pocketoption - DEBUG - Balance -> -117 -> Not enough for Withdrawal
2024-06-18 16:01:02,685 - pocketoption - DEBUG - Bonus -> 0.0 -> Not enough for Withdrawal
2024-06-18 16:01:03,609 - pocketoption - DEBUG - Second Check -> Latest ID: 164123 | Existing ID: 164123
2024-06-18 16:59:03,237 - pocketoption - DEBUG - Old session worked fine.
2024-06-18 16:59:05,490 - pocketoption - DEBUG - Processed -> Statistics -> Current week
2024-06-18 16:59:05,490 - pocketoption - DEBUG - Total time taken to perform the task: 5.1 seconds
2024-06-18 17:00:00,874 - pocketoption - INFO - Target [ID:610323477]: success
2024-06-18 17:00:01,171 - pocketoption - INFO - Target [ID:1838317981]: success
2024-06-18 17:01:02,038 - pocketoption - DEBUG - First Check -> Latest ID: 164123 | Existing ID: 164123
2024-06-18 17:01:02,648 - pocketoption - DEBUG - Balance -> -117 -> Not enough for Withdrawal
2024-06-18 17:01:02,648 - pocketoption - DEBUG - Bonus -> 0.0 -> Not enough for Withdrawal
2024-06-18 17:01:03,758 - pocketoption - DEBUG - Second Check -> Latest ID: 164123 | Existing ID: 164123
2024-06-18 17:59:01,417 - pocketoption - DEBUG - Old session worked fine.
2024-06-18 17:59:03,340 - pocketoption - DEBUG - Processed -> Statistics -> Current week
2024-06-18 17:59:03,340 - pocketoption - DEBUG - Total time taken to perform the task: 2.86 seconds
2024-06-18 18:00:00,577 - pocketoption - DEBUG - No change detected!!
2024-06-18 18:01:01,806 - pocketoption - DEBUG - First Check -> Latest ID: 164123 | Existing ID: 164123
2024-06-18 18:01:02,416 - pocketoption - DEBUG - Balance -> -117 -> Not enough for Withdrawal
2024-06-18 18:01:02,416 - pocketoption - DEBUG - Bonus -> 0.0 -> Not enough for Withdrawal
2024-06-18 18:01:03,335 - pocketoption - DEBUG - Second Check -> Latest ID: 164123 | Existing ID: 164123
2024-06-18 18:59:02,641 - pocketoption - DEBUG - Old session worked fine.
2024-06-18 18:59:04,127 - pocketoption - DEBUG - Processed -> Statistics -> Current week
2024-06-18 18:59:04,127 - pocketoption - DEBUG - Total time taken to perform the task: 3.13 seconds
2024-06-18 19:00:00,928 - pocketoption - INFO - Target [ID:610323477]: success
2024-06-18 19:00:01,209 - pocketoption - INFO - Target [ID:1838317981]: success
2024-06-18 19:01:02,408 - pocketoption - DEBUG - First Check -> Latest ID: 164123 | Existing ID: 164123
2024-06-18 19:01:02,970 - pocketoption - DEBUG - Balance -> -117 -> Not enough for Withdrawal
2024-06-18 19:01:02,970 - pocketoption - DEBUG - Bonus -> 0.0 -> Not enough for Withdrawal
2024-06-18 19:01:05,316 - pocketoption - DEBUG - Second Check -> Latest ID: 164123 | Existing ID: 164123
2024-06-18 19:18:12,154 - pocketoption - DEBUG - Date: 2024-06-11 | Hour: 22
2024-06-18 19:18:12,185 - pocketoption - DEBUG - Date: 2024-06-18 | Hour: 22
2024-06-18 19:59:01,885 - pocketoption - DEBUG - Old session worked fine.
2024-06-18 19:59:03,667 - pocketoption - DEBUG - Processed -> Statistics -> Current week
2024-06-18 19:59:03,667 - pocketoption - DEBUG - Total time taken to perform the task: 3.17 seconds
2024-06-18 20:00:00,995 - pocketoption - DEBUG - No change detected!!
2024-06-18 20:01:01,989 - pocketoption - DEBUG - First Check -> Latest ID: 164123 | Existing ID: 164123
2024-06-18 20:01:02,584 - pocketoption - DEBUG - Balance -> -117 -> Not enough for Withdrawal
2024-06-18 20:01:02,584 - pocketoption - DEBUG - Bonus -> 0.0 -> Not enough for Withdrawal
2024-06-18 20:01:03,475 - pocketoption - DEBUG - Second Check -> Latest ID: 164123 | Existing ID: 164123
2024-06-18 20:59:02,204 - pocketoption - DEBUG - Old session worked fine.
2024-06-18 20:59:03,814 - pocketoption - DEBUG - Processed -> Statistics -> Current week
2024-06-18 20:59:03,814 - pocketoption - DEBUG - Total time taken to perform the task: 2.95 seconds
2024-06-18 21:00:00,811 - pocketoption - INFO - Target [ID:610323477]: success
2024-06-18 21:00:01,061 - pocketoption - INFO - Target [ID:1838317981]: success
2024-06-18 21:01:01,896 - pocketoption - DEBUG - First Check -> Latest ID: 164123 | Existing ID: 164123
2024-06-18 21:01:02,553 - pocketoption - DEBUG - Balance -> -117 -> Not enough for Withdrawal
2024-06-18 21:01:02,553 - pocketoption - DEBUG - Bonus -> 0.0 -> Not enough for Withdrawal
2024-06-18 21:01:03,507 - pocketoption - DEBUG - Second Check -> Latest ID: 164123 | Existing ID: 164123
2024-06-18 21:59:01,772 - pocketoption - DEBUG - Old session worked fine.
2024-06-18 21:59:03,210 - pocketoption - DEBUG - Processed -> Statistics -> Current week
2024-06-18 21:59:03,226 - pocketoption - DEBUG - Total time taken to perform the task: 3.03 seconds
2024-06-18 22:00:01,032 - pocketoption - INFO - Target [ID:610323477]: success
2024-06-18 22:00:01,298 - pocketoption - INFO - Target [ID:1838317981]: success
2024-06-18 22:01:01,431 - pocketoption - DEBUG - First Check -> Latest ID: 164123 | Existing ID: 164123
2024-06-18 22:01:02,056 - pocketoption - DEBUG - Balance -> -117 -> Not enough for Withdrawal
2024-06-18 22:01:02,056 - pocketoption - DEBUG - Bonus -> 0.0 -> Not enough for Withdrawal
2024-06-18 22:01:02,963 - pocketoption - DEBUG - Second Check -> Latest ID: 164123 | Existing ID: 164123
2024-06-18 22:59:03,436 - pocketoption - DEBUG - Old session worked fine.
2024-06-18 22:59:05,140 - pocketoption - DEBUG - Processed -> Statistics -> Current week
2024-06-18 22:59:05,140 - pocketoption - DEBUG - Total time taken to perform the task: 4.22 seconds
2024-06-18 23:00:00,494 - pocketoption - DEBUG - No change detected!!
2024-06-18 23:01:02,833 - pocketoption - DEBUG - First Check -> Latest ID: 164123 | Existing ID: 164123
2024-06-18 23:01:03,427 - pocketoption - DEBUG - Balance -> -117 -> Not enough for Withdrawal
2024-06-18 23:01:03,443 - pocketoption - DEBUG - Bonus -> 0.0 -> Not enough for Withdrawal
2024-06-18 23:01:04,474 - pocketoption - DEBUG - Second Check -> Latest ID: 164123 | Existing ID: 164123
2024-06-18 23:59:03,052 - pocketoption - DEBUG - Old session worked fine.
2024-06-18 23:59:04,974 - pocketoption - DEBUG - Processed -> Statistics -> Current week
2024-06-18 23:59:04,974 - pocketoption - DEBUG - Total time taken to perform the task: 4.64 seconds
2024-06-19 00:00:00,880 - pocketoption - INFO - Target [ID:610323477]: success
2024-06-19 00:00:01,161 - pocketoption - INFO - Target [ID:1838317981]: success
2024-06-19 00:01:02,322 - pocketoption - DEBUG - First Check -> Latest ID: 164123 | Existing ID: 164123
2024-06-19 00:01:02,914 - pocketoption - DEBUG - Balance -> -117 -> Not enough for Withdrawal
2024-06-19 00:01:02,914 - pocketoption - DEBUG - Bonus -> 0.0 -> Not enough for Withdrawal
2024-06-19 00:01:03,867 - pocketoption - DEBUG - Second Check -> Latest ID: 164123 | Existing ID: 164123
2024-06-19 00:59:03,495 - pocketoption - DEBUG - Old session worked fine.
2024-06-19 00:59:05,261 - pocketoption - DEBUG - Processed -> Statistics -> Current week
2024-06-19 00:59:05,261 - pocketoption - DEBUG - Total time taken to perform the task: 4.58 seconds
2024-06-19 01:00:01,442 - pocketoption - INFO - Target [ID:610323477]: success
2024-06-19 01:00:01,739 - pocketoption - INFO - Target [ID:1838317981]: success
2024-06-19 01:01:01,890 - pocketoption - DEBUG - First Check -> Latest ID: 164123 | Existing ID: 164123
2024-06-19 01:01:02,515 - pocketoption - DEBUG - Balance -> -117 -> Not enough for Withdrawal
2024-06-19 01:01:02,515 - pocketoption - DEBUG - Bonus -> 0.0 -> Not enough for Withdrawal
2024-06-19 01:01:03,423 - pocketoption - DEBUG - Second Check -> Latest ID: 164123 | Existing ID: 164123
2024-06-19 01:59:01,384 - pocketoption - DEBUG - Old session worked fine.
2024-06-19 01:59:03,634 - pocketoption - DEBUG - Processed -> Statistics -> Current week
2024-06-19 01:59:03,634 - pocketoption - DEBUG - Total time taken to perform the task: 3.49 seconds
2024-06-19 02:00:00,102 - pocketoption - DEBUG - No change detected!!
2024-06-19 02:01:02,394 - pocketoption - DEBUG - First Check -> Latest ID: 164123 | Existing ID: 164123
2024-06-19 02:01:03,019 - pocketoption - DEBUG - Balance -> -117 -> Not enough for Withdrawal
2024-06-19 02:01:03,019 - pocketoption - DEBUG - Bonus -> 0.0 -> Not enough for Withdrawal
2024-06-19 02:01:03,956 - pocketoption - DEBUG - Second Check -> Latest ID: 164123 | Existing ID: 164123
2024-06-19 02:59:01,946 - pocketoption - DEBUG - Old session worked fine.
2024-06-19 02:59:04,088 - pocketoption - DEBUG - Processed -> Statistics -> Current week
2024-06-19 02:59:04,088 - pocketoption - DEBUG - Total time taken to perform the task: 3.55 seconds
2024-06-19 03:00:01,071 - pocketoption - INFO - Target [ID:610323477]: success
2024-06-19 03:00:01,337 - pocketoption - INFO - Target [ID:1838317981]: success
2024-06-19 03:01:02,052 - pocketoption - DEBUG - First Check -> Latest ID: 164123 | Existing ID: 164123
2024-06-19 03:01:02,661 - pocketoption - DEBUG - Balance -> -117 -> Not enough for Withdrawal
2024-06-19 03:01:02,661 - pocketoption - DEBUG - Bonus -> 0.0 -> Not enough for Withdrawal
2024-06-19 03:01:05,350 - pocketoption - DEBUG - Second Check -> Latest ID: 164123 | Existing ID: 164123
2024-06-19 03:59:01,843 - pocketoption - DEBUG - Old session worked fine.
2024-06-19 03:59:03,578 - pocketoption - DEBUG - Processed -> Statistics -> Current week
2024-06-19 03:59:03,578 - pocketoption - DEBUG - Total time taken to perform the task: 3.21 seconds
2024-06-19 04:00:01,351 - pocketoption - INFO - Target [ID:610323477]: success
2024-06-19 04:00:01,618 - pocketoption - INFO - Target [ID:1838317981]: success
2024-06-19 04:01:01,826 - pocketoption - DEBUG - First Check -> Latest ID: 164123 | Existing ID: 164123
2024-06-19 04:01:02,406 - pocketoption - DEBUG - Balance -> -117 -> Not enough for Withdrawal
2024-06-19 04:01:02,415 - pocketoption - DEBUG - Bonus -> 0.0 -> Not enough for Withdrawal
2024-06-19 04:01:03,290 - pocketoption - DEBUG - Second Check -> Latest ID: 164123 | Existing ID: 164123
